Workbook

Sheet README
A1: Symbiotec DCV: Solu-Medrol vs Solu-Cortef calculations
A2: Companion workbook to the report 'Pfizer-only Cortef vials anchor Symbiotec's DCV case'. Data as of 21 October 2026.
A4: Colour legend
A5: Input | B5: Blue text: hard-coded input copied from a cited source (source ID in the row or column note)
A6: Formula | B6: Black text: formula calculated in this workbook
A7: Link | B7: Green text: formula linking to another sheet
A8: Assumption | B8: Yellow fill: analyst assumption to review or change
A10: Sheets
A11: Sheet | B11: What it calculates | C11: Report section
A12: Report_Map | B12: Every number quoted in the report, linked live to the cell that calculates it | C12: All
A13: Assumptions | B13: ASP divisor, billing units per vial, code-change quarter, FX, review clock, key dates | C13: All
A14: CMS_PL | B14: Input: Part B payment limit per billing unit by HCPCS code, Q1 2016 to Q4 2026 | C14: ASP
A15: ASP_per_vial | B15: Implied ASP per vial = payment limit x billing units / 1.06; quarterly and annual averages | C15: ASP
A16: ASP_growth | B16: Peaks, 1y change, 3y and 5y CAGRs, quarter-on-quarter moves | C16: ASP
A17: Pfizer_WAC | B17: Pfizer list price per vial by presentation and date; Jul 2024 to Jul 2026 changes; 2025 Solu-Medrol cuts; ASP vs WAC | C17: Price points
A18: NADAC | B18: Retail acquisition cost; generic as % of brand | C18: Price points
A19: SDUD_NDC_data | B19: Input: Medicaid prescriptions, units and dollars by NDC and year (aggregated from SDUD national rows) | C19: Share proxies
A20: Medicaid_SDUD | B20: Prescription shares by labeler and strength, HSS large-vial slice, 250 mg billing-unit drag | C20: Share proxies
A21: CMS_Spending | B21: Part D and Medicaid Spending by Drug 2024; Part B volume and spend per unit; HSS vs MPSS spend ratios | C21: Share proxies; market size
A22: Market_Size | B22: Market-size figures, ICICI estimates in US$, Pfizer Medrol revenue, capacity cross-check | C22: Market size; implications
... A24: Sources | B24: Every source used in this workbook, with links | C24: All
A26: Method notes
A27: - Medicare Part B pays ASP + 6% for these multi-source drugs, so implied ASP = CMS payment limit / 1.06 (divisor in Assumptions).
A28: - CMS replaced J2920/J2930 (MPSS) with J2919 (per 5 mg) and J1020/J1030/J1040 (MPA) with J1010 (per 1 mg) from Q2 2024. Per-vial series for MPSS and MPA switch codes at that quarter, so do not splice growth across it.
A29: - Medicaid SDUD is outpatient and pre-rebate. Use prescription share for direction, not as true market share. 2026 SDUD covers Q1 only.
A30: - SDUD_NDC_data was aggregated in Python from the national rows of the SDUD annual files for every NDC RxNorm links to these molecules. All shares on Medicaid_SDUD are recomputed here with SUMIFS on that table.
A31: - Payment limits, list prices, NADAC and CMS spending figures are copied from the cited files without adjustment.

Sheet Report_Map
A1: Report figures linked to their calculations
A2: Each value is a live link. 'Report value' is what the Word report states; 'Check' compares to the rounding shown in the report.
A4: Report section | B4: Figure | C4: Workbook value | D4: Report value | E4: Check | F4: Calculated on
A5: Summary / ASP | B5: MPSS 125 mg implied ASP per vial, old-code peak (Q3 2018) | C5: =ASP_growth!$S$7 -> 6.5707547 | D5: 6.57 | E5: =IF(ABS(C5-D5)<=MAX(0.0051,ABS(D5)*0.02),"OK","Check") -> OK | F5: ASP_growth
A6: Summary / ASP | B6: MPSS 125 mg implied ASP per vial, new-code (J2919) peak (Q4 2024) | C6: =ASP_growth!$U$7 -> 7.1698113 | D6: 7.17 | E6: =IF(ABS(C6-D6)<=MAX(0.0051,ABS(D6)*0.02),"OK","Check") -> OK | F6: ASP_growth
A7: Summary / ASP | B7: MPSS 125 mg implied ASP per vial, Q4 2026 | C7: =INDEX(ASP_per_vial!$E$6:$P$49,MATCH("2026-Q4",ASP_per_vial!$A$6:$A$49,0),MATCH("MPSS 125 mg",ASP_per_vial!$E$5:$P$5,0)) -> 6.0141509 | D7: 6.01 | E7: =IF(ABS(C7-D7)<=MAX(0.0051,ABS(D7)*0.02),"OK","Check") -> OK | F7: ASP_per_vial
A8: Summary / ASP | B8: HSS 100 mg implied ASP per vial, Q4 2026 | C8: =INDEX(ASP_per_vial!$E$6:$P$49,MATCH("2026-Q4",ASP_per_vial!$A$6:$A$49,0),MATCH("HSS 100 mg",ASP_per_vial!$E$5:$P$5,0)) -> 21.838679 | D8: 21.84 | E8: =IF(ABS(C8-D8)<=MAX(0.0051,ABS(D8)*0.02),"OK","Check") -> OK | F8: ASP_per_vial
A9: Summary / ASP | B9: HSS 250 mg implied ASP per vial, Q4 2026 (2.5 units) | C9: =INDEX(ASP_per_vial!$E$6:$P$49,MATCH("2026-Q4",ASP_per_vial!$A$6:$A$49,0),MATCH("HSS 250 mg (2.5 units)",ASP_per_vial!$E$5:$P$5,0)) -> 54.596698 | D9: 54.6 | E9: =IF(ABS(C9-D9)<=MAX(0.0051,ABS(D9)*0.02),"OK","Check") -> OK | F9: ASP_per_vial
A10: Summary / ASP | B10: HSS 250 mg implied ASP per vial, Q4 2026 (3 units) | C10: =INDEX(ASP_per_vial!$E$6:$P$49,MATCH("2026-Q4",ASP_per_vial!$A$6:$A$49,0),MATCH("HSS 250 mg (3 units)",ASP_per_vial!$E$5:$P$5,0)) -> 65.516038 | D10: 65.52 | E10: =IF(ABS(C10-D10)<=MAX(0.0051,ABS(D10)*0.02),"OK","Check") -> OK | F10: ASP_per_vial
A11: Summary / ASP | B11: HSS 500 mg implied ASP per vial, Q4 2026 | C11: =INDEX(ASP_per_vial!$E$6:$P$49,MATCH("2026-Q4",ASP_per_vial!$A$6:$A$49,0),MATCH("HSS 500 mg",ASP_per_vial!$E$5:$P$5,0)) -> 109.1934 | D11: 109.19 | E11: =IF(ABS(C11-D11)<=MAX(0.0051,ABS(D11)*0.02),"OK","Check") -> OK | F11: ASP_per_vial
A12: Summary / ASP | B12: HSS 1 g implied ASP per vial, Q4 2026 | C12: =INDEX(ASP_per_vial!$E$6:$P$49,MATCH("2026-Q4",ASP_per_vial!$A$6:$A$49,0),MATCH("HSS 1 g",ASP_per_vial!$E$5:$P$5,0)) -> 218.38679 | D12: 218.39 | E12: =IF(ABS(C12-D12)<=MAX(0.0051,ABS(D12)*0.02),"OK","Check") -> OK | F12: ASP_per_vial
A13: Summary / ASP | B13: J1720 payment-limit CAGR, Q1 2016 to Q4 2026 (~11%) | C13: =ASP_growth!$B$77 -> 0.11050728 | D13: 0.11 | E13: =IF(ABS(C13-D13)<=MAX(0.006,ABS(D13)*0.02),"OK","Check") -> OK | F13: ASP_growth
A14: ASP | B14: HSS 100 mg 1y change | C14: =ASP_growth!$L$11 -> 0.086195571 | D14: 0.086 | E14: =IF(ABS(C14-D14)<=MAX(0.006,ABS(D14)*0.02),"OK","Check") -> OK | F14: ASP_growth
A15: ASP | B15: HSS 100 mg 5y CAGR | C15: =ASP_growth!$N$11 -> 0.093426438 | D15: 0.093 | E15: =IF(ABS(C15-D15)<=MAX(0.006,ABS(D15)*0.02),"OK","Check") -> OK | F15: ASP_growth
A16: ASP | B16: MPSS 125 mg 1y change (off Q4 2025 trough) | C16: =ASP_growth!$L$7 -> 0.21428571 | D16: 0.214 | E16: =IF(ABS(C16-D16)<=MAX(0.006,ABS(D16)*0.02),"OK","Check") -> OK | F16: ASP_growth
A17: ASP | B17: MPSS 125 mg 5y CAGR (crosses recode) | C17: =ASP_growth!$N$7 -> 0.027550096 | D17: 0.027 | E17: =IF(ABS(C17-D17)<=MAX(0.006,ABS(D17)*0.02),"OK","Check") -> OK | F17: ASP_growth
A18: ASP | B18: MPSS 40 mg ASP, Q1 2024 (last old code) | C18: =INDEX(ASP_per_vial!$E$6:$P$49,MATCH("2024-Q1",ASP_per_vial!$A$6:$A$49,0),MATCH("MPSS 40 mg",ASP_per_vial!$E$5:$P$5,0)) -> 3.9509434 | D18: 3.95 | E18: =IF(ABS(C18-D18)<=MAX(0.0051,ABS(D18)*0.02),"OK","Check") -> OK | F18: ASP_per_vial
A19: ASP | B19: MPSS 40 mg ASP, Q2 2024 (first new code) | C19: =INDEX(ASP_per_vial!$E$6:$P$49,MATCH("2024-Q2",ASP_per_vial!$A$6:$A$49,0),MATCH("MPSS 40 mg",ASP_per_vial!$E$5:$P$5,0)) -> 2.0603774 | D19: 2.06 | E19: =IF(ABS(C19-D19)<=MAX(0.0051,ABS(D19)*0.02),"OK","Check") -> OK | F19: ASP_per_vial
A20: ASP | B20: MPSS 125 mg change Q1 2016 to Q3 2018 | C20: =ASP_growth!$P$7 -> 0.69671133 | D20: 0.7 | E20: =IF(ABS(C20-D20)<=MAX(0.006,ABS(D20)*0.02),"OK","Check") -> OK | F20: ASP_growth
A21: ASP | B21: MPSS 40 mg change Q1 2016 to Q3 2018 | C21: =ASP_growth!$P$6 -> 0.65804003 | D21: 0.66 | E21: =IF(ABS(C21-D21)<=MAX(0.006,ABS(D21)*0.02),"OK","Check") -> OK | F21: ASP_growth
A22: ASP | B22: J2919 change Q2 2024 to Q4 2026 | C22: =ASP_growth!$Q$7 -> -0.065934066 | D22: -0.066 | E22: =IF(ABS(C22-D22)<=MAX(0.006,ABS(D22)*0.02),"OK","Check") -> OK | F22: ASP_growth
A23: ASP | B23: J2919 change in Q4 2025 | C23: =ASP_growth!$B$73 -> -0.18918919 | D23: -0.189 | E23: =IF(ABS(C23-D23)<=MAX(0.006,ABS(D23)*0.02),"OK","Check") -> OK | F23: ASP_growth
A24: ASP | B24: J2919 change in Q1 2026 | C24: =ASP_growth!$B$74 -> 0.25714286 | D24: 0.257 | E24: =IF(ABS(C24-D24)<=MAX(0.006,ABS(D24)*0.02),"OK","Check") -> OK | F24: ASP_growth
A25: ASP | B25: J2919 implied ASP per 5 mg, 2025 average | C25: =ASP_growth!$B$75 -> 0.23301887 | D25: 0.233 | E25: =IF(ABS(C25-D25)<=MAX(0.0011,ABS(D25)*0.02),"OK","Check") -> OK | F25: ASP_growth
A26: ASP | B26: J2919 implied ASP per 5 mg, 2026 average | C26: =ASP_growth!$B$76 -> 0.23207547 | D26: 0.232 | E26: =IF(ABS(C26-D26)<=MAX(0.0011,ABS(D26)*0.02),"OK","Check") -> OK | F26: ASP_growth
A27: ASP | B27: J1720 change in Q3 2017 | C27: =ASP_growth!$B$71 -> 0.20123976 | D27: 0.201 | E27: =IF(ABS(C27-D27)<=MAX(0.006,ABS(D27)*0.02),"OK","Check") -> OK | F27: ASP_growth
A28: ASP | B28: J1720 change in Q3 2022 | C28: =ASP_growth!$B$72 -> 0.19202333 | D28: 0.192 | E28: =IF(ABS(C28-D28)<=MAX(0.006,ABS(D28)*0.02),"OK","Check") -> OK | F28: ASP_growth
A29: ASP | B29: J1720 largest quarterly fall (report: never 10% or more) | C29: =ASP_growth!$B$69 -> -0.022968821 | F29: ASP_growth
A30: ASP | B30: MPA 40 mg/mL change Q2 2024 to Q4 2026 (J1010) | C30: =ASP_growth!$Q$16 -> -0.082089552 | D30: -0.082 | E30: =IF(ABS(C30-D30)<=MAX(0.006,ABS(D30)*0.02),"OK","Check") -> OK | F30: ASP_growth
A31: ASP | B31: MPA 40 mg/mL implied ASP per vial, Q4 2026 | C31: =INDEX(ASP_per_vial!$E$6:$P$49,MATCH("2026-Q4",ASP_per_vial!$A$6:$A$49,0),MATCH("MPA 40 mg/mL 1 mL",ASP_per_vial!$E$5:$P$5,0)) -> 4.6415094 | D31: 4.64 | E31: =IF(ABS(C31-D31)<=MAX(0.0051,ABS(D31)*0.02),"OK","Check") -> OK | F31: ASP_per_vial
A32: ASP | B32: MPA 80 mg/mL implied ASP per vial, Q4 2026 | C32: =INDEX(ASP_per_vial!$E$6:$P$49,MATCH("2026-Q4",ASP_per_vial!$A$6:$A$49,0),MATCH("MPA 80 mg/mL 1 mL",ASP_per_vial!$E$5:$P$5,0)) -> 9.2830189 | D32: 9.28 | E32: =IF(ABS(C32-D32)<=MAX(0.0051,ABS(D32)*0.02),"OK","Check") -> OK | F32: ASP_per_vial
A33: Price points | B33: Solu-Cortef WAC change Jul-24 to Jul-26: low end (single vials) | C33: =Pfizer_WAC!$K$29 -> 0.17973856 | D33: 0.18 | E33: =IF(ABS(C33-D33)<=MAX(0.006,ABS(D33)*0.02),"OK","Check") -> OK | F33: Pfizer_WAC
A34: Price points | B34: Solu-Cortef WAC change Jul-24 to Jul-26: high end (single vials) | C34: =Pfizer_WAC!$K$30 -> 0.29187689 | D34: 0.292 | E34: =IF(ABS(C34-D34)<=MAX(0.006,ABS(D34)*0.02),"OK","Check") -> OK | F34: Pfizer_WAC
A35: Price points | B35: Solu-Cortef WAC change Jul-24 to Jul-26: 25-pack low end | C35: =Pfizer_WAC!$K$31 -> 0.15755483 | F35: Pfizer_WAC
A36: Price points | B36: Solu-Medrol largest mid-2025 WAC cut (1 g multi-dose vial) | C36: =Pfizer_WAC!$K$32 -> -0.42360164 | D36: -0.424 | E36: =IF(ABS(C36-D36)<=MAX(0.006,ABS(D36)*0.02),"OK","Check") -> OK | F36: Pfizer_WAC
A37: Price points | B37: Solu-Medrol smallest mid-2025 WAC cut | C37: =Pfizer_WAC!$K$33 -> -0.16998516 | D37: -0.17 | E37: =IF(ABS(C37-D37)<=MAX(0.006,ABS(D37)*0.02),"OK","Check") -> OK | F37: Pfizer_WAC
A38: Price points | B38: Solu-Medrol lines cut in mid-2025 | C38: =Pfizer_WAC!$K$34 -> 5 | D38: 5 | E38: =IF(ABS(C38-D38)<=MAX(0.0011,ABS(D38)*0.02),"OK","Check") -> OK | F38: Pfizer_WAC
A39: Price points | B39: Solu-Medrol 40 mg Act-O-Vial line A cut | C39: =Pfizer_WAC!$K$35 -> -0.24337121 | D39: -0.244 | E39: =IF(ABS(C39-D39)<=MAX(0.006,ABS(D39)*0.02),"OK","Check") -> OK | F39: Pfizer_WAC
A40: Price points | B40: Solu-Medrol 40 mg Act-O-Vial line C cut | C40: =Pfizer_WAC!$K$36 -> -0.16998516 | D40: -0.17 | E40: =IF(ABS(C40-D40)<=MAX(0.006,ABS(D40)*0.02),"OK","Check") -> OK | F40: Pfizer_WAC
A41: Price points | B41: Solu-Medrol 125 mg Act-O-Vial line A cut | C41: =Pfizer_WAC!$K$37 -> -0.2523337 | D41: -0.252 | E41: =IF(ABS(C41-D41)<=MAX(0.006,ABS(D41)*0.02),"OK","Check") -> OK | F41: Pfizer_WAC
...

Sheet Assumptions
A1: Assumptions and conversion factors
A4: Parameter | B4: Value | C4: Unit | D4: Source / note
A5: ASP add-on divisor (payment limit = ASP x 1.06) | B5: 1.06 | C5: x | D5: S01: Medicare Part B pays ASP + 6% for multi-source drugs; inflation-rebate coinsurance column reads 20% in every quarter used
A6: First quarter of new codes J2919 / J1010: year | B6: 2024 | C6: year | D6: S04: J2919 and J1010 first appear in the April 2024 CMS file
A7: First quarter of new codes: quarter number | B7: 2 | C7: quarter | D7: S04
A8: Cutover quarter index | B8: =B6+(B7-1)/4 -> 2024.25 | C8: index | D8: Formula: year + (quarter - 1) / 4
A9: FX rate | B9: 86.5 | C9: INR per US$ | D9: Analyst assumption used only to convert ICICI's INR estimates; update as needed
A10: FDA review goal, standard original ANDA | B10: 10 | C10: months | D10: S09: GDUFA III, act on 90% of standard original ANDAs within 10 months of submission
A11: Symbiotec first DCV ANDA filing date | B11: 46266 | C11: date | D11: S25 slide 5: filed 'September 2026'. Day not disclosed; 1st of month assumed
A12: Second DCV ANDA filing window: start | B12: 46388 | C12: date | D12: S25 slide 5: 'scheduled for Q4 FY27' (Jan-Mar 2027)
A13: Second DCV ANDA filing window: end | B13: 46477 | C13: date | D13: S25 slide 5
A14: CGT exclusivity period | B14: 180 | C14: days | D14: S08: 180-day competitive generic therapy exclusivity
A15: Cipla HSS first commercial marketing | B15: 45561 | C15: date | D15: S08: FDA CGT list
A16: Cipla HSS ANDA 214050 approval | B16: 45540 | C16: date | D16: S05: Orange Book
A17: Report as-of date | B17: 46316 | C17: date | D17: Date the data were pulled
A20: Billing units per vial (CMS NDC-HCPCS crosswalk convention)
A21: Vial | B21: Old code (to Q1 2024) | C21: Old units per vial | D21: New code (from Q2 2024) | E21: New units per vial | F21: Source / note
A22: MPSS 40 mg | B22: J2920 | C22: 1 | D22: J2919 | E22: 8 | F22: J2920 = up to 40 mg; J2919 = 5 mg. S01, S04
A23: MPSS 125 mg | B23: J2930 | C23: 1 | D23: J2919 | E23: 25 | F23: J2930 = up to 125 mg. S01, S04
A24: MPSS 500 mg | B24: J2930 | C24: 4 | D24: J2919 | E24: 100 | F24: S01, S04
A25: MPSS 1 g | B25: J2930 | C25: 8 | D25: J2919 | E25: 200 | F25: S01, S04
A26: MPSS 2 g | B26: J2930 | C26: 16 | D26: J2919 | E26: 400 | F26: S01, S04
A27: HSS 100 mg | B27: J1720 | C27: 1 | D27: J1720 | E27: 1 | F27: J1720 = up to 100 mg. S03
A28: HSS 250 mg (2.5 units) | B28: J1720 | C28: 2.5 | D28: J1720 | E28: 2.5 | F28: CMS crosswalk convention through Q3 2026. S01
A29: HSS 250 mg (3 units) | B29: J1720 | C29: 3 | D29: J1720 | E29: 3 | F29: October 2026 crosswalk convention ('UP TO 100 MG'). S03
A30: HSS 500 mg | B30: J1720 | C30: 5 | D30: J1720 | E30: 5 | F30: S03
A31: HSS 1 g | B31: J1720 | C31: 10 | D31: J1720 | E31: 10 | F31: S03
A32: MPA 40 mg/mL 1 mL | B32: J1030 | C32: 1 | D32: J1010 | E32: 40 | F32: J1030 = 40 mg; J1010 = 1 mg. S01, S04
A33: MPA 80 mg/mL 1 mL | B33: J1040 | C33: 1 | D33: J1010 | E33: 80 | F33: J1040 = 80 mg. S01, S04

Sheet CMS_PL
A1: Input: CMS Part B payment limit per billing unit (US$)
A2: Source S01 (each quarter's pricing file, URL in column N). Values copied unchanged.
A5: Quarter | B5: Year | C5: Qtr | D5: Quarter index | E5: J2920 MPSS up to 40 mg | F5: J2930 MPSS up to 125 mg | G5: J2919 MPSS per 5 mg | H5: J1720 HSS up to 100 mg | I5: J1030 MPA 40 mg | J5: J1040 MPA 80 mg | K5: J1010 MPA per 1 mg | L5: J1020 MPA 20 mg | M5: ASP sales quarter | N5: Payment-limit file (CMS)
A6: 2016-Q1 | B6: 2016 | C6: 1 | D6: =VALUE(B6)+(C6-1)/4 -> 2016 | E6: 2.898 | F6: 4.105 | H6: 7.502 | I6: 4.308 | J6: 8.334 | L6: 4.495 | M6: 3Q15 | N6: https://www.cms.gov/Medicare/Medicare-Fee-for-Service-Part-B-Drugs/McrPartBDrugAvgSalesPrice/downloads/2016-January-ASP-Pricing-File.zip
A7: 2016-Q2 | B7: 2016 | C7: 2 | D7: =VALUE(B7)+(C7-1)/4 -> 2016.25 | E7: 2.955 | F7: 4.213 | H7: 7.462 | I7: 4.489 | J7: 8.564 | L7: 4.493 | M7: 4Q15 | N7: https://www.cms.gov/Medicare/Medicare-Fee-for-Service-Part-B-Drugs/McrPartBDrugAvgSalesPrice/downloads/2016-April-ASP-Pricing-File.zip
A8: 2016-Q3 | B8: 2016 | C8: 3 | D8: =VALUE(B8)+(C8-1)/4 -> 2016.5 | E8: 3.331 | F8: 4.964 | H8: 8.163 | I8: 4.954 | J8: 9.478 | L8: 4.754 | M8: 1Q16 | N8: https://www.cms.gov/Medicare/Medicare-Fee-for-Service-Part-B-Drugs/McrPartBDrugAvgSalesPrice/Downloads/2016-July-ASP-Pricing-File.zip
A9: 2016-Q4 | B9: 2016 | C9: 4 | D9: =VALUE(B9)+(C9-1)/4 -> 2016.75 | E9: 3.726 | F9: 5.126 | H9: 8.531 | I9: 5.222 | J9: 9.8 | L9: 4.821 | M9: 2Q16 | N9: https://www.cms.gov/Medicare/Medicare-Fee-for-Service-Part-B-Drugs/McrPartBDrugAvgSalesPrice/Downloads/2016-October-ASP-Pricing-File.zip
A10: 2017-Q1 | B10: 2017 | C10: 1 | D10: =VALUE(B10)+(C10-1)/4 -> 2017 | E10: 4.002 | F10: 5.498 | H10: 9.118 | I10: 5.472 | J10: 10.268 | L10: 4.987 | M10: 3Q16 | N10: https://www.cms.gov/Medicare/Medicare-Fee-for-Service-Part-B-Drugs/McrPartBDrugAvgSalesPrice/Downloads/2017-January-ASP-Pricing-Files.zip
A11: 2017-Q2 | B11: 2017 | C11: 2 | D11: =VALUE(B11)+(C11-1)/4 -> 2017.25 | E11: 4.064 | F11: 5.568 | H11: 9.034 | I11: 5.568 | J11: 10.614 | L11: 4.99 | M11: 4Q16 | N11: https://www.cms.gov/Medicare/Medicare-Fee-for-Service-Part-B-Drugs/McrPartBDrugAvgSalesPrice/Downloads/2017-April-ASP-Pricing.zip
A12: 2017-Q3 | B12: 2017 | C12: 3 | D12: =VALUE(B12)+(C12-1)/4 -> 2017.5 | E12: 4.348 | F12: 6.033 | H12: 10.852 | I12: 6.004 | J12: 11.53 | L12: 5.402 | M12: 1Q17 | N12: https://www.cms.gov/Medicare/Medicare-Fee-for-Service-Part-B-Drugs/McrPartBDrugAvgSalesPrice/Downloads/2017-July-ASP-Pricing-File.zip
A13: 2017-Q4 | B13: 2017 | C13: 4 | D13: =VALUE(B13)+(C13-1)/4 -> 2017.75 | E13: 4.337 | F13: 6.093 | H13: 11.279 | I13: 6.362 | J13: 12.26 | L13: 5.592 | M13: 2Q17 | N13: https://www.cms.gov/Medicare/Medicare-Fee-for-Service-Part-B-Drugs/McrPartBDrugAvgSalesPrice/Downloads/2017-October-ASP-Pricing-File.zip
A14: 2018-Q1 | B14: 2018 | C14: 1 | D14: =VALUE(B14)+(C14-1)/4 -> 2018 | E14: 4.346 | F14: 5.985 | H14: 11.931 | I14: 6.694 | J14: 12.963 | L14: 5.945 | M14: 3Q17 | N14: https://www.cms.gov/Medicare/Medicare-Fee-for-Service-Part-B-Drugs/McrPartBDrugAvgSalesPrice/Downloads/2018-January-ASP-Pricing-File.zip
A15: 2018-Q2 | B15: 2018 | C15: 2 | D15: =VALUE(B15)+(C15-1)/4 -> 2018.25 | E15: 4.537 | F15: 6.672 | H15: 12.05 | I15: 6.638 | J15: 12.909 | L15: 4.837 | M15: 4Q17 | N15: https://www.cms.gov/Medicare/Medicare-Fee-for-Service-Part-B-Drugs/McrPartBDrugAvgSalesPrice/Downloads/2018-April-ASP-Pricing-File.zip
A16: 2018-Q3 | B16: 2018 | C16: 3 | D16: =VALUE(B16)+(C16-1)/4 -> 2018.5 | E16: 4.805 | F16: 6.965 | H16: 13.177 | I16: 7.001 | J16: 13.51 | L16: 4.177 | M16: 1Q18 | N16: https://www.cms.gov/Medicare/Medicare-Fee-for-Service-Part-B-Drugs/McrPartBDrugAvgSalesPrice/Downloads/2018-July-ASP-Pricing-File.zip
A17: 2018-Q4 | B17: 2018 | C17: 4 | D17: =VALUE(B17)+(C17-1)/4 -> 2018.75 | E17: 4.717 | F17: 6.942 | H17: 13.051 | I17: 6.773 | J17: 13.321 | L17: 4.314 | M17: 2Q18 | N17: https://www.cms.gov/Medicare/Medicare-Fee-for-Service-Part-B-Drugs/McrPartBDrugAvgSalesPrice/Downloads/2018-Oct-ASP-Pricing-File.zip
... A38: 2024-Q1 | B38: 2024 | C38: 1 | D38: =VALUE(B38)+(C38-1)/4 -> 2024 | E38: 4.188 | F38: 5.882 | H38: 17.845 | I38: 6.419 | J38: 9.803 | L38: 7.038 | M38: 3Q23 | N38: https://www.cms.gov/files/zip/january-2024-asp-pricing-file.zip
A39: 2024-Q2 | B39: 2024 | C39: 2 | D39: =VALUE(B39)+(C39-1)/4 -> 2024.25 | G39: 0.273 | H39: 18.459 | K39: 0.134 | M39: 4Q23 | N39: https://www.cms.gov/files/zip/april-2024-asp-pricing-file.zip
A40: 2024-Q3 | B40: 2024 | C40: 3 | D40: =VALUE(B40)+(C40-1)/4 -> 2024.5 | G40: 0.295 | H40: 19.853 | K40: 0.138 | M40: 1Q24 | N40: https://www.cms.gov/files/zip/july-2024-asp-pricing-file.zip
A41: 2024-Q4 | B41: 2024 | C41: 4 | D41: =VALUE(B41)+(C41-1)/4 -> 2024.75 | G41: 0.304 | H41: 19.397 | K41: 0.119 | M41: 2Q24 | N41: https://www.cms.gov/files/zip/october-2024-asp-pricing-file.zip
A42: 2025-Q1 | B42: 2025 | C42: 1 | D42: =VALUE(B42)+(C42-1)/4 -> 2025 | G42: 0.268 | H42: 20.939 | K42: 0.117 | M42: 3Q24 | N42: https://www.cms.gov/files/zip/january-2025-asp-pricing-file-03/11/25-final-file.zip
A43: 2025-Q2 | B43: 2025 | C43: 2 | D43: =VALUE(B43)+(C43-1)/4 -> 2025.25 | G43: 0.251 | H43: 20.58 | K43: 0.11 | M43: 4Q24 | N43: https://www.cms.gov/files/zip/april-2025-asp-pricing-file.zip
A44: 2025-Q3 | B44: 2025 | C44: 3 | D44: =VALUE(B44)+(C44-1)/4 -> 2025.5 | G44: 0.259 | H44: 21.201 | K44: 0.12 | M44: 1Q25 | N44: https://www.cms.gov/files/zip/july-2025-asp-pricing-file.zip
A45: 2025-Q4 | B45: 2025 | C45: 4 | D45: =VALUE(B45)+(C45-1)/4 -> 2025.75 | G45: 0.21 | H45: 21.312 | K45: 0.119 | M45: 2Q25 | N45: https://www.cms.gov/files/zip/october-2025-asp-pricing-final-file.zip
A46: 2026-Q1 | B46: 2026 | C46: 1 | D46: =VALUE(B46)+(C46-1)/4 -> 2026 | G46: 0.264 | H46: 22.061 | K46: 0.12 | M46: 3Q25 | N46: https://www.cms.gov/files/zip/january-2026-medicare-part-b-payment-limit-files.zip
A47: 2026-Q2 | B47: 2026 | C47: 2 | D47: =VALUE(B47)+(C47-1)/4 -> 2026.25 | G47: 0.241 | H47: 22.141 | K47: 0.112 | M47: 4Q25 | N47: https://www.cms.gov/files/zip/april-2026-medicare-part-b-payment-limit-files-final-file.zip
A48: 2026-Q3 | B48: 2026 | C48: 3 | D48: =VALUE(B48)+(C48-1)/4 -> 2026.5 | G48: 0.224 | H48: 23.056 | K48: 0.117 | M48: 1Q26 | N48: https://www.cms.gov/files/zip/july-2026-medicare-part-b-payment-limit-files.zip
A49: 2026-Q4 | B49: 2026 | C49: 4 | D49: =VALUE(B49)+(C49-1)/4 -> 2026.75 | G49: 0.255 | H49: 23.149 | K49: 0.123 | M49: 2Q26 | N49: https://www.cms.gov/files/zip/october-2026-medicare-part-b-payment-limit-files-final.zip

Sheet ASP_per_vial
A1: Implied ASP per vial (US$) = payment limit x billing units per vial / 1.06
A2: MPSS and MPA switch from the old to the new HCPCS code at the cutover quarter in Assumptions. Inputs: CMS_PL, Assumptions.
A5: Quarter | B5: Year | C5: Quarter index | D5: Code regime | E5: MPSS 40 mg | F5: MPSS 125 mg | G5: MPSS 500 mg | H5: MPSS 1 g | I5: MPSS 2 g | J5: HSS 100 mg | K5: HSS 250 mg (2.5 units) | L5: HSS 250 mg (3 units) | M5: HSS 500 mg | N5: HSS 1 g | O5: MPA 40 mg/mL 1 mL | P5: MPA 80 mg/mL 1 mL
A6: =CMS_PL!A6 -> 2016-Q1 | B6: =CMS_PL!B6 -> 2016 | C6: =CMS_PL!D6 -> 2016 | D6: =IF(C6>=Assumptions!$B$8,"New code","Old code") -> Old code | E6: =IF($C6>=Assumptions!$B$8,CMS_PL!G6*Assumptions!$E$22,CMS_PL!E6*Assumptions!$C$22)/Assumptions!$B$5 -> 2.7339623 | F6: =IF($C6>=Assumptions!$B$8,CMS_PL!G6*Assumptions!$E$23,CMS_PL!F6*Assumptions!$C$23)/Assumptions!$B$5 -> 3.8726415 | G6: =IF($C6>=Assumptions!$B$8,CMS_PL!G6*Assumptions!$E$24,CMS_PL!F6*Assumptions!$C$24)/Assumptions!$B$5 -> 15.490566 | H6: =IF($C6>=Assumptions!$B$8,CMS_PL!G6*Assumptions!$E$25,CMS_PL!F6*Assumptions!$C$25)/Assumptions!$B$5 -> 30.981132 | I6: =IF($C6>=Assumptions!$B$8,CMS_PL!G6*Assumptions!$E$26,CMS_PL!F6*Assumptions!$C$26)/Assumptions!$B$5 -> 61.962264 | J6: =IF($C6>=Assumptions!$B$8,CMS_PL!H6*Assumptions!$E$27,CMS_PL!H6*Assumptions!$C$27)/Assumptions!$B$5 -> 7.0773585 | K6: =IF($C6>=Assumptions!$B$8,CMS_PL!H6*Assumptions!$E$28,CMS_PL!H6*Assumptions!$C$28)/Assumptions!$B$5 -> 17.693396 | L6: =IF($C6>=Assumptions!$B$8,CMS_PL!H6*Assumptions!$E$29,CMS_PL!H6*Assumptions!$C$29)/Assumptions!$B$5 -> 21.232075 | M6: =IF($C6>=Assumptions!$B$8,CMS_PL!H6*Assumptions!$E$30,CMS_PL!H6*Assumptions!$C$30)/Assumptions!$B$5 -> 35.386792 | N6: =IF($C6>=Assumptions!$B$8,CMS_PL!H6*Assumptions!$E$31,CMS_PL!H6*Assumptions!$C$31)/Assumptions!$B$5 -> 70.773585 | O6: =IF($C6>=Assumptions!$B$8,CMS_PL!K6*Assumptions!$E$32,CMS_PL!I6*Assumptions!$C$32)/Assumptions!$B$5 -> 4.0641509 | P6: =IF($C6>=Assumptions!$B$8,CMS_PL!K6*Assumptions!$E$33,CMS_PL!J6*Assumptions!$C$33)/Assumptions!$B$5 -> 7.8622642
A7: =CMS_PL!A7 -> 2016-Q2 | B7: =CMS_PL!B7 -> 2016 | C7: =CMS_PL!D7 -> 2016.25 | D7: =IF(C7>=Assumptions!$B$8,"New code","Old code") -> Old code | E7: =IF($C7>=Assumptions!$B$8,CMS_PL!G7*Assumptions!$E$22,CMS_PL!E7*Assumptions!$C$22)/Assumptions!$B$5 -> 2.7877358 | F7: =IF($C7>=Assumptions!$B$8,CMS_PL!G7*Assumptions!$E$23,CMS_PL!F7*Assumptions!$C$23)/Assumptions!$B$5 -> 3.9745283 | G7: =IF($C7>=Assumptions!$B$8,CMS_PL!G7*Assumptions!$E$24,CMS_PL!F7*Assumptions!$C$24)/Assumptions!$B$5 -> 15.898113 | H7: =IF($C7>=Assumptions!$B$8,CMS_PL!G7*Assumptions!$E$25,CMS_PL!F7*Assumptions!$C$25)/Assumptions!$B$5 -> 31.796226 | I7: =IF($C7>=Assumptions!$B$8,CMS_PL!G7*Assumptions!$E$26,CMS_PL!F7*Assumptions!$C$26)/Assumptions!$B$5 -> 63.592453 | J7: =IF($C7>=Assumptions!$B$8,CMS_PL!H7*Assumptions!$E$27,CMS_PL!H7*Assumptions!$C$27)/Assumptions!$B$5 -> 7.0396226 | K7: =IF($C7>=Assumptions!$B$8,CMS_PL!H7*Assumptions!$E$28,CMS_PL!H7*Assumptions!$C$28)/Assumptions!$B$5 -> 17.599057 | L7: =IF($C7>=Assumptions!$B$8,CMS_PL!H7*Assumptions!$E$29,CMS_PL!H7*Assumptions!$C$29)/Assumptions!$B$5 -> 21.118868 | M7: =IF($C7>=Assumptions!$B$8,CMS_PL!H7*Assumptions!$E$30,CMS_PL!H7*Assumptions!$C$30)/Assumptions!$B$5 -> 35.198113 | N7: =IF($C7>=Assumptions!$B$8,CMS_PL!H7*Assumptions!$E$31,CMS_PL!H7*Assumptions!$C$31)/Assumptions!$B$5 -> 70.396226 | O7: =IF($C7>=Assumptions!$B$8,CMS_PL!K7*Assumptions!$E$32,CMS_PL!I7*Assumptions!$C$32)/Assumptions!$B$5 -> 4.2349057 | P7: =IF($C7>=Assumptions!$B$8,CMS_PL!K7*Assumptions!$E$33,CMS_PL!J7*Assumptions!$C$33)/Assumptions!$B$5 -> 8.0792453
A8: =CMS_PL!A8 -> 2016-Q3 | B8: =CMS_PL!B8 -> 2016 | C8: =CMS_PL!D8 -> 2016.5 | D8: =IF(C8>=Assumptions!$B$8,"New code","Old code") -> Old code | E8: =IF($C8>=Assumptions!$B$8,CMS_PL!G8*Assumptions!$E$22,CMS_PL!E8*Assumptions!$C$22)/Assumptions!$B$5 -> 3.1424528 | F8: =IF($C8>=Assumptions!$B$8,CMS_PL!G8*Assumptions!$E$23,CMS_PL!F8*Assumptions!$C$23)/Assumptions!$B$5 -> 4.6830189 | G8: =IF($C8>=Assumptions!$B$8,CMS_PL!G8*Assumptions!$E$24,CMS_PL!F8*Assumptions!$C$24)/Assumptions!$B$5 -> 18.732075 | H8: =IF($C8>=Assumptions!$B$8,CMS_PL!G8*Assumptions!$E$25,CMS_PL!F8*Assumptions!$C$25)/Assumptions!$B$5 -> 37.464151 | I8: =IF($C8>=Assumptions!$B$8,CMS_PL!G8*Assumptions!$E$26,CMS_PL!F8*Assumptions!$C$26)/Assumptions!$B$5 -> 74.928302 | J8: =IF($C8>=Assumptions!$B$8,CMS_PL!H8*Assumptions!$E$27,CMS_PL!H8*Assumptions!$C$27)/Assumptions!$B$5 -> 7.7009434 | K8: =IF($C8>=Assumptions!$B$8,CMS_PL!H8*Assumptions!$E$28,CMS_PL!H8*Assumptions!$C$28)/Assumptions!$B$5 -> 19.252358 | L8: =IF($C8>=Assumptions!$B$8,CMS_PL!H8*Assumptions!$E$29,CMS_PL!H8*Assumptions!$C$29)/Assumptions!$B$5 -> 23.10283 | M8: =IF($C8>=Assumptions!$B$8,CMS_PL!H8*Assumptions!$E$30,CMS_PL!H8*Assumptions!$C$30)/Assumptions!$B$5 -> 38.504717 | N8: =IF($C8>=Assumptions!$B$8,CMS_PL!H8*Assumptions!$E$31,CMS_PL!H8*Assumptions!$C$31)/Assumptions!$B$5 -> 77.009434 | O8: =IF($C8>=Assumptions!$B$8,CMS_PL!K8*Assumptions!$E$32,CMS_PL!I8*Assumptions!$C$32)/Assumptions!$B$5 -> 4.6735849 | P8: =IF($C8>=Assumptions!$B$8,CMS_PL!K8*Assumptions!$E$33,CMS_PL!J8*Assumptions!$C$33)/Assumptions!$B$5 -> 8.9415094
A9: =CMS_PL!A9 -> 2016-Q4 | B9: =CMS_PL!B9 -> 2016 | C9: =CMS_PL!D9 -> 2016.75 | D9: =IF(C9>=Assumptions!$B$8,"New code","Old code") -> Old code | E9: =IF($C9>=Assumptions!$B$8,CMS_PL!G9*Assumptions!$E$22,CMS_PL!E9*Assumptions!$C$22)/Assumptions!$B$5 -> 3.5150943 | F9: =IF($C9>=Assumptions!$B$8,CMS_PL!G9*Assumptions!$E$23,CMS_PL!F9*Assumptions!$C$23)/Assumptions!$B$5 -> 4.8358491 | G9: =IF($C9>=Assumptions!$B$8,CMS_PL!G9*Assumptions!$E$24,CMS_PL!F9*Assumptions!$C$24)/Assumptions!$B$5 -> 19.343396 | H9: =IF($C9>=Assumptions!$B$8,CMS_PL!G9*Assumptions!$E$25,CMS_PL!F9*Assumptions!$C$25)/Assumptions!$B$5 -> 38.686792 | I9: =IF($C9>=Assumptions!$B$8,CMS_PL!G9*Assumptions!$E$26,CMS_PL!F9*Assumptions!$C$26)/Assumptions!$B$5 -> 77.373585 | J9: =IF($C9>=Assumptions!$B$8,CMS_PL!H9*Assumptions!$E$27,CMS_PL!H9*Assumptions!$C$27)/Assumptions!$B$5 -> 8.0481132 | K9: =IF($C9>=Assumptions!$B$8,CMS_PL!H9*Assumptions!$E$28,CMS_PL!H9*Assumptions!$C$28)/Assumptions!$B$5 -> 20.120283 | L9: =IF($C9>=Assumptions!$B$8,CMS_PL!H9*Assumptions!$E$29,CMS_PL!H9*Assumptions!$C$29)/Assumptions!$B$5 -> 24.14434 | M9: =IF($C9>=Assumptions!$B$8,CMS_PL!H9*Assumptions!$E$30,CMS_PL!H9*Assumptions!$C$30)/Assumptions!$B$5 -> 40.240566 | N9: =IF($C9>=Assumptions!$B$8,CMS_PL!H9*Assumptions!$E$31,CMS_PL!H9*Assumptions!$C$31)/Assumptions!$B$5 -> 80.481132 | O9: =IF($C9>=Assumptions!$B$8,CMS_PL!K9*Assumptions!$E$32,CMS_PL!I9*Assumptions!$C$32)/Assumptions!$B$5 -> 4.9264151 | P9: =IF($C9>=Assumptions!$B$8,CMS_PL!K9*Assumptions!$E$33,CMS_PL!J9*Assumptions!$C$33)/Assumptions!$B$5 -> 9.245283
A10: =CMS_PL!A10 -> 2017-Q1 | B10: =CMS_PL!B10 -> 2017 | C10: =CMS_PL!D10 -> 2017 | D10: =IF(C10>=Assumptions!$B$8,"New code","Old code") -> Old code | E10: =IF($C10>=Assumptions!$B$8,CMS_PL!G10*Assumptions!$E$22,CMS_PL!E10*Assumptions!$C$22)/Assumptions!$B$5 -> 3.7754717 | F10: =IF($C10>=Assumptions!$B$8,CMS_PL!G10*Assumptions!$E$23,CMS_PL!F10*Assumptions!$C$23)/Assumptions!$B$5 -> 5.1867925 | G10: =IF($C10>=Assumptions!$B$8,CMS_PL!G10*Assumptions!$E$24,CMS_PL!F10*Assumptions!$C$24)/Assumptions!$B$5 -> 20.74717 | H10: =IF($C10>=Assumptions!$B$8,CMS_PL!G10*Assumptions!$E$25,CMS_PL!F10*Assumptions!$C$25)/Assumptions!$B$5 -> 41.49434 | I10: =IF($C10>=Assumptions!$B$8,CMS_PL!G10*Assumptions!$E$26,CMS_PL!F10*Assumptions!$C$26)/Assumptions!$B$5 -> 82.988679 | J10: =IF($C10>=Assumptions!$B$8,CMS_PL!H10*Assumptions!$E$27,CMS_PL!H10*Assumptions!$C$27)/Assumptions!$B$5 -> 8.6018868 | K10: =IF($C10>=Assumptions!$B$8,CMS_PL!H10*Assumptions!$E$28,CMS_PL!H10*Assumptions!$C$28)/Assumptions!$B$5 -> 21.504717 | L10: =IF($C10>=Assumptions!$B$8,CMS_PL!H10*Assumptions!$E$29,CMS_PL!H10*Assumptions!$C$29)/Assumptions!$B$5 -> 25.80566 | M10: =IF($C10>=Assumptions!$B$8,CMS_PL!H10*Assumptions!$E$30,CMS_PL!H10*Assumptions!$C$30)/Assumptions!$B$5 -> 43.009434 | N10: =IF($C10>=Assumptions!$B$8,CMS_PL!H10*Assumptions!$E$31,CMS_PL!H10*Assumptions!$C$31)/Assumptions!$B$5 -> 86.018868 | O10: =IF($C10>=Assumptions!$B$8,CMS_PL!K10*Assumptions!$E$32,CMS_PL!I10*Assumptions!$C$32)/Assumptions!$B$5 -> 5.1622642 | P10: =IF($C10>=Assumptions!$B$8,CMS_PL!K10*Assumptions!$E$33,CMS_PL!J10*Assumptions!$C$33)/Assumptions!$B$5 -> 9.6867925
A11: =CMS_PL!A11 -> 2017-Q2 | B11: =CMS_PL!B11 -> 2017 | C11: =CMS_PL!D11 -> 2017.25 | D11: =IF(C11>=Assumptions!$B$8,"New code","Old code") -> Old code | E11: =IF($C11>=Assumptions!$B$8,CMS_PL!G11*Assumptions!$E$22,CMS_PL!E11*Assumptions!$C$22)/Assumptions!$B$5 -> 3.8339623 | F11: =IF($C11>=Assumptions!$B$8,CMS_PL!G11*Assumptions!$E$23,CMS_PL!F11*Assumptions!$C$23)/Assumptions!$B$5 -> 5.2528302 | G11: =IF($C11>=Assumptions!$B$8,CMS_PL!G11*Assumptions!$E$24,CMS_PL!F11*Assumptions!$C$24)/Assumptions!$B$5 -> 21.011321 | H11: =IF($C11>=Assumptions!$B$8,CMS_PL!G11*Assumptions!$E$25,CMS_PL!F11*Assumptions!$C$25)/Assumptions!$B$5 -> 42.022642 | I11: =IF($C11>=Assumptions!$B$8,CMS_PL!G11*Assumptions!$E$26,CMS_PL!F11*Assumptions!$C$26)/Assumptions!$B$5 -> 84.045283 | J11: =IF($C11>=Assumptions!$B$8,CMS_PL!H11*Assumptions!$E$27,CMS_PL!H11*Assumptions!$C$27)/Assumptions!$B$5 -> 8.5226415 | K11: =IF($C11>=Assumptions!$B$8,CMS_PL!H11*Assumptions!$E$28,CMS_PL!H11*Assumptions!$C$28)/Assumptions!$B$5 -> 21.306604 | L11: =IF($C11>=Assumptions!$B$8,CMS_PL!H11*Assumptions!$E$29,CMS_PL!H11*Assumptions!$C$29)/Assumptions!$B$5 -> 25.567925 | M11: =IF($C11>=Assumptions!$B$8,CMS_PL!H11*Assumptions!$E$30,CMS_PL!H11*Assumptions!$C$30)/Assumptions!$B$5 -> 42.613208 | N11: =IF($C11>=Assumptions!$B$8,CMS_PL!H11*Assumptions!$E$31,CMS_PL!H11*Assumptions!$C$31)/Assumptions!$B$5 -> 85.226415 | O11: =IF($C11>=Assumptions!$B$8,CMS_PL!K11*Assumptions!$E$32,CMS_PL!I11*Assumptions!$C$32)/Assumptions!$B$5 -> 5.2528302 | P11: =IF($C11>=Assumptions!$B$8,CMS_PL!K11*Assumptions!$E$33,CMS_PL!J11*Assumptions!$C$33)/Assumptions!$B$5 -> 10.013208
A12: =CMS_PL!A12 -> 2017-Q3 | B12: =CMS_PL!B12 -> 2017 | C12: =CMS_PL!D12 -> 2017.5 | D12: =IF(C12>=Assumptions!$B$8,"New code","Old code") -> Old code | E12: =IF($C12>=Assumptions!$B$8,CMS_PL!G12*Assumptions!$E$22,CMS_PL!E12*Assumptions!$C$22)/Assumptions!$B$5 -> 4.1018868 | F12: =IF($C12>=Assumptions!$B$8,CMS_PL!G12*Assumptions!$E$23,CMS_PL!F12*Assumptions!$C$23)/Assumptions!$B$5 -> 5.6915094 | G12: =IF($C12>=Assumptions!$B$8,CMS_PL!G12*Assumptions!$E$24,CMS_PL!F12*Assumptions!$C$24)/Assumptions!$B$5 -> 22.766038 | H12: =IF($C12>=Assumptions!$B$8,CMS_PL!G12*Assumptions!$E$25,CMS_PL!F12*Assumptions!$C$25)/Assumptions!$B$5 -> 45.532075 | I12: =IF($C12>=Assumptions!$B$8,CMS_PL!G12*Assumptions!$E$26,CMS_PL!F12*Assumptions!$C$26)/Assumptions!$B$5 -> 91.064151 | J12: =IF($C12>=Assumptions!$B$8,CMS_PL!H12*Assumptions!$E$27,CMS_PL!H12*Assumptions!$C$27)/Assumptions!$B$5 -> 10.237736 | K12: =IF($C12>=Assumptions!$B$8,CMS_PL!H12*Assumptions!$E$28,CMS_PL!H12*Assumptions!$C$28)/Assumptions!$B$5 -> 25.59434 | L12: =IF($C12>=Assumptions!$B$8,CMS_PL!H12*Assumptions!$E$29,CMS_PL!H12*Assumptions!$C$29)/Assumptions!$B$5 -> 30.713208 | M12: =IF($C12>=Assumptions!$B$8,CMS_PL!H12*Assumptions!$E$30,CMS_PL!H12*Assumptions!$C$30)/Assumptions!$B$5 -> 51.188679 | N12: =IF($C12>=Assumptions!$B$8,CMS_PL!H12*Assumptions!$E$31,CMS_PL!H12*Assumptions!$C$31)/Assumptions!$B$5 -> 102.37736 | O12: =IF($C12>=Assumptions!$B$8,CMS_PL!K12*Assumptions!$E$32,CMS_PL!I12*Assumptions!$C$32)/Assumptions!$B$5 -> 5.6641509 | P12: =IF($C12>=Assumptions!$B$8,CMS_PL!K12*Assumptions!$E$33,CMS_PL!J12*Assumptions!$C$33)/Assumptions!$B$5 -> 10.877358
A13: =CMS_PL!A13 -> 2017-Q4 | B13: =CMS_PL!B13 -> 2017 | C13: =CMS_PL!D13 -> 2017.75 | D13: =IF(C13>=Assumptions!$B$8,"New code","Old code") -> Old code | E13: =IF($C13>=Assumptions!$B$8,CMS_PL!G13*Assumptions!$E$22,CMS_PL!E13*Assumptions!$C$22)/Assumptions!$B$5 -> 4.0915094 | F13: =IF($C13>=Assumptions!$B$8,CMS_PL!G13*Assumptions!$E$23,CMS_PL!F13*Assumptions!$C$23)/Assumptions!$B$5 -> 5.7481132 | G13: =IF($C13>=Assumptions!$B$8,CMS_PL!G13*Assumptions!$E$24,CMS_PL!F13*Assumptions!$C$24)/Assumptions!$B$5 -> 22.992453 | H13: =IF($C13>=Assumptions!$B$8,CMS_PL!G13*Assumptions!$E$25,CMS_PL!F13*Assumptions!$C$25)/Assumptions!$B$5 -> 45.984906 | I13: =IF($C13>=Assumptions!$B$8,CMS_PL!G13*Assumptions!$E$26,CMS_PL!F13*Assumptions!$C$26)/Assumptions!$B$5 -> 91.969811 | J13: =IF($C13>=Assumptions!$B$8,CMS_PL!H13*Assumptions!$E$27,CMS_PL!H13*Assumptions!$C$27)/Assumptions!$B$5 -> 10.640566 | K13: =IF($C13>=Assumptions!$B$8,CMS_PL!H13*Assumptions!$E$28,CMS_PL!H13*Assumptions!$C$28)/Assumptions!$B$5 -> 26.601415 | L13: =IF($C13>=Assumptions!$B$8,CMS_PL!H13*Assumptions!$E$29,CMS_PL!H13*Assumptions!$C$29)/Assumptions!$B$5 -> 31.921698 | M13: =IF($C13>=Assumptions!$B$8,CMS_PL!H13*Assumptions!$E$30,CMS_PL!H13*Assumptions!$C$30)/Assumptions!$B$5 -> 53.20283 | N13: =IF($C13>=Assumptions!$B$8,CMS_PL!H13*Assumptions!$E$31,CMS_PL!H13*Assumptions!$C$31)/Assumptions!$B$5 -> 106.40566 | O13: =IF($C13>=Assumptions!$B$8,CMS_PL!K13*Assumptions!$E$32,CMS_PL!I13*Assumptions!$C$32)/Assumptions!$B$5 -> 6.0018868 | P13: =IF($C13>=Assumptions!$B$8,CMS_PL!K13*Assumptions!$E$33,CMS_PL!J13*Assumptions!$C$33)/Assumptions!$B$5 -> 11.566038
A14: =CMS_PL!A14 -> 2018-Q1 | B14: =CMS_PL!B14 -> 2018 | C14: =CMS_PL!D14 -> 2018 | D14: =IF(C14>=Assumptions!$B$8,"New code","Old code") -> Old code | E14: =IF($C14>=Assumptions!$B$8,CMS_PL!G14*Assumptions!$E$22,CMS_PL!E14*Assumptions!$C$22)/Assumptions!$B$5 -> 4.1 | F14: =IF($C14>=Assumptions!$B$8,CMS_PL!G14*Assumptions!$E$23,CMS_PL!F14*Assumptions!$C$23)/Assumptions!$B$5 -> 5.6462264 | G14: =IF($C14>=Assumptions!$B$8,CMS_PL!G14*Assumptions!$E$24,CMS_PL!F14*Assumptions!$C$24)/Assumptions!$B$5 -> 22.584906 | H14: =IF($C14>=Assumptions!$B$8,CMS_PL!G14*Assumptions!$E$25,CMS_PL!F14*Assumptions!$C$25)/Assumptions!$B$5 -> 45.169811 | I14: =IF($C14>=Assumptions!$B$8,CMS_PL!G14*Assumptions!$E$26,CMS_PL!F14*Assumptions!$C$26)/Assumptions!$B$5 -> 90.339623 | J14: =IF($C14>=Assumptions!$B$8,CMS_PL!H14*Assumptions!$E$27,CMS_PL!H14*Assumptions!$C$27)/Assumptions!$B$5 -> 11.25566 | K14: =IF($C14>=Assumptions!$B$8,CMS_PL!H14*Assumptions!$E$28,CMS_PL!H14*Assumptions!$C$28)/Assumptions!$B$5 -> 28.139151 | L14: =IF($C14>=Assumptions!$B$8,CMS_PL!H14*Assumptions!$E$29,CMS_PL!H14*Assumptions!$C$29)/Assumptions!$B$5 -> 33.766981 | M14: =IF($C14>=Assumptions!$B$8,CMS_PL!H14*Assumptions!$E$30,CMS_PL!H14*Assumptions!$C$30)/Assumptions!$B$5 -> 56.278302 | N14: =IF($C14>=Assumptions!$B$8,CMS_PL!H14*Assumptions!$E$31,CMS_PL!H14*Assumptions!$C$31)/Assumptions!$B$5 -> 112.5566 | O14: =IF($C14>=Assumptions!$B$8,CMS_PL!K14*Assumptions!$E$32,CMS_PL!I14*Assumptions!$C$32)/Assumptions!$B$5 -> 6.3150943 | P14: =IF($C14>=Assumptions!$B$8,CMS_PL!K14*Assumptions!$E$33,CMS_PL!J14*Assumptions!$C$33)/Assumptions!$B$5 -> 12.229245
A15: =CMS_PL!A15 -> 2018-Q2 | B15: =CMS_PL!B15 -> 2018 | C15: =CMS_PL!D15 -> 2018.25 | D15: =IF(C15>=Assumptions!$B$8,"New code","Old code") -> Old code | E15: =IF($C15>=Assumptions!$B$8,CMS_PL!G15*Assumptions!$E$22,CMS_PL!E15*Assumptions!$C$22)/Assumptions!$B$5 -> 4.2801887 | F15: =IF($C15>=Assumptions!$B$8,CMS_PL!G15*Assumptions!$E$23,CMS_PL!F15*Assumptions!$C$23)/Assumptions!$B$5 -> 6.2943396 | G15: =IF($C15>=Assumptions!$B$8,CMS_PL!G15*Assumptions!$E$24,CMS_PL!F15*Assumptions!$C$24)/Assumptions!$B$5 -> 25.177358 | H15: =IF($C15>=Assumptions!$B$8,CMS_PL!G15*Assumptions!$E$25,CMS_PL!F15*Assumptions!$C$25)/Assumptions!$B$5 -> 50.354717 | I15: =IF($C15>=Assumptions!$B$8,CMS_PL!G15*Assumptions!$E$26,CMS_PL!F15*Assumptions!$C$26)/Assumptions!$B$5 -> 100.70943 | J15: =IF($C15>=Assumptions!$B$8,CMS_PL!H15*Assumptions!$E$27,CMS_PL!H15*Assumptions!$C$27)/Assumptions!$B$5 -> 11.367925 | K15: =IF($C15>=Assumptions!$B$8,CMS_PL!H15*Assumptions!$E$28,CMS_PL!H15*Assumptions!$C$28)/Assumptions!$B$5 -> 28.419811 | L15: =IF($C15>=Assumptions!$B$8,CMS_PL!H15*Assumptions!$E$29,CMS_PL!H15*Assumptions!$C$29)/Assumptions!$B$5 -> 34.103774 | M15: =IF($C15>=Assumptions!$B$8,CMS_PL!H15*Assumptions!$E$30,CMS_PL!H15*Assumptions!$C$30)/Assumptions!$B$5 -> 56.839623 | N15: =IF($C15>=Assumptions!$B$8,CMS_PL!H15*Assumptions!$E$31,CMS_PL!H15*Assumptions!$C$31)/Assumptions!$B$5 -> 113.67925 | O15: =IF($C15>=Assumptions!$B$8,CMS_PL!K15*Assumptions!$E$32,CMS_PL!I15*Assumptions!$C$32)/Assumptions!$B$5 -> 6.2622642 | P15: =IF($C15>=Assumptions!$B$8,CMS_PL!K15*Assumptions!$E$33,CMS_PL!J15*Assumptions!$C$33)/Assumptions!$B$5 -> 12.178302
A16: =CMS_PL!A16 -> 2018-Q3 | B16: =CMS_PL!B16 -> 2018 | C16: =CMS_PL!D16 -> 2018.5 | D16: =IF(C16>=Assumptions!$B$8,"New code","Old code") -> Old code | E16: =IF($C16>=Assumptions!$B$8,CMS_PL!G16*Assumptions!$E$22,CMS_PL!E16*Assumptions!$C$22)/Assumptions!$B$5 -> 4.5330189 | F16: =IF($C16>=Assumptions!$B$8,CMS_PL!G16*Assumptions!$E$23,CMS_PL!F16*Assumptions!$C$23)/Assumptions!$B$5 -> 6.5707547 | G16: =IF($C16>=Assumptions!$B$8,CMS_PL!G16*Assumptions!$E$24,CMS_PL!F16*Assumptions!$C$24)/Assumptions!$B$5 -> 26.283019 | H16: =IF($C16>=Assumptions!$B$8,CMS_PL!G16*Assumptions!$E$25,CMS_PL!F16*Assumptions!$C$25)/Assumptions!$B$5 -> 52.566038 | I16: =IF($C16>=Assumptions!$B$8,CMS_PL!G16*Assumptions!$E$26,CMS_PL!F16*Assumptions!$C$26)/Assumptions!$B$5 -> 105.13208 | J16: =IF($C16>=Assumptions!$B$8,CMS_PL!H16*Assumptions!$E$27,CMS_PL!H16*Assumptions!$C$27)/Assumptions!$B$5 -> 12.431132 | K16: =IF($C16>=Assumptions!$B$8,CMS_PL!H16*Assumptions!$E$28,CMS_PL!H16*Assumptions!$C$28)/Assumptions!$B$5 -> 31.07783 | L16: =IF($C16>=Assumptions!$B$8,CMS_PL!H16*Assumptions!$E$29,CMS_PL!H16*Assumptions!$C$29)/Assumptions!$B$5 -> 37.293396 | M16: =IF($C16>=Assumptions!$B$8,CMS_PL!H16*Assumptions!$E$30,CMS_PL!H16*Assumptions!$C$30)/Assumptions!$B$5 -> 62.15566 | N16: =IF($C16>=Assumptions!$B$8,CMS_PL!H16*Assumptions!$E$31,CMS_PL!H16*Assumptions!$C$31)/Assumptions!$B$5 -> 124.31132 | O16: =IF($C16>=Assumptions!$B$8,CMS_PL!K16*Assumptions!$E$32,CMS_PL!I16*Assumptions!$C$32)/Assumptions!$B$5 -> 6.604717 | P16: =IF($C16>=Assumptions!$B$8,CMS_PL!K16*Assumptions!$E$33,CMS_PL!J16*Assumptions!$C$33)/Assumptions!$B$5 -> 12.745283
A17: =CMS_PL!A17 -> 2018-Q4 | B17: =CMS_PL!B17 -> 2018 | C17: =CMS_PL!D17 -> 2018.75 | D17: =IF(C17>=Assumptions!$B$8,"New code","Old code") -> Old code | E17: =IF($C17>=Assumptions!$B$8,CMS_PL!G17*Assumptions!$E$22,CMS_PL!E17*Assumptions!$C$22)/Assumptions!$B$5 -> 4.45 | F17: =IF($C17>=Assumptions!$B$8,CMS_PL!G17*Assumptions!$E$23,CMS_PL!F17*Assumptions!$C$23)/Assumptions!$B$5 -> 6.5490566 | G17: =IF($C17>=Assumptions!$B$8,CMS_PL!G17*Assumptions!$E$24,CMS_PL!F17*Assumptions!$C$24)/Assumptions!$B$5 -> 26.196226 | H17: =IF($C17>=Assumptions!$B$8,CMS_PL!G17*Assumptions!$E$25,CMS_PL!F17*Assumptions!$C$25)/Assumptions!$B$5 -> 52.392453 | I17: =IF($C17>=Assumptions!$B$8,CMS_PL!G17*Assumptions!$E$26,CMS_PL!F17*Assumptions!$C$26)/Assumptions!$B$5 -> 104.78491 | J17: =IF($C17>=Assumptions!$B$8,CMS_PL!H17*Assumptions!$E$27,CMS_PL!H17*Assumptions!$C$27)/Assumptions!$B$5 -> 12.312264 | K17: =IF($C17>=Assumptions!$B$8,CMS_PL!H17*Assumptions!$E$28,CMS_PL!H17*Assumptions!$C$28)/Assumptions!$B$5 -> 30.78066 | L17: =IF($C17>=Assumptions!$B$8,CMS_PL!H17*Assumptions!$E$29,CMS_PL!H17*Assumptions!$C$29)/Assumptions!$B$5 -> 36.936792 | M17: =IF($C17>=Assumptions!$B$8,CMS_PL!H17*Assumptions!$E$30,CMS_PL!H17*Assumptions!$C$30)/Assumptions!$B$5 -> 61.561321 | N17: =IF($C17>=Assumptions!$B$8,CMS_PL!H17*Assumptions!$E$31,CMS_PL!H17*Assumptions!$C$31)/Assumptions!$B$5 -> 123.12264 | O17: =IF($C17>=Assumptions!$B$8,CMS_PL!K17*Assumptions!$E$32,CMS_PL!I17*Assumptions!$C$32)/Assumptions!$B$5 -> 6.3896226 | P17: =IF($C17>=Assumptions!$B$8,CMS_PL!K17*Assumptions!$E$33,CMS_PL!J17*Assumptions!$C$33)/Assumptions!$B$5 -> 12.566981
... A49: =CMS_PL!A49 -> 2026-Q4 | B49: =CMS_PL!B49 -> 2026 | C49: =CMS_PL!D49 -> 2026.75 | D49: =IF(C49>=Assumptions!$B$8,"New code","Old code") -> New code | E49: =IF($C49>=Assumptions!$B$8,CMS_PL!G49*Assumptions!$E$22,CMS_PL!E49*Assumptions!$C$22)/Assumptions!$B$5 -> 1.9245283 | F49: =IF($C49>=Assumptions!$B$8,CMS_PL!G49*Assumptions!$E$23,CMS_PL!F49*Assumptions!$C$23)/Assumptions!$B$5 -> 6.0141509 | G49: =IF($C49>=Assumptions!$B$8,CMS_PL!G49*Assumptions!$E$24,CMS_PL!F49*Assumptions!$C$24)/Assumptions!$B$5 -> 24.056604 | H49: =IF($C49>=Assumptions!$B$8,CMS_PL!G49*Assumptions!$E$25,CMS_PL!F49*Assumptions!$C$25)/Assumptions!$B$5 -> 48.113208 | I49: =IF($C49>=Assumptions!$B$8,CMS_PL!G49*Assumptions!$E$26,CMS_PL!F49*Assumptions!$C$26)/Assumptions!$B$5 -> 96.226415 | J49: =IF($C49>=Assumptions!$B$8,CMS_PL!H49*Assumptions!$E$27,CMS_PL!H49*Assumptions!$C$27)/Assumptions!$B$5 -> 21.838679 | K49: =IF($C49>=Assumptions!$B$8,CMS_PL!H49*Assumptions!$E$28,CMS_PL!H49*Assumptions!$C$28)/Assumptions!$B$5 -> 54.596698 | L49: =IF($C49>=Assumptions!$B$8,CMS_PL!H49*Assumptions!$E$29,CMS_PL!H49*Assumptions!$C$29)/Assumptions!$B$5 -> 65.516038 | M49: =IF($C49>=Assumptions!$B$8,CMS_PL!H49*Assumptions!$E$30,CMS_PL!H49*Assumptions!$C$30)/Assumptions!$B$5 -> 109.1934 | N49: =IF($C49>=Assumptions!$B$8,CMS_PL!H49*Assumptions!$E$31,CMS_PL!H49*Assumptions!$C$31)/Assumptions!$B$5 -> 218.38679 | O49: =IF($C49>=Assumptions!$B$8,CMS_PL!K49*Assumptions!$E$32,CMS_PL!I49*Assumptions!$C$32)/Assumptions!$B$5 -> 4.6415094 | P49: =IF($C49>=Assumptions!$B$8,CMS_PL!K49*Assumptions!$E$33,CMS_PL!J49*Assumptions!$C$33)/Assumptions!$B$5 -> 9.2830189
A52: Annual average implied ASP per vial (mean of the quarterly files effective in each year). 2024 blends Q1 old code with Q2-Q4 new code.
A53: Year | E53: MPSS 40 mg | F53: MPSS 125 mg | G53: MPSS 500 mg | H53: MPSS 1 g | I53: MPSS 2 g | J53: HSS 100 mg | K53: HSS 250 mg (2.5 units) | L53: HSS 250 mg (3 units) | M53: HSS 500 mg | N53: HSS 1 g | O53: MPA 40 mg/mL 1 mL | P53: MPA 80 mg/mL 1 mL
A54: 2016 | E54: =AVERAGEIFS(E$6:E$49,$B$6:$B$49,$A54) -> 3.0448113 | F54: =AVERAGEIFS(F$6:F$49,$B$6:$B$49,$A54) -> 4.3415094 | G54: =AVERAGEIFS(G$6:G$49,$B$6:$B$49,$A54) -> 17.366038 | H54: =AVERAGEIFS(H$6:H$49,$B$6:$B$49,$A54) -> 34.732075 | I54: =AVERAGEIFS(I$6:I$49,$B$6:$B$49,$A54) -> 69.464151 | J54: =AVERAGEIFS(J$6:J$49,$B$6:$B$49,$A54) -> 7.4665094 | K54: =AVERAGEIFS(K$6:K$49,$B$6:$B$49,$A54) -> 18.666274 | L54: =AVERAGEIFS(L$6:L$49,$B$6:$B$49,$A54) -> 22.399528 | ... P54: =AVERAGEIFS(P$6:P$49,$B$6:$B$49,$A54) -> 8.5320755
A55: 2017 | E55: =AVERAGEIFS(E$6:E$49,$B$6:$B$49,$A55) -> 3.9507075 | F55: =AVERAGEIFS(F$6:F$49,$B$6:$B$49,$A55) -> 5.4698113 | G55: =AVERAGEIFS(G$6:G$49,$B$6:$B$49,$A55) -> 21.879245 | H55: =AVERAGEIFS(H$6:H$49,$B$6:$B$49,$A55) -> 43.758491 | I55: =AVERAGEIFS(I$6:I$49,$B$6:$B$49,$A55) -> 87.516981 | J55: =AVERAGEIFS(J$6:J$49,$B$6:$B$49,$A55) -> 9.5007075 | K55: =AVERAGEIFS(K$6:K$49,$B$6:$B$49,$A55) -> 23.751769 | L55: =AVERAGEIFS(L$6:L$49,$B$6:$B$49,$A55) -> 28.502123 | ... P55: =AVERAGEIFS(P$6:P$49,$B$6:$B$49,$A55) -> 10.535849
A56: 2018 | E56: =AVERAGEIFS(E$6:E$49,$B$6:$B$49,$A56) -> 4.3408019 | F56: =AVERAGEIFS(F$6:F$49,$B$6:$B$49,$A56) -> 6.2650943 | G56: =AVERAGEIFS(G$6:G$49,$B$6:$B$49,$A56) -> 25.060377 | H56: =AVERAGEIFS(H$6:H$49,$B$6:$B$49,$A56) -> 50.120755 | I56: =AVERAGEIFS(I$6:I$49,$B$6:$B$49,$A56) -> 100.24151 | J56: =AVERAGEIFS(J$6:J$49,$B$6:$B$49,$A56) -> 11.841745 | K56: =AVERAGEIFS(K$6:K$49,$B$6:$B$49,$A56) -> 29.604363 | L56: =AVERAGEIFS(L$6:L$49,$B$6:$B$49,$A56) -> 35.525236 | ... P56: =AVERAGEIFS(P$6:P$49,$B$6:$B$49,$A56) -> 12.429953
A57: 2019 | E57: =AVERAGEIFS(E$6:E$49,$B$6:$B$49,$A57) -> 4.3188679 | F57: =AVERAGEIFS(F$6:F$49,$B$6:$B$49,$A57) -> 6.0323113 | G57: =AVERAGEIFS(G$6:G$49,$B$6:$B$49,$A57) -> 24.129245 | H57: =AVERAGEIFS(H$6:H$49,$B$6:$B$49,$A57) -> 48.258491 | I57: =AVERAGEIFS(I$6:I$49,$B$6:$B$49,$A57) -> 96.516981 | J57: =AVERAGEIFS(J$6:J$49,$B$6:$B$49,$A57) -> 12.258726 | K57: =AVERAGEIFS(K$6:K$49,$B$6:$B$49,$A57) -> 30.646816 | L57: =AVERAGEIFS(L$6:L$49,$B$6:$B$49,$A57) -> 36.776179 | ... P57: =AVERAGEIFS(P$6:P$49,$B$6:$B$49,$A57) -> 11.62783
A58: 2020 | E58: =AVERAGEIFS(E$6:E$49,$B$6:$B$49,$A58) -> 4.1856132 | F58: =AVERAGEIFS(F$6:F$49,$B$6:$B$49,$A58) -> 5.9106132 | G58: =AVERAGEIFS(G$6:G$49,$B$6:$B$49,$A58) -> 23.642453 | H58: =AVERAGEIFS(H$6:H$49,$B$6:$B$49,$A58) -> 47.284906 | I58: =AVERAGEIFS(I$6:I$49,$B$6:$B$49,$A58) -> 94.569811 | J58: =AVERAGEIFS(J$6:J$49,$B$6:$B$49,$A58) -> 12.792217 | K58: =AVERAGEIFS(K$6:K$49,$B$6:$B$49,$A58) -> 31.980542 | L58: =AVERAGEIFS(L$6:L$49,$B$6:$B$49,$A58) -> 38.376651 | ... P58: =AVERAGEIFS(P$6:P$49,$B$6:$B$49,$A58) -> 10.94717
A59: 2021 | E59: =AVERAGEIFS(E$6:E$49,$B$6:$B$49,$A59) -> 3.9591981 | F59: =AVERAGEIFS(F$6:F$49,$B$6:$B$49,$A59) -> 5.259434 | G59: =AVERAGEIFS(G$6:G$49,$B$6:$B$49,$A59) -> 21.037736 | H59: =AVERAGEIFS(H$6:H$49,$B$6:$B$49,$A59) -> 42.075472 | I59: =AVERAGEIFS(I$6:I$49,$B$6:$B$49,$A59) -> 84.150943 | J59: =AVERAGEIFS(J$6:J$49,$B$6:$B$49,$A59) -> 13.666509 | K59: =AVERAGEIFS(K$6:K$49,$B$6:$B$49,$A59) -> 34.166274 | L59: =AVERAGEIFS(L$6:L$49,$B$6:$B$49,$A59) -> 40.999528 | ... P59: =AVERAGEIFS(P$6:P$49,$B$6:$B$49,$A59) -> 10.042689
A60: 2022 | E60: =AVERAGEIFS(E$6:E$49,$B$6:$B$49,$A60) -> 3.9938679 | F60: =AVERAGEIFS(F$6:F$49,$B$6:$B$49,$A60) -> 5.4896226 | G60: =AVERAGEIFS(G$6:G$49,$B$6:$B$49,$A60) -> 21.958491 | H60: =AVERAGEIFS(H$6:H$49,$B$6:$B$49,$A60) -> 43.916981 | I60: =AVERAGEIFS(I$6:I$49,$B$6:$B$49,$A60) -> 87.833962 | J60: =AVERAGEIFS(J$6:J$49,$B$6:$B$49,$A60) -> 15.318868 | K60: =AVERAGEIFS(K$6:K$49,$B$6:$B$49,$A60) -> 38.29717 | L60: =AVERAGEIFS(L$6:L$49,$B$6:$B$49,$A60) -> 45.956604 | ... P60: =AVERAGEIFS(P$6:P$49,$B$6:$B$49,$A60) -> 10.465566
A61: 2023 | E61: =AVERAGEIFS(E$6:E$49,$B$6:$B$49,$A61) -> 3.745283 | F61: =AVERAGEIFS(F$6:F$49,$B$6:$B$49,$A61) -> 5.2183962 | G61: =AVERAGEIFS(G$6:G$49,$B$6:$B$49,$A61) -> 20.873585 | H61: =AVERAGEIFS(H$6:H$49,$B$6:$B$49,$A61) -> 41.74717 | I61: =AVERAGEIFS(I$6:I$49,$B$6:$B$49,$A61) -> 83.49434 | J61: =AVERAGEIFS(J$6:J$49,$B$6:$B$49,$A61) -> 16.740094 | K61: =AVERAGEIFS(K$6:K$49,$B$6:$B$49,$A61) -> 41.850236 | L61: =AVERAGEIFS(L$6:L$49,$B$6:$B$49,$A61) -> 50.220283 | ... P61: =AVERAGEIFS(P$6:P$49,$B$6:$B$49,$A61) -> 11.233726
A62: 2024 | E62: =AVERAGEIFS(E$6:E$49,$B$6:$B$49,$A62) -> 2.6330189 | F62: =AVERAGEIFS(F$6:F$49,$B$6:$B$49,$A62) -> 6.5287736 | G62: =AVERAGEIFS(G$6:G$49,$B$6:$B$49,$A62) -> 26.115094 | H62: =AVERAGEIFS(H$6:H$49,$B$6:$B$49,$A62) -> 52.230189 | I62: =AVERAGEIFS(I$6:I$49,$B$6:$B$49,$A62) -> 104.46038 | J62: =AVERAGEIFS(J$6:J$49,$B$6:$B$49,$A62) -> 17.81934 | K62: =AVERAGEIFS(K$6:K$49,$B$6:$B$49,$A62) -> 44.548349 | L62: =AVERAGEIFS(L$6:L$49,$B$6:$B$49,$A62) -> 53.458019 | ... P62: =AVERAGEIFS(P$6:P$49,$B$6:$B$49,$A62) -> 9.6893868
A63: 2025 | E63: =AVERAGEIFS(E$6:E$49,$B$6:$B$49,$A63) -> 1.8641509 | F63: =AVERAGEIFS(F$6:F$49,$B$6:$B$49,$A63) -> 5.8254717 | G63: =AVERAGEIFS(G$6:G$49,$B$6:$B$49,$A63) -> 23.301887 | H63: =AVERAGEIFS(H$6:H$49,$B$6:$B$49,$A63) -> 46.603774 | I63: =AVERAGEIFS(I$6:I$49,$B$6:$B$49,$A63) -> 93.207547 | J63: =AVERAGEIFS(J$6:J$49,$B$6:$B$49,$A63) -> 19.818868 | K63: =AVERAGEIFS(K$6:K$49,$B$6:$B$49,$A63) -> 49.54717 | L63: =AVERAGEIFS(L$6:L$49,$B$6:$B$49,$A63) -> 59.456604 | ... P63: =AVERAGEIFS(P$6:P$49,$B$6:$B$49,$A63) -> 8.7924528
A64: 2026 | E64: =AVERAGEIFS(E$6:E$49,$B$6:$B$49,$A64) -> 1.8566038 | F64: =AVERAGEIFS(F$6:F$49,$B$6:$B$49,$A64) -> 5.8018868 | G64: =AVERAGEIFS(G$6:G$49,$B$6:$B$49,$A64) -> 23.207547 | H64: =AVERAGEIFS(H$6:H$49,$B$6:$B$49,$A64) -> 46.415094 | I64: =AVERAGEIFS(I$6:I$49,$B$6:$B$49,$A64) -> 92.830189 | J64: =AVERAGEIFS(J$6:J$49,$B$6:$B$49,$A64) -> 21.322406 | K64: =AVERAGEIFS(K$6:K$49,$B$6:$B$49,$A64) -> 53.306014 | L64: =AVERAGEIFS(L$6:L$49,$B$6:$B$49,$A64) -> 63.967217 | ... P64: =AVERAGEIFS(P$6:P$49,$B$6:$B$49,$A64) -> 8.9056604

Sheet ASP_growth
A1: ASP growth: peaks, changes and CAGRs per vial
A2: All values look up ASP_per_vial. Row 4 holds the quarter looked up in each column; row 3 its quarter index.
A3: Quarter index | B3: =INDEX(CMS_PL!$D$6:$D$49,MATCH(B4,CMS_PL!$A$6:$A$49,0)) -> 2016 | C3: =INDEX(CMS_PL!$D$6:$D$49,MATCH(C4,CMS_PL!$A$6:$A$49,0)) -> 2018.5 | D3: =INDEX(CMS_PL!$D$6:$D$49,MATCH(D4,CMS_PL!$A$6:$A$49,0)) -> 2021.75 | E3: =INDEX(CMS_PL!$D$6:$D$49,MATCH(E4,CMS_PL!$A$6:$A$49,0)) -> 2023.75 | F3: =INDEX(CMS_PL!$D$6:$D$49,MATCH(F4,CMS_PL!$A$6:$A$49,0)) -> 2024 | G3: =INDEX(CMS_PL!$D$6:$D$49,MATCH(G4,CMS_PL!$A$6:$A$49,0)) -> 2024.25 | H3: =INDEX(CMS_PL!$D$6:$D$49,MATCH(H4,CMS_PL!$A$6:$A$49,0)) -> 2025.75 | I3: =INDEX(CMS_PL!$D$6:$D$49,MATCH(I4,CMS_PL!$A$6:$A$49,0)) -> 2026.75
A4: Quarter looked up | B4: 2016-Q1 | C4: 2018-Q3 | D4: 2021-Q4 | E4: 2023-Q4 | F4: 2024-Q1 | G4: 2024-Q2 | H4: 2025-Q4 | I4: 2026-Q4
A5: Vial | B5: ASP 2016-Q1 | C5: ASP 2018-Q3 | D5: ASP 2021-Q4 | E5: ASP 2023-Q4 | F5: ASP 2024-Q1 | G5: ASP 2024-Q2 | H5: ASP 2025-Q4 | I5: ASP 2026-Q4 | J5: Peak ASP | K5: Peak quarter | L5: 1y change (Q4'25 to Q4'26) | M5: 3y CAGR (Q4'23 to Q4'26) | N5: 5y CAGR (Q4'21 to Q4'26) | O5: CAGR Q1'16 to Q4'26 | P5: Change Q1'16 to Q3'18 | Q5: Change Q2'24 to Q4'26 (new code) | R5: Note | S5: Peak, old code (to Q1 2024) | T5: Quarter of old-code peak | U5: Peak, new code (from Q2 2024) | V5: Quarter of new-code peak
A6: MPSS 40 mg | B6: =INDEX(ASP_per_vial!$E$6:$P$49,MATCH(B$4,ASP_per_vial!$A$6:$A$49,0),MATCH($A6,ASP_per_vial!$E$5:$P$5,0)) -> 2.7339623 | C6: =INDEX(ASP_per_vial!$E$6:$P$49,MATCH(C$4,ASP_per_vial!$A$6:$A$49,0),MATCH($A6,ASP_per_vial!$E$5:$P$5,0)) -> 4.5330189 | D6: =INDEX(ASP_per_vial!$E$6:$P$49,MATCH(D$4,ASP_per_vial!$A$6:$A$49,0),MATCH($A6,ASP_per_vial!$E$5:$P$5,0)) -> 3.8754717 | E6: =INDEX(ASP_per_vial!$E$6:$P$49,MATCH(E$4,ASP_per_vial!$A$6:$A$49,0),MATCH($A6,ASP_per_vial!$E$5:$P$5,0)) -> 3.2386792 | F6: =INDEX(ASP_per_vial!$E$6:$P$49,MATCH(F$4,ASP_per_vial!$A$6:$A$49,0),MATCH($A6,ASP_per_vial!$E$5:$P$5,0)) -> 3.9509434 | G6: =INDEX(ASP_per_vial!$E$6:$P$49,MATCH(G$4,ASP_per_vial!$A$6:$A$49,0),MATCH($A6,ASP_per_vial!$E$5:$P$5,0)) -> 2.0603774 | H6: =INDEX(ASP_per_vial!$E$6:$P$49,MATCH(H$4,ASP_per_vial!$A$6:$A$49,0),MATCH($A6,ASP_per_vial!$E$5:$P$5,0)) -> 1.5849057 | I6: =INDEX(ASP_per_vial!$E$6:$P$49,MATCH(I$4,ASP_per_vial!$A$6:$A$49,0),MATCH($A6,ASP_per_vial!$E$5:$P$5,0)) -> 1.9245283 | J6: =MAX(INDEX(ASP_per_vial!$E$6:$P$49,0,MATCH($A6,ASP_per_vial!$E$5:$P$5,0))) -> 4.5962264 | K6: =INDEX(ASP_per_vial!$A$6:$A$49,MATCH(J6,INDEX(ASP_per_vial!$E$6:$P$49,0,MATCH($A6,ASP_per_vial!$E$5:$P$5,0)),0)) -> 2019-Q1 | L6: =I6/H6-1 -> 0.21428571 | M6: =(I6/E6)^(1/(I$3-E$3))-1 -> -0.15927856 | N6: =(I6/D6)^(1/(I$3-D$3))-1 -> -0.13063941 | O6: =(I6/B6)^(1/(I$3-B$3))-1 -> -0.032130264 | P6: =C6/B6-1 -> 0.65804003 | Q6: =I6/G6-1 -> -0.065934066 | R6: Windows before Q2 2024 cross the code change | S6: =_xlfn.MAXIFS(INDEX(ASP_per_vial!$E$6:$P$49,0,MATCH($A6,ASP_per_vial!$E$5:$P$5,0)),ASP_per_vial!$C$6:$C$49,"<"&Assumptions!$B$8) -> 4.5962264 | T6: =INDEX(ASP_per_vial!$A$6:$A$49,MATCH(S6,INDEX(ASP_per_vial!$E$6:$P$49,0,MATCH($A6,ASP_per_vial!$E$5:$P$5,0)),0)) -> 2019-Q1 | U6: =_xlfn.MAXIFS(INDEX(ASP_per_vial!$E$6:$P$49,0,MATCH($A6,ASP_per_vial!$E$5:$P$5,0)),ASP_per_vial!$C$6:$C$49,">="&Assumptions!$B$8) -> 2.2943396 | V6: =INDEX(ASP_per_vial!$A$6:$A$49,MATCH(U6,INDEX(ASP_per_vial!$E$6:$P$49,0,MATCH($A6,ASP_per_vial!$E$5:$P$5,0)),0)) -> 2024-Q4
A7: MPSS 125 mg | B7: =INDEX(ASP_per_vial!$E$6:$P$49,MATCH(B$4,ASP_per_vial!$A$6:$A$49,0),MATCH($A7,ASP_per_vial!$E$5:$P$5,0)) -> 3.8726415 | C7: =INDEX(ASP_per_vial!$E$6:$P$49,MATCH(C$4,ASP_per_vial!$A$6:$A$49,0),MATCH($A7,ASP_per_vial!$E$5:$P$5,0)) -> 6.5707547 | D7: =INDEX(ASP_per_vial!$E$6:$P$49,MATCH(D$4,ASP_per_vial!$A$6:$A$49,0),MATCH($A7,ASP_per_vial!$E$5:$P$5,0)) -> 5.25 | E7: =INDEX(ASP_per_vial!$E$6:$P$49,MATCH(E$4,ASP_per_vial!$A$6:$A$49,0),MATCH($A7,ASP_per_vial!$E$5:$P$5,0)) -> 4.7028302 | F7: =INDEX(ASP_per_vial!$E$6:$P$49,MATCH(F$4,ASP_per_vial!$A$6:$A$49,0),MATCH($A7,ASP_per_vial!$E$5:$P$5,0)) -> 5.5490566 | G7: =INDEX(ASP_per_vial!$E$6:$P$49,MATCH(G$4,ASP_per_vial!$A$6:$A$49,0),MATCH($A7,ASP_per_vial!$E$5:$P$5,0)) -> 6.4386792 | H7: =INDEX(ASP_per_vial!$E$6:$P$49,MATCH(H$4,ASP_per_vial!$A$6:$A$49,0),MATCH($A7,ASP_per_vial!$E$5:$P$5,0)) -> 4.9528302 | I7: =INDEX(ASP_per_vial!$E$6:$P$49,MATCH(I$4,ASP_per_vial!$A$6:$A$49,0),MATCH($A7,ASP_per_vial!$E$5:$P$5,0)) -> 6.0141509 | J7: =MAX(INDEX(ASP_per_vial!$E$6:$P$49,0,MATCH($A7,ASP_per_vial!$E$5:$P$5,0))) -> 7.1698113 | K7: =INDEX(ASP_per_vial!$A$6:$A$49,MATCH(J7,INDEX(ASP_per_vial!$E$6:$P$49,0,MATCH($A7,ASP_per_vial!$E$5:$P$5,0)),0)) -> 2024-Q4 | L7: =I7/H7-1 -> 0.21428571 | M7: =(I7/E7)^(1/(I$3-E$3))-1 -> 0.085437968 | N7: =(I7/D7)^(1/(I$3-D$3))-1 -> 0.027550096 | O7: =(I7/B7)^(1/(I$3-B$3))-1 -> 0.041796705 | P7: =C7/B7-1 -> 0.69671133 | Q7: =I7/G7-1 -> -0.065934066 | R7: Windows before Q2 2024 cross the code change | S7: =_xlfn.MAXIFS(INDEX(ASP_per_vial!$E$6:$P$49,0,MATCH($A7,ASP_per_vial!$E$5:$P$5,0)),ASP_per_vial!$C$6:$C$49,"<"&Assumptions!$B$8) -> 6.5707547 | T7: =INDEX(ASP_per_vial!$A$6:$A$49,MATCH(S7,INDEX(ASP_per_vial!$E$6:$P$49,0,MATCH($A7,ASP_per_vial!$E$5:$P$5,0)),0)) -> 2018-Q3 | U7: =_xlfn.MAXIFS(INDEX(ASP_per_vial!$E$6:$P$49,0,MATCH($A7,ASP_per_vial!$E$5:$P$5,0)),ASP_per_vial!$C$6:$C$49,">="&Assumptions!$B$8) -> 7.1698113 | V7: =INDEX(ASP_per_vial!$A$6:$A$49,MATCH(U7,INDEX(ASP_per_vial!$E$6:$P$49,0,MATCH($A7,ASP_per_vial!$E$5:$P$5,0)),0)) -> 2024-Q4
A8: MPSS 500 mg | B8: =INDEX(ASP_per_vial!$E$6:$P$49,MATCH(B$4,ASP_per_vial!$A$6:$A$49,0),MATCH($A8,ASP_per_vial!$E$5:$P$5,0)) -> 15.490566 | C8: =INDEX(ASP_per_vial!$E$6:$P$49,MATCH(C$4,ASP_per_vial!$A$6:$A$49,0),MATCH($A8,ASP_per_vial!$E$5:$P$5,0)) -> 26.283019 | D8: =INDEX(ASP_per_vial!$E$6:$P$49,MATCH(D$4,ASP_per_vial!$A$6:$A$49,0),MATCH($A8,ASP_per_vial!$E$5:$P$5,0)) -> 21 | E8: =INDEX(ASP_per_vial!$E$6:$P$49,MATCH(E$4,ASP_per_vial!$A$6:$A$49,0),MATCH($A8,ASP_per_vial!$E$5:$P$5,0)) -> 18.811321 | F8: =INDEX(ASP_per_vial!$E$6:$P$49,MATCH(F$4,ASP_per_vial!$A$6:$A$49,0),MATCH($A8,ASP_per_vial!$E$5:$P$5,0)) -> 22.196226 | G8: =INDEX(ASP_per_vial!$E$6:$P$49,MATCH(G$4,ASP_per_vial!$A$6:$A$49,0),MATCH($A8,ASP_per_vial!$E$5:$P$5,0)) -> 25.754717 | H8: =INDEX(ASP_per_vial!$E$6:$P$49,MATCH(H$4,ASP_per_vial!$A$6:$A$49,0),MATCH($A8,ASP_per_vial!$E$5:$P$5,0)) -> 19.811321 | I8: =INDEX(ASP_per_vial!$E$6:$P$49,MATCH(I$4,ASP_per_vial!$A$6:$A$49,0),MATCH($A8,ASP_per_vial!$E$5:$P$5,0)) -> 24.056604 | J8: =MAX(INDEX(ASP_per_vial!$E$6:$P$49,0,MATCH($A8,ASP_per_vial!$E$5:$P$5,0))) -> 28.679245 | K8: =INDEX(ASP_per_vial!$A$6:$A$49,MATCH(J8,INDEX(ASP_per_vial!$E$6:$P$49,0,MATCH($A8,ASP_per_vial!$E$5:$P$5,0)),0)) -> 2024-Q4 | L8: =I8/H8-1 -> 0.21428571 | M8: =(I8/E8)^(1/(I$3-E$3))-1 -> 0.085437968 | N8: =(I8/D8)^(1/(I$3-D$3))-1 -> 0.027550096 | O8: =(I8/B8)^(1/(I$3-B$3))-1 -> 0.041796705 | P8: =C8/B8-1 -> 0.69671133 | Q8: =I8/G8-1 -> -0.065934066 | R8: Windows before Q2 2024 cross the code change | S8: =_xlfn.MAXIFS(INDEX(ASP_per_vial!$E$6:$P$49,0,MATCH($A8,ASP_per_vial!$E$5:$P$5,0)),ASP_per_vial!$C$6:$C$49,"<"&Assumptions!$B$8) -> 26.283019 | T8: =INDEX(ASP_per_vial!$A$6:$A$49,MATCH(S8,INDEX(ASP_per_vial!$E$6:$P$49,0,MATCH($A8,ASP_per_vial!$E$5:$P$5,0)),0)) -> 2018-Q3 | U8: =_xlfn.MAXIFS(INDEX(ASP_per_vial!$E$6:$P$49,0,MATCH($A8,ASP_per_vial!$E$5:$P$5,0)),ASP_per_vial!$C$6:$C$49,">="&Assumptions!$B$8) -> 28.679245 | V8: =INDEX(ASP_per_vial!$A$6:$A$49,MATCH(U8,INDEX(ASP_per_vial!$E$6:$P$49,0,MATCH($A8,ASP_per_vial!$E$5:$P$5,0)),0)) -> 2024-Q4
A9: MPSS 1 g | B9: =INDEX(ASP_per_vial!$E$6:$P$49,MATCH(B$4,ASP_per_vial!$A$6:$A$49,0),MATCH($A9,ASP_per_vial!$E$5:$P$5,0)) -> 30.981132 | C9: =INDEX(ASP_per_vial!$E$6:$P$49,MATCH(C$4,ASP_per_vial!$A$6:$A$49,0),MATCH($A9,ASP_per_vial!$E$5:$P$5,0)) -> 52.566038 | D9: =INDEX(ASP_per_vial!$E$6:$P$49,MATCH(D$4,ASP_per_vial!$A$6:$A$49,0),MATCH($A9,ASP_per_vial!$E$5:$P$5,0)) -> 42 | E9: =INDEX(ASP_per_vial!$E$6:$P$49,MATCH(E$4,ASP_per_vial!$A$6:$A$49,0),MATCH($A9,ASP_per_vial!$E$5:$P$5,0)) -> 37.622642 | F9: =INDEX(ASP_per_vial!$E$6:$P$49,MATCH(F$4,ASP_per_vial!$A$6:$A$49,0),MATCH($A9,ASP_per_vial!$E$5:$P$5,0)) -> 44.392453 | G9: =INDEX(ASP_per_vial!$E$6:$P$49,MATCH(G$4,ASP_per_vial!$A$6:$A$49,0),MATCH($A9,ASP_per_vial!$E$5:$P$5,0)) -> 51.509434 | H9: =INDEX(ASP_per_vial!$E$6:$P$49,MATCH(H$4,ASP_per_vial!$A$6:$A$49,0),MATCH($A9,ASP_per_vial!$E$5:$P$5,0)) -> 39.622642 | I9: =INDEX(ASP_per_vial!$E$6:$P$49,MATCH(I$4,ASP_per_vial!$A$6:$A$49,0),MATCH($A9,ASP_per_vial!$E$5:$P$5,0)) -> 48.113208 | J9: =MAX(INDEX(ASP_per_vial!$E$6:$P$49,0,MATCH($A9,ASP_per_vial!$E$5:$P$5,0))) -> 57.358491 | K9: =INDEX(ASP_per_vial!$A$6:$A$49,MATCH(J9,INDEX(ASP_per_vial!$E$6:$P$49,0,MATCH($A9,ASP_per_vial!$E$5:$P$5,0)),0)) -> 2024-Q4 | L9: =I9/H9-1 -> 0.21428571 | M9: =(I9/E9)^(1/(I$3-E$3))-1 -> 0.085437968 | N9: =(I9/D9)^(1/(I$3-D$3))-1 -> 0.027550096 | O9: =(I9/B9)^(1/(I$3-B$3))-1 -> 0.041796705 | P9: =C9/B9-1 -> 0.69671133 | Q9: =I9/G9-1 -> -0.065934066 | R9: Windows before Q2 2024 cross the code change | S9: =_xlfn.MAXIFS(INDEX(ASP_per_vial!$E$6:$P$49,0,MATCH($A9,ASP_per_vial!$E$5:$P$5,0)),ASP_per_vial!$C$6:$C$49,"<"&Assumptions!$B$8) -> 52.566038 | T9: =INDEX(ASP_per_vial!$A$6:$A$49,MATCH(S9,INDEX(ASP_per_vial!$E$6:$P$49,0,MATCH($A9,ASP_per_vial!$E$5:$P$5,0)),0)) -> 2018-Q3 | U9: =_xlfn.MAXIFS(INDEX(ASP_per_vial!$E$6:$P$49,0,MATCH($A9,ASP_per_vial!$E$5:$P$5,0)),ASP_per_vial!$C$6:$C$49,">="&Assumptions!$B$8) -> 57.358491 | V9: =INDEX(ASP_per_vial!$A$6:$A$49,MATCH(U9,INDEX(ASP_per_vial!$E$6:$P$49,0,MATCH($A9,ASP_per_vial!$E$5:$P$5,0)),0)) -> 2024-Q4
