Workbook

Sheet README
A1: Vitamin D3 global market size: extrapolation model (2020/2022 base to 2026E)
A3: Prepared | B3: 21 October 2026, for Symbiotec Pharmalab coverage. Ingredient (producer) level, not finished-product retail value.
A4: Method | B4: Volume(grade, year) = 2020 base x grade share x volume index; Value = volume x price on the same potency basis. Feed and human/pharma grades are kept separate because their prices differ.
A5: Base year | B5: 2020 actual global output of 6,250 t (500,000 IU/g basis), Boyar data relayed in Zhejiang Garden Biochemical's CSRC-registered convertible bond prospectus. No English-language public document states actual 2020 or 2022 global output; English corroboration is on the 'Base-year evidence' sheet. 2022 is derived; enter your own 2022 base in Inputs to test it.
A6: Units | B6: Tonnes are 500,000 IU/g feed-powder equivalent ('D3-500') unless labelled 'pure'. 80 t D3-500 = 1 t pure cholecalciferol (40 MIU/g). Values in USD m.
A7: How to use | B7: Edit only the blue cells on 'Inputs' (yellow = key assumptions). Everything else is formula-driven. Low/High columns drive the value range rows.
A8: Colour code | B8: Blue text = hard-coded input; black = formula; green = link from another sheet; yellow fill = key assumption.
A9: Sources | B9: Every input row on 'Inputs', 'Feed index', 'Trade data' and 'Base-year evidence' carries its source, date, page and URL, plus a source-type tag. 'Analyst assumption' marks judgement.
A10: Main caveats | B10: (1) The 2020 base is a Chinese consultancy figure relayed in a prospectus. (2) The feed/human split is an assumption (evidence range 11-30% human). (3) Annual average prices are reconstructed from sparse dated points. (4) FX rates are assumptions. (5) Alltech feed levels are not comparable year to year, so the chain-linked stated growth rates are used.
A12: Key outputs (live)
A13: 2026E volume, t D3-500 | B13: =Model!E9 -> 6820.6472
A14: 2026E volume, t pure D3 | B14: =Model!E10 -> 85.25809
A15: 2026E value, USD m (API-equivalent) | B15: =Model!E22 -> 156.53047
A16: 2026E value range, USD m | B16: =TEXT(Model!E24,"#,##0")&" - "&TEXT(Model!E25,"#,##0") -> 122 - 194
A17: 2026E feed share of value | B17: =Model!E23 -> 0.72219865
A18: 2025 value, USD m (for comparison) | B18: =Model!D22 -> 212.44311
A19: 2026E value from IFEEDER 2023 base, USD m (500K / 1 MIU readings) | B19: =TEXT(Model!B51,"#,##0")&" / "&TEXT(Model!C51,"#,##0") -> 94 / 187

Sheet Inputs
A1: Inputs: edit blue cells only
A3: Ref | B3: Input | C3: Base | D3: Low | E3: High | F3: Unit | G3: Source / basis | H3: Date | I3: Page | J3: URL | K3: Source type | L3: Note
A4: B1 | B4: 2020 global D3 output (actual) | C4: 6250 | D4: 6000 | E4: 6500 | F4: t D3-500 | G4: Boyar (博亚和讯), '2020 China Vitamin Industry Development Report', relayed in Zhejiang Garden Biochemical (300401.SZ) convertible bond prospectus (创业板向不特定对象发行可转换公司债券募集说明书) | H4: 1 Mar 2023 | I4: printed p.1-1-375 | J4: http://static.cninfo.com.cn/finalpage/2023-03-02/1216024789.PDF | K4: Company filing relaying consultancy | L4: Same figure in Garden's revised reply to SZSE inquiry, 28 Oct 2022, pp.1-36-37. Range reflects English cross-checks (ECHEMI <7,500 t; OPRD ~100 t pure).
A5: B2 | B5: Potency conversion: t D3-500 per t pure D3 | C5: 80 | F5: ratio | G5: Garden Bio H1 2026 report definitions: crystalline D3 40 MIU/g, feed grade 500,000 IU/g (40,000,000 / 500,000 = 80) | H5: 15 Aug 2026 | I5: definitions | J5: http://static.cninfo.com.cn/finalpage/2026-08-15/1225473446.PDF | K5: Company filing
A6: B3 | B6: Human/pharma share of 2020 volume | C6: 0.2 | D6: 0.11 | E6: 0.3 | F6: % of t | G6: Analyst assumption. Evidence: FEFAC factsheet (75% of D3 to feed, i.e. 25% non-feed); CITIC via Hubei Gongtong SZSE reply (20.6%, 2021, broker); Garden 2010 legal opinion (19%); Jiemian 2020 (~11%) | H6: 2025 (FEFAC) | I6: PDF p.31 (FEFAC) | J6: https://fefac.eu/wp-content/uploads/2025/11/Fact-sheet-vulnerability-PUBLIC_rev20251118.pdf | K6: Analyst assumption (institutional evidence) | L6: Biggest swing factor for value mix; total value is less sensitive (see Sensitivity).
A7: C1 | B7: Feed volume growth 2026 vs 2025 | C7: 0.015 | D7: 0.01 | E7: 0.02 | F7: % YoY | G7: Analyst assumption. Alltech chain-linked 2021-25 average ~1.2% a year (2025: +2.9%); FAO Food Outlook June 2026 world meat +1.0% (via 3tres3) | H7: Jul 2026 | J7: https://www.3tres3.com/en/print/22631 | K7: Analyst assumption | L7: No Alltech 2026 forecast exists. D3 inclusion per tonne held constant.
A8: D1 | B8: Human volume index 2022 (2020 = 1) | C8: 0.95 | D8: 0.9 | E8: 1 | F8: index | G8: Analyst assumption from Fermenta filed human-D3 volume changes (CY2022/CY2020 = 0.93), CARE Nov 2023 (destocking), dsm-firmenich 2022-23 commentary | H8: 2022-23 | J8: https://www.careratings.com/upload/CompanyFiles/PR/202311131111_Fermenta_Biotech_Limited.pdf | K8: Analyst assumption (company filings) | L8: Fermenta volumes: FY21 +71%, FY22 +7%, FY23 -30% (BSE earnings presentations).
A9: D2 | B9: Human volume index 2025 (2020 = 1) | C9: 1.13 | D9: 1.05 | E9: 1.2 | F9: index | G9: Analyst assumption from Fermenta filed volumes (CY2025/CY2020 = 1.13; FY24 -18%, FY25 +43%, FY26 +21%) and NBJ (US vitamin D 2025 +12.7% vs 2020) | H9: 2026 | I9: AR p.14 | J9: https://fermentabiotech.com/wp-content/uploads/2026/09/Annual-Report-2025-26-1.pdf | K9: Analyst assumption (company filings)
A10: D3 | B10: Human volume index 2026E (2020 = 1) | C10: 1.15 | D10: 1.05 | E10: 1.28 | F10: index | G10: Analyst assumption: Fermenta Q1FY27 human volumes +18% QoQ; FY27 flat to +10% gives 1.19-1.28; base trimmed for one-producer bias | H10: Aug 2026 | J10: https://fermentabiotech.com/wp-content/uploads/2026/09/Investor-PresentationQ1FY27.pdf | K10: Analyst assumption (company filings)
A11: E1 | B11: Feed-grade price 2020 (annual avg) | C11: 26 | D11: 23 | E11: 30 | F11: USD/kg D3-500 | G11: Analyst reconstruction from dated points: Feedinfo 2020 EUR 9-60/kg (Fermenta BSE deck); Glowlit spot USD 34.8 (27 Mar), ~39.1 (8 Jun), 21.1 (2 Sep); Fermenta 'USD 17-20' (Nov 2020) | H11: 2020 | I11: deck p.26 | J11: https://www.bseindia.com/xml-data/corpfiling/AttachHis/33107246-301d-4469-922a-4a7d52f54130.pdf | K11: Analyst estimate (trade press, company filing) | L11: 2020 had a COVID price spike (Apr-May).
A12: E2 | B12: Feed-grade price 2022 (annual avg) | C12: 11.5 | D12: 10 | E12: 13 | F12: USD/kg D3-500 | G12: Analyst reconstruction: Feedinfo 2022 EUR 7-16/kg (Fermenta Q1FY24 presentation p.8); Fermenta FY23 animal price -25% YoY | H12: Aug 2023 | I12: p.8 | J12: https://www.bseindia.com/xml-data/corpfiling/AttachHis/3eda258d-3e05-4203-9491-0bf011255523.pdf | K12: Analyst estimate (company filing relaying Feedinfo) | L12: 2022 was the price trough.
A13: E3 | B13: Feed-grade price 2025 (annual avg) | C13: 32 | D13: 27 | E13: 40 | F13: USD/kg D3-500 | G13: Analyst reconstruction: dsm-firmenich Q4 2025 outlook (North America contracts USD 35-42/kg, 15 Sep 2025); India imports from Switzerland USD 34.3/kg (DGCI&S); Brazil China-origin USD 28.8/kg (Comex Stat) | H13: 15 Sep 2025 | J13: https://www.dsm-firmenich.com/anh/en_NA/news/articles/vitamin-market-outlook-q4-2025.html | K13: Analyst estimate (producer commentary, official trade data)
A14: E4 | B14: Feed-grade price 2026E (annual avg) | C14: 21 | D14: 17 | E14: 25 | F14: USD/kg D3-500 | G14: Analyst reconstruction: Fermenta Q1FY27 animal realisation -40% YoY; Brazil China-origin USD 24.0/kg Jan-Sep 2026 (Comex Stat); dsm-firmenich 11 Sep 2026 'relatively soft' | H14: Sep 2026 | J14: https://www.dsm-firmenich.com/anh/en_NA/news/articles/vitamin-market-update-q4-2026.html | K14: Analyst estimate (company filing, official trade data) | L14: China domestic ~RMB 95-105/kg in Oct 2026.
A15: F1 | B15: Human/pharma crystalline price 2020 | C15: 2200 | D15: 1600 | E15: 3300 | F15: USD/kg pure | G15: Fermenta analyst meet (BSE, 23 Nov 2020): human side 'between $2000 to $3000 per kg'; India DGCI&S export unit value for crystalline-type rows USD 1,569/kg (CY2020) | H15: 23 Nov 2020 | J15: https://www.bseindia.com/xml-data/corpfiling/AttachHis/23445550-d343-4c2e-98b8-ed6d83f24557.pdf | K15: Company filing; official trade data
A16: F2 | B16: Human/pharma crystalline price 2022 | C16: 2390 | D16: 1700 | E16: 3300 | F16: USD/kg pure | G16: Analyst estimate: 2020 x (1 + ~9%), from India crystalline-tier export unit values USD 1,569 (2020) to 1,705 (2022) | H16: Oct 2026 pull | J16: https://tradestat.commerce.gov.in/eidb/commodity_wise_all_countries_export | K16: Analyst estimate (official trade data)
A17: F3 | B17: Human/pharma crystalline price 2025 | C17: 2420 | D17: 1700 | E17: 3300 | F17: USD/kg pure | G17: Analyst estimate: India crystalline-tier export unit value USD 1,728 (CY2025), +10% vs 2020; Fermenta human price changes FY21-FY25 +2% to +5% a year | H17: Oct 2026 pull | J17: https://tradestat.commerce.gov.in/eidb/commodity_wise_all_countries_export | K17: Analyst estimate (official trade data)
A18: F4 | B18: Human/pharma crystalline price 2026E | C18: 2420 | D18: 1700 | E18: 3300 | F18: USD/kg pure | G18: Analyst assumption: flat on 2025 | H18: 2026 | K18: Analyst assumption
A19: D0 | B19: Human volume index 2023 (2020 = 1) | C19: 0.8 | D19: 0.7 | E19: 0.95 | F19: index | G19: Analyst assumption: Fermenta filed human volumes give CY2023/CY2020 = 0.73 (FY23 -30%, FY24 -18%); CARE Nov 2023: channel 'saddled with surplus stocks'; dsm-firmenich FY2023 HNC volumes -6% ('persistent destocking'). End-consumption fell less than Fermenta's sales | H19: Nov 2023 | J19: https://www.careratings.com/upload/CompanyFiles/PR/202311131111_Fermenta_Biotech_Limited.pdf | K19: Analyst assumption (company filings) | L19: Used only in the IFEEDER 2023 base check.
A20: J1 | B20: IFEEDER 2023 global D3 supply | C20: 3640 | F20: MT (basis unstated) | G20: Decision Innovation Solutions & Lobo Consulting Solutions for IFEEDER (AFIA research foundation), 'Strategic Assessment on Impact of Vitamin and Amino Acid Supply Chain Disruptions on U.S. Food Security', section 3.3.3: 'estimate global vitamin D3 supply for 2023 at 3,640 MT' | H20: Nov 2025 | I20: p.23 | J20: https://www.afia.org/pub/?id=c9faec10-dada-d077-7081-0e9bd8e1bcee | K20: Institutional study (consultant estimates) | L20: No IU/g potency basis is given anywhere in the section. p.2 table labels 3,639 as capacity (inconsistent).
A21: J2 | B21: IFEEDER 2023 global D3 demand | C21: 3755 | F21: MT (basis unstated) | G21: Decision Innovation Solutions & Lobo Consulting Solutions for IFEEDER (AFIA research foundation), 'Strategic Assessment on Impact of Vitamin and Amino Acid Supply Chain Disruptions on U.S. Food Security', section 3.3.3: 'global demand at approximately 3,755 MT' | H21: Nov 2025 | I21: p.23 | J21: https://www.afia.org/pub/?id=c9faec10-dada-d077-7081-0e9bd8e1bcee | K21: Institutional study (consultant estimates)
A22: J3 | B22: IFEEDER 2023 global D3 capacity | C22: 19000 | F22: MT (basis unstated) | G22: Decision Innovation Solutions & Lobo Consulting Solutions for IFEEDER (AFIA research foundation), 'Strategic Assessment on Impact of Vitamin and Amino Acid Supply Chain Disruptions on U.S. Food Security', section 3.3.3: capacity 'about 19,000 MT' (corroborated by 'multiple industry sources'); flat to June 2025; utilisation 20%; China ~93%, India 5%, EU 3% | H22: Nov 2025 | I22: p.23, Fig. 13 | J22: https://www.afia.org/pub/?id=c9faec10-dada-d077-7081-0e9bd8e1bcee | K22: Institutional study (consultant estimates) | L22: Capacity/demand of ~5x matches FEFAC's 'five times demand' (2025 factsheet).
A23: J4 | B23: Reading A: IU/g basis of IFEEDER tonnes | C23: 500000 | F23: IU/g | G23: Analyst assumption: industry convention for feed-grade tonnage (D3-500) | K23: Analyst assumption
A24: J5 | B24: Reading B: IU/g basis of IFEEDER tonnes | C24: 1000000 | F24: IU/g | G24: Analyst assumption: D3 1.0 MIU/g (oil) convention | K24: Analyst assumption
A25: G1 | B25: Optional: your 2022 base volume (blank = derived) | F25: t D3-500 | G25: Enter a 2022 actual-output figure if you have one; the '2022-base check' block on Model re-runs 2026E from it | K25: User input | L25: No public 2022 global output figure was found in English or Chinese filings.
A26: H1 | B26: FX: RMB per USD | C26: 7.2 | F26: RMB/USD | G26: Analyst assumption (approximate 2025-26 rate) | K26: Analyst assumption | L26: Used only in cross-checks.
A27: H3 | B27: FX: RMB per USD (2022) | C27: 6.7 | F27: RMB/USD | G27: Analyst assumption (approximate 2022 average) | K27: Analyst assumption | L27: Used only in the 2022 Garden cross-check.
A28: H2 | B28: FX: INR per USD | C28: 88 | F28: INR/USD | G28: Analyst assumption (approximate FY26 rate) | K28: Analyst assumption | L28: Used only in cross-checks.

Sheet Feed index
A1: Global compound feed volume index (Alltech Agri-Food Outlook)
A2: Headline levels are restated almost every year (coverage changes), so the index chains each release's stated YoY growth. 2020 = 1.000.
A4: Data year | B4: Headline, Mt (as published) | C4: Stated YoY | D4: Chain index (2020 = 1) | E4: Release | F4: Source | G4: Source type
A5: 2020 | B5: 1187.7 | C5: 0.01 | D5: 1 | E5: 26 Jan 2021 | F5: https://www.agnavigator.com/Article/2021/01/26/china-back-on-top-in-global-feed-production-ranking/ | G5: Company survey via trade press
A6: 2021 | B6: 1235 | C6: 0.023 | D6: =D5*(1+C6) -> 1.023 | E6: 9 Feb 2022 | F6: https://www.provisioneronline.com/articles/112062-2022-alltech-agri-food-outlook-reveals-global-feed-production-survey-data-and-trends-shaping-the-future | G6: Company survey via trade press
A7: 2022 | B7: 1266 | C7: -0.0042 | D7: =D6*(1+C7) -> 1.0187034 | E7: 24 Jan 2023 | F7: https://www.poultryproducer.com/?p=17574 | G7: Company survey via trade press
A8: 2023 | B8: 1290 | C8: -0.0001 | D8: =D7*(1+C8) -> 1.0186015 | E8: 2 Apr 2024 (adjusted 15 Apr 2024) | F8: https://millingmea.com/global-feed-production-remains-steady-despite-challenges-alltech-agri-food-outlook-2024/ | G8: Company survey via trade press
A9: 2024 | B9: 1396 | C9: 0.012 | D9: =D8*(1+C9) -> 1.0308247 | E9: 29 Apr 2025 | F9: https://www.alltech.com/press-release/2025-alltech-agri-food-outlook-shares-global-feed-production-survey-data | G9: Company press release
A10: 2025 | B10: 1440 | C10: 0.029 | D10: =D9*(1+C10) -> 1.0607187 | E10: 21 Apr 2026 | F10: https://www.alltech.com/press-release/2026-alltech-agri-food-outlook-shares-global-feed-production-survey-data | G10: Company press release
A12: Note: 2023 YoY uses Alltech's 15 Apr 2024 adjustment (-0.01%; first published -0.2%). 2024 growth is against a restated 2023 of 1,380 Mt. The 2026 release cites 38,837 mills vs 28,235 a year earlier.

Sheet Model
A1: Extrapolation from the 2020 base (USD m unless stated)
A3: Line | B3: 2020 | C3: 2022 | D3: 2025 | E3: 2026E | F3: Formula / note
A4: Volume
A5: Feed volume index (2020 = 1) | B5: 1 | C5: =FeedIdx2022 -> 1.0187034 | D5: =FeedIdx2025 -> 1.0607187 | E5: =D5*(1+FeedG2026) -> 1.0766294 | F5: Alltech chain-linked stated growth ('Feed index'); 2026 = 2025 x (1 + Inputs C1)
A6: Human/pharma volume index (2020 = 1) | B6: 1 | C6: =HumIdx2022 -> 0.95 | D6: =HumIdx2025 -> 1.13 | E6: =HumIdx2026 -> 1.15 | F6: Inputs D1-D3 (Fermenta filed volumes, NBJ, CRN, dsm-firmenich)
A7: Feed volume, t D3-500 | B7: =Base2020*(1-HumanShare)*B5 -> 5000 | C7: =Base2020*(1-HumanShare)*C5 -> 5093.517 | D7: =Base2020*(1-HumanShare)*D5 -> 5303.5933 | E7: =Base2020*(1-HumanShare)*E5 -> 5383.1472 | F7: 2020 base x (1 - human share) x feed index
A8: Human/pharma volume, t D3-500 | B8: =Base2020*HumanShare*B6 -> 1250 | C8: =Base2020*HumanShare*C6 -> 1187.5 | D8: =Base2020*HumanShare*D6 -> 1412.5 | E8: =Base2020*HumanShare*E6 -> 1437.5 | F8: 2020 base x human share x human index
A9: Total volume, t D3-500 | B9: =B7+B8 -> 6250 | C9: =C7+C8 -> 6281.017 | D9: =D7+D8 -> 6716.0933 | E9: =E7+E8 -> 6820.6472
A10: Total volume, t pure D3 | B10: =B9/Potency -> 78.125 | C10: =C9/Potency -> 78.512713 | D10: =D9/Potency -> 83.951167 | E10: =E9/Potency -> 85.25809 | F10: ÷ 80 (Inputs B2)
A11: Human/pharma volume, t pure D3 | B11: =B8/Potency -> 15.625 | C11: =C8/Potency -> 14.84375 | D11: =D8/Potency -> 17.65625 | E11: =E8/Potency -> 17.96875
A12: Volume growth vs 2020 | B12: =B9/$B$9-1 -> 0 | C12: =C9/$B$9-1 -> 0.00496272 | D12: =D9/$B$9-1 -> 0.074574933 | E12: =E9/$B$9-1 -> 0.091303557
A14: Prices
A15: Feed-grade price, USD/kg D3-500 | B15: =FeedP2020 -> 26 | C15: =FeedP2022 -> 11.5 | D15: =FeedP2025 -> 32 | E15: =FeedP2026 -> 21 | F15: Inputs E1-E4 (annual averages)
A16: Human/pharma crystalline price, USD/kg pure | B16: =HumP2020 -> 2200 | C16: =HumP2022 -> 2390 | D16: =HumP2025 -> 2420 | E16: =HumP2026 -> 2420 | F16: Inputs F1-F4
A17: Human price per IU vs feed (x) | B17: =B16/Potency/B15 -> 1.0576923 | C17: =C16/Potency/C15 -> 2.5978261 | D17: =D16/Potency/D15 -> 0.9453125 | E17: =E16/Potency/E15 -> 1.4404762 | F17: Crystalline price ÷ 80 ÷ feed price: per-IU premium of human grade
A19: Value (ingredient level, USD m)
A20: Feed value | B20: =B7*B15/1000 -> 130 | C20: =C7*C15/1000 -> 58.575446 | D20: =D7*D15/1000 -> 169.71499 | E20: =E7*E15/1000 -> 113.04609 | F20: t x USD/kg ÷ 1,000
A21: Human/pharma value (API-equivalent) | B21: =B11*B16/1000 -> 34.375 | C21: =C11*C16/1000 -> 35.476562 | D21: =D11*D16/1000 -> 42.728125 | E21: =E11*E16/1000 -> 43.484375 | F21: t pure x USD/kg ÷ 1,000
A22: Total value, USD m | B22: =B20+B21 -> 164.375 | C22: =C20+C21 -> 94.052008 | D22: =D20+D21 -> 212.44311 | E22: =E20+E21 -> 156.53047
A23: Feed share of value | B23: =IF(B22=0,0,B20/B22) -> 0.79087452 | C23: =IF(C22=0,0,C20/C22) -> 0.62279846 | D23: =IF(D22=0,0,D20/D22) -> 0.79887263 | E23: =IF(E22=0,0,E20/E22) -> 0.72219865
A24: Total value, low (low prices) | B24: =B7*FeedP2020_L/1000+B11*HumP2020_L/1000 -> 140 | C24: =C7*FeedP2022_L/1000+C11*HumP2022_L/1000 -> 76.169545 | D24: =D7*FeedP2025_L/1000+D11*HumP2025_L/1000 -> 173.21264 | E24: =E7*FeedP2026_L/1000+E11*HumP2026_L/1000 -> 122.06038 | F24: Volume at base; prices at Inputs 'Low'
A25: Total value, high (high prices) | B25: =B7*FeedP2020_H/1000+B11*HumP2020_H/1000 -> 201.5625 | C25: =C7*FeedP2022_H/1000+C11*HumP2022_H/1000 -> 115.2001 | D25: =D7*FeedP2025_H/1000+D11*HumP2025_H/1000 -> 270.40936 | E25: =E7*FeedP2026_H/1000+E11*HumP2026_H/1000 -> 193.87556 | F25: Volume at base; prices at Inputs 'High'
A27: 2022-base check (re-runs 2026E from a 2022 volume)
A28: 2022 base volume used, t D3-500 | B28: =IF(ISNUMBER(Base2022User),Base2022User,C9) -> 6281.017 | F28: Your Inputs G1 figure if entered, else the derived 2022 total (C9)
A29: Human share of 2022 base | B29: =C8/C9 -> 0.18906174 | F29: From the 2020-base path
A30: Feed multiplier 2022 -> 2026 | B30: =E5/C5 -> 1.0568625 | F30: Feed index ratio
A31: Human multiplier 2022 -> 2026 | B31: =E6/C6 -> 1.2105263 | F31: Human index ratio
A32: 2026E volume from 2022 base, t D3-500 | B32: =B28*(1-B29)*B30+B28*B29*B31 -> 6820.6472
A33: 2026E value from 2022 base, USD m | B33: =B28*(1-B29)*B30*FeedP2026/1000+B28*B29*B31/Potency*HumP2026/1000 -> 156.53047
A34: Difference vs 2020-base 2026E value | B34: =IF(E22=0,0,B33/E22-1) -> 0 | F34: Zero unless you enter your own 2022 base
A36: Interpretation: API-equivalent human value prices all human volume at crystalline USD/kg; formulated forms (oils, CWS beadlets, spray-dried D3 100) sell at several times that per IU, so an 'as-sold' human market is larger (see Cross-checks). For an API maker such as Symbiotec, the API-equivalent pool is the relevant addressable market.
A38: 2023 IFEEDER base check (English public source; potency basis unstated) | B38: Reading A: 500,000 IU/g | C38: Reading B: 1,000,000 IU/g
A40: IFEEDER 2023 supply, MT as stated | B40: =IF_Supply -> 3640 | C40: =IF_Supply -> 3640 | F40: Inputs J1 (p.23)
A41: Assumed potency, IU/g | B41: =IF_BasisA -> 500000 | C41: =IF_BasisB -> 1000000 | F41: Inputs J4/J5
A42: 2023 supply, t D3-500 equivalent | B42: =B40*B41/500000 -> 3640 | C42: =C40*C41/500000 -> 7280 | F42: MT x IU/g ÷ 500,000
A43: 2023 supply, t pure D3 | B43: =B42/Potency -> 45.5 | C43: =C42/Potency -> 91
A44: Model's own 2023 volume (2020 base), t D3-500 | B44: =Base2020*(1-HumanShare)*FeedIdx2023+Base2020*HumanShare*HumIdx2023 -> 6093.0076 | C44: =Base2020*(1-HumanShare)*FeedIdx2023+Base2020*HumanShare*HumIdx2023 -> 6093.0076 | F44: Boyar 2020 base rolled to 2023 with the same indices
A45: IFEEDER as % of model 2023 | B45: =IF(B44=0,0,B42/B44) -> 0.59740611 | C45: =IF(C44=0,0,C42/C44) -> 1.1948122
A46: Human share of 2023 volume | B46: =Base2020*HumanShare*HumIdx2023/B44 -> 0.16412256 | C46: =Base2020*HumanShare*HumIdx2023/C44 -> 0.16412256 | F46: From the model path
A47: Feed multiplier 2023 -> 2026 | B47: =$E$5/FeedIdx2023 -> 1.0569682 | C47: =$E$5/FeedIdx2023 -> 1.0569682 | F47: Feed index ratio
...

Sheet Sensitivity
A1: 2026E total value (USD m): feed-grade price x human share
A2: Other inputs at base. Rows: feed-grade price USD/kg D3-500. Columns: human/pharma share of 2020 volume.
A4: Feed price \ human share | B4: 0.11 | C4: 0.15 | D4: 0.2 | E4: 0.25 | F4: 0.3
A5: 15 | B5: =Base2020*(1-B$4)*Model!$E$5*$A5/1000+Base2020*B$4*Model!$E$6/Potency*HumP2026/1000 -> 113.74768 | C5: =Base2020*(1-C$4)*Model!$E$5*$A5/1000+Base2020*C$4*Model!$E$6/Potency*HumP2026/1000 -> 118.40719 | D5: =Base2020*(1-D$4)*Model!$E$5*$A5/1000+Base2020*D$4*Model!$E$6/Potency*HumP2026/1000 -> 124.23158 | E5: =Base2020*(1-E$4)*Model!$E$5*$A5/1000+Base2020*E$4*Model!$E$6/Potency*HumP2026/1000 -> 130.05598 | F5: =Base2020*(1-F$4)*Model!$E$5*$A5/1000+Base2020*F$4*Model!$E$6/Potency*HumP2026/1000 -> 135.88037
A6: 17 | B6: =Base2020*(1-B$4)*Model!$E$5*$A6/1000+Base2020*B$4*Model!$E$6/Potency*HumP2026/1000 -> 125.72518 | C6: =Base2020*(1-C$4)*Model!$E$5*$A6/1000+Base2020*C$4*Model!$E$6/Potency*HumP2026/1000 -> 129.84638 | D6: =Base2020*(1-D$4)*Model!$E$5*$A6/1000+Base2020*D$4*Model!$E$6/Potency*HumP2026/1000 -> 134.99788 | E6: =Base2020*(1-E$4)*Model!$E$5*$A6/1000+Base2020*E$4*Model!$E$6/Potency*HumP2026/1000 -> 140.14938 | F6: =Base2020*(1-F$4)*Model!$E$5*$A6/1000+Base2020*F$4*Model!$E$6/Potency*HumP2026/1000 -> 145.30088
A7: 19 | B7: =Base2020*(1-B$4)*Model!$E$5*$A7/1000+Base2020*B$4*Model!$E$6/Potency*HumP2026/1000 -> 137.70268 | C7: =Base2020*(1-C$4)*Model!$E$5*$A7/1000+Base2020*C$4*Model!$E$6/Potency*HumP2026/1000 -> 141.28557 | D7: =Base2020*(1-D$4)*Model!$E$5*$A7/1000+Base2020*D$4*Model!$E$6/Potency*HumP2026/1000 -> 145.76417 | E7: =Base2020*(1-E$4)*Model!$E$5*$A7/1000+Base2020*E$4*Model!$E$6/Potency*HumP2026/1000 -> 150.24278 | F7: =Base2020*(1-F$4)*Model!$E$5*$A7/1000+Base2020*F$4*Model!$E$6/Potency*HumP2026/1000 -> 154.72139
A8: 21 | B8: =Base2020*(1-B$4)*Model!$E$5*$A8/1000+Base2020*B$4*Model!$E$6/Potency*HumP2026/1000 -> 149.68018 | C8: =Base2020*(1-C$4)*Model!$E$5*$A8/1000+Base2020*C$4*Model!$E$6/Potency*HumP2026/1000 -> 152.72475 | D8: =Base2020*(1-D$4)*Model!$E$5*$A8/1000+Base2020*D$4*Model!$E$6/Potency*HumP2026/1000 -> 156.53047 | E8: =Base2020*(1-E$4)*Model!$E$5*$A8/1000+Base2020*E$4*Model!$E$6/Potency*HumP2026/1000 -> 160.33618 | F8: =Base2020*(1-F$4)*Model!$E$5*$A8/1000+Base2020*F$4*Model!$E$6/Potency*HumP2026/1000 -> 164.14189
A9: 23 | B9: =Base2020*(1-B$4)*Model!$E$5*$A9/1000+Base2020*B$4*Model!$E$6/Potency*HumP2026/1000 -> 161.65769 | C9: =Base2020*(1-C$4)*Model!$E$5*$A9/1000+Base2020*C$4*Model!$E$6/Potency*HumP2026/1000 -> 164.16394 | D9: =Base2020*(1-D$4)*Model!$E$5*$A9/1000+Base2020*D$4*Model!$E$6/Potency*HumP2026/1000 -> 167.29676 | E9: =Base2020*(1-E$4)*Model!$E$5*$A9/1000+Base2020*E$4*Model!$E$6/Potency*HumP2026/1000 -> 170.42958 | F9: =Base2020*(1-F$4)*Model!$E$5*$A9/1000+Base2020*F$4*Model!$E$6/Potency*HumP2026/1000 -> 173.5624
A10: 25 | B10: =Base2020*(1-B$4)*Model!$E$5*$A10/1000+Base2020*B$4*Model!$E$6/Potency*HumP2026/1000 -> 173.63519 | C10: =Base2020*(1-C$4)*Model!$E$5*$A10/1000+Base2020*C$4*Model!$E$6/Potency*HumP2026/1000 -> 175.60313 | D10: =Base2020*(1-D$4)*Model!$E$5*$A10/1000+Base2020*D$4*Model!$E$6/Potency*HumP2026/1000 -> 178.06306 | E10: =Base2020*(1-E$4)*Model!$E$5*$A10/1000+Base2020*E$4*Model!$E$6/Potency*HumP2026/1000 -> 180.52298 | F10: =Base2020*(1-F$4)*Model!$E$5*$A10/1000+Base2020*F$4*Model!$E$6/Potency*HumP2026/1000 -> 182.98291
A11: 30 | B11: =Base2020*(1-B$4)*Model!$E$5*$A11/1000+Base2020*B$4*Model!$E$6/Potency*HumP2026/1000 -> 203.57895 | C11: =Base2020*(1-C$4)*Model!$E$5*$A11/1000+Base2020*C$4*Model!$E$6/Potency*HumP2026/1000 -> 204.2011 | D11: =Base2020*(1-D$4)*Model!$E$5*$A11/1000+Base2020*D$4*Model!$E$6/Potency*HumP2026/1000 -> 204.97879 | E11: =Base2020*(1-E$4)*Model!$E$5*$A11/1000+Base2020*E$4*Model!$E$6/Potency*HumP2026/1000 -> 205.75648 | F11: =Base2020*(1-F$4)*Model!$E$5*$A11/1000+Base2020*F$4*Model!$E$6/Potency*HumP2026/1000 -> 206.53418
A12: 35 | B12: =Base2020*(1-B$4)*Model!$E$5*$A12/1000+Base2020*B$4*Model!$E$6/Potency*HumP2026/1000 -> 233.5227 | C12: =Base2020*(1-C$4)*Model!$E$5*$A12/1000+Base2020*C$4*Model!$E$6/Potency*HumP2026/1000 -> 232.79907 | D12: =Base2020*(1-D$4)*Model!$E$5*$A12/1000+Base2020*D$4*Model!$E$6/Potency*HumP2026/1000 -> 231.89453 | E12: =Base2020*(1-E$4)*Model!$E$5*$A12/1000+Base2020*E$4*Model!$E$6/Potency*HumP2026/1000 -> 230.98999 | F12: =Base2020*(1-F$4)*Model!$E$5*$A12/1000+Base2020*F$4*Model!$E$6/Potency*HumP2026/1000 -> 230.08545
A14: 2026E total volume (t D3-500) is almost insensitive to the split: see Model row 9.

Sheet Base-year evidence
A1: Evidence for 2020-2023 global market size (volume and value)
A3: Year | B3: Figure as stated | C3: Metric | D3: Stated basis | E3: Implied t D3-500 | F3: Implied t pure | G3: Language | H3: Document | I3: Page | J3: Date | K3: URL | L3: Source type | M3: Used? | N3: Comment
A4: 2020 | B4: 6,250 t | C4: Actual output | D4: 500,000 IU/g | E4: 6250 | F4: =E4/Potency -> 78.125 | G4: Chinese | H4: Zhejiang Garden Biochemical CB prospectus, citing Boyar 2020 China Vitamin Industry Development Report | I4: p.1-1-375 | J4: 1 Mar 2023 | K4: http://static.cninfo.com.cn/finalpage/2023-03-02/1216024789.PDF | L4: Company filing relaying consultancy | M4: Base | N4: Only actual-output figure found in any public filing.
A5: 2020 | B5: 14,600 t | C5: Capacity | D5: 500,000 IU/g | E5: 14600 | F5: =E5/Potency -> 182.5 | G5: Chinese | H5: Same prospectus (Boyar) | I5: p.1-1-375 | J5: 1 Mar 2023 | K5: http://static.cninfo.com.cn/finalpage/2023-03-02/1216024789.PDF | L5: Company filing relaying consultancy | M5: No | N5: Implies ~43% utilisation.
A6: 2020 | B6: Garden >3,000 t = >40% of industry | C6: Producer share | D6: Unstated | E6: 7500 | F6: =E6/Potency -> 93.75 | G6: English | H6: ECHEMI, 'Vitamin prices bottomed out and the traditional peak sales season is coming', citing China Feed Industry Information Network | J6: 17 Aug 2020 | K6: https://www.echemi.com/cms/114560.html | L6: Trade aggregator | M6: Cross-check | N6: Implies industry below ~7,500 t (upper bound); consistent with 6,250 t.
A7: Pre-2021 | B7: 10,000-12,000 MT 'before pandemic' | C7: Management estimate | D7: Unstated (likely D3-500) | E7: 11000 | F7: =E7/Potency -> 137.5 | G7: English | H7: Fermenta Biotech Q3 FY22 earnings call transcript (BSE filing) | I7: PDF p.14 (printed p.13) | J7: 16 Feb 2022 | K7: https://www.bseindia.com/xml-data/corpfiling/AttachHis/9e5e419e-6095-47a2-a06e-bf49cfe9a712.pdf | L7: Company filing (management estimate, unsourced) | M7: Cross-check | N7: Matches broker demand estimates rather than actual output; Q2 FY22 call (17 Nov 2021) calls it the animal-feed market.
A8: Undated | B8: ~100 t a year worldwide production | C8: Production | D8: Pure D3 | E8: 8000 | F8: =E8/Potency -> 100 | G8: English | H8: Schütz J. et al. (dsm-firmenich), Organic Process Research & Development 28(11) | J8: 25 Oct 2024 | K8: https://doi.org/10.1021/acs.oprd.4c00333 | L8: Peer-reviewed (producer-authored) | M8: Cross-check | N8: Quote read via search index (publisher blocked); year not stated.
A9: 2023 | B9: Supply 3,640 MT; demand ~3,755 MT; capacity ~19,000 MT; China ~93% of capacity | C9: Supply/demand | D9: Unstated | E9: 3640 | F9: =E9/Potency -> 45.5 | G9: English | H9: IFEEDER (AFIA foundation) / DIS & LCS, Strategic Assessment on Vitamin and Amino Acid Supply Chain Disruptions | I9: p.23 | J9: Nov 2025 | K9: https://www.afia.org/pub/?id=c9faec10-dada-d077-7081-0e9bd8e1bcee | L9: Institutional study | M9: Check | N9: Basis unstated; see Model rows 38-56 for both readings. p.2 table labels 3,639 as capacity.
A10: 2021 | B10: 10,308 t (feed 8,189 t) | C10: Use | D10: 500,000 IU/g | E10: 10308 | F10: =E10/Potency -> 128.85 | G10: Chinese | H10: Hubei Gongtong reply to SZSE inquiry, citing CITIC Securities | J10: 30 Aug 2022 | L10: Company filing relaying broker | M10: No | N10: Broker-derived demand.
A11: 2021-22 | B11: 14,793 t | C11: Theoretical demand | D11: 500,000 IU/g | E11: 14793 | F11: =E11/Potency -> 184.9125 | G11: Chinese | H11: Garden CB prospectus (own calculation: Alltech feed x 6 g/t; population x dose) | I11: pp.1-1-101 to 103 | J11: 1 Mar 2023 | K11: http://static.cninfo.com.cn/finalpage/2023-03-02/1216024789.PDF | L11: Company filing | M11: No | N11: Need, not consumption.
A12: 2019 | B12: Demand ~6,750 t; capacity ~14,600 t | C12: Demand | D12: 500,000 IU/g | E12: 6750 | F12: =E12/Potency -> 84.375 | G12: English | H12: BP Equities, Fermenta Biotech initiating coverage (citing Boyar) | I12: p.7 | J12: Mar 2021 | K12: https://s3.ap-south-1.amazonaws.com/bpwealth-cdn/pdf/1618577883-BP%20Equities_%20Fermenta%20Biotech%20Ltd._Initiating%20Coverage_BUY_Trgt%20402.pdf | L12: Broker research | M12: No | N12: English fallback only (broker).
A13: 2022 | B13: 6,281 t (derived) | C13: Derived output | D13: 500,000 IU/g | E13: =Model!C9 -> 6281.017 | F13: =E13/Potency -> 78.512713 | G13: Model | H13: This model: 2020 base x indices | L13: Analyst calculation | M13: Model | N13: No public 2022 output figure found.
A14: 2020 | B14: USD 1.1bn ('vitamin D', all forms) | C14: Value | D14: Finished/all forms | G14: English | H14: MarketsandMarkets via IPS News reprint | J14: 17 Aug 2020 | K14: https://ipsnews.net/business/?p=62618 | L14: Paid market research | M14: No | N14: Not an ingredient-level value; includes D2 and analogues.
A15: 2022 | B15: USD 1.3bn ('vitamin D', all forms) | C15: Value | D15: Finished/all forms | G15: English | H15: MarketsandMarkets press release | J15: 25 Nov 2022 | K15: https://www.marketsandmarkets.com/PressReleases/vitamin-d.asp | L15: Paid market research | M15: No | N15: As above.
A16: 1997-98 | B16: EU ECU 20m (1998); world ~ECU 67m (1997 producer turnover) | C16: Value | D16: Producer sales | G16: English | H16: European Commission Decision 2003/2/EC (vitamins cartel), recital 60 and table p. L 6/13 | I16: OJ L 6/7, L 6/13 | J16: 10 Jan 2003 | K16: http://publications.europa.eu/resource/celex/32003D0002 | L16: Regulator decision | M16: No | N16: Only official value figure; historical.
A18: Implied t D3-500 for ECHEMI is the upper bound (3,000 / 40%); for Fermenta the midpoint; for OPRD 100 t pure x 80.

Sheet Cross-checks
A1: Cross-checks against company disclosures
A3: Check | B3: Input | C3: Value | D3: Unit | E3: Source | F3: URL | G3: Source type
A4: Garden 2025: implied market from revenue/share | B4: Garden vitamin products revenue 2025 | C4: 613.5 | D4: RMB m | E4: Garden 2025 annual report, segment table | F4: http://static.cninfo.com.cn/finalpage/2026-04-18/1225116031.PDF | G4: Company filing
B5: Garden D3 market share (low) | C5: 0.3 | D5: % | E5: Garden investor Q&A: '公司维生素D3产品当前市占率30-40%' | F5: http://static.cninfo.com.cn/finalpage/2025-04-07/1223021870.PDF | G5: Company filing
B6: Garden D3 market share (high) | C6: 0.4 | D6: % | E6: Same | F6: http://static.cninfo.com.cn/finalpage/2025-04-07/1223021870.PDF | G6: Company filing
B7: Implied 2025 market, USD m (high end, at 30%) | C7: =C4/C5/FX_RMB -> 284.02778 | D7: USD m | E7: Calculation | G7: Analyst calculation
B8: Implied 2025 market, USD m (low end, at 40%) | C8: =C4/C6/FX_RMB -> 213.02083 | D8: USD m | E8: Calculation | G8: Analyst calculation
B9: Model 2025 value (feed + human), USD m | C9: =Model!D22 -> 212.44311 | D9: USD m | E9: Model row 22 | G9: Model
A10: Garden 2022: implied market | B10: Garden D3 and analogues revenue 2022 | C10: 386 | D10: RMB m | E10: Lianhe Ratings, Garden convertible bond tracking rating report | F10: https://www.lhratings.com/reports/B0648-P66511-2022-GZ2024.pdf | G10: Credit rating report
B11: Implied 2022 market at 30% share, USD m (RMB 6.7/USD) | C11: =C10/C5/FX_RMB22 -> 192.0398 | D11: USD m | E11: Calculation (Inputs FX 2022) | G11: Analyst calculation
B12: Model 2022 value, USD m | C12: =Model!C22 -> 94.052008 | D12: USD m | E12: Model row 22 | G12: Model
A13: Fermenta FY26: human 'as-sold' market | B13: Fermenta human-nutrition D3 revenue FY26 | C13: 292.7 | D13: INR cr | E13: Fermenta Annual Report 2025-26, MD&A p.14 | F13: https://fermentabiotech.com/wp-content/uploads/2026/09/Annual-Report-2025-26-1.pdf | G13: Company filing
B14: Fermenta share of human D3 (claim) | C14: 0.25 | D14: % | E14: BP Equities initiation (broker), Mar 2021: ~25% of human-grade D3 API | F14: https://s3.ap-south-1.amazonaws.com/bpwealth-cdn/pdf/1618577883-BP%20Equities_%20Fermenta%20Biotech%20Ltd._Initiating%20Coverage_BUY_Trgt%20402.pdf | G14: Broker research (management claim)
B15: Implied human market, as-sold, USD m | C15: =C13*10/FX_INR/C14 -> 133.04545 | D15: USD m | E15: Calculation (INR cr x 10 = INR m) | G15: Analyst calculation
B16: Model human value 2025, API-equivalent, USD m | C16: =Model!D21 -> 42.728125 | D16: USD m | E16: Model row 21 | G16: Model
A17: Feed inclusion sanity check (2020) | B17: Global feed 2020, Mt | C17: ='Feed index'!B5 -> 1187.7 | D17: Mt | E17: Alltech 2021 Agri-Food Outlook | G17: Link
B18: Implied average D3 inclusion, g D3-500 per t feed | C18: =Model!B7/C17 -> 4.2098173 | D18: g/t | E18: Feed volume t x 1e6 g ÷ feed Mt x 1e6 t | G18: Analyst calculation
B19: Implied average D3 inclusion, IU/kg feed | C19: =C18*500 -> 2104.9086 | D19: IU/kg | E19: g/t x 500,000 IU/g ÷ 1,000 kg | G19: Analyst calculation
A21: Reading: revenue/share checks run above the API-equivalent model because producer revenue includes formulated forms, 25-OH-D3 and food grades sold at higher per-IU prices. Treat the model as a floor for an API-level pool.

Sheet Trade data
A1: Official trade data (country-level proxies, not global consumption)
A3: Series | B3: Period | C3: Value, USD m | D3: Volume, kg | E3: Unit value, USD/kg | F3: Authority | G3: Code | H3: URL / query
A4: India imports, Vitamin D | B4: CY2020 | C4: 6.9 | D4: 23944 | E4: =IF(D4=0,0,C4*1000000/D4) -> 288.1724 | F4: DGCI&S / Ministry of Commerce (tradestat) | G4: ITC-HS 29362940 | H4: https://tradestat.commerce.gov.in/meidb/commodity_wise_all_countries_import
A5: India imports, Vitamin D | B5: CY2022 | C5: 11.03 | D5: 18433 | E5: =IF(D5=0,0,C5*1000000/D5) -> 598.38333 | F5: DGCI&S / Ministry of Commerce (tradestat) | G5: ITC-HS 29362940 | H5: https://tradestat.commerce.gov.in/meidb/commodity_wise_all_countries_import
A6: India imports, Vitamin D | B6: CY2025 | C6: 16.67 | D6: 212562 | E6: =IF(D6=0,0,C6*1000000/D6) -> 78.424177 | F6: DGCI&S / Ministry of Commerce (tradestat) | G6: ITC-HS 29362940 | H6: https://tradestat.commerce.gov.in/meidb/commodity_wise_all_countries_import
A7: India exports, Vitamin D | B7: CY2020 | C7: 17.63 | D7: 114306 | E7: =IF(D7=0,0,C7*1000000/D7) -> 154.23512 | F7: DGCI&S / Ministry of Commerce (tradestat) | G7: ITC-HS 29362940 | H7: https://tradestat.commerce.gov.in/meidb/commodity_wise_all_countries_export
A8: India exports, Vitamin D | B8: CY2022 | C8: 16.97 | D8: 106865 | E8: =IF(D8=0,0,C8*1000000/D8) -> 158.79848 | F8: DGCI&S / Ministry of Commerce (tradestat) | G8: ITC-HS 29362940 | H8: https://tradestat.commerce.gov.in/meidb/commodity_wise_all_countries_export
A9: India exports, Vitamin D | B9: CY2025 | C9: 29.95 | D9: 201222 | E9: =IF(D9=0,0,C9*1000000/D9) -> 148.84058 | F9: DGCI&S / Ministry of Commerce (tradestat) | G9: ITC-HS 29362940 | H9: https://tradestat.commerce.gov.in/meidb/commodity_wise_all_countries_export
A10: Brazil imports, Vitamin D3 unmixed | B10: 2020 | C10: 11.26287 | D10: 203950 | E10: =IF(D10=0,0,C10*1000000/D10) -> 55.223682 | F10: SECEX/MDIC Comex Stat | G10: NCM 29362921 | H10: https://comexstat.mdic.gov.br/en/geral
A11: Brazil imports, Vitamin D3 unmixed | B11: 2022 | C11: 17.394553 | D11: 136778 | E11: =IF(D11=0,0,C11*1000000/D11) -> 127.17362 | F11: SECEX/MDIC Comex Stat | G11: NCM 29362921 | H11: https://comexstat.mdic.gov.br/en/geral
A12: Brazil imports, Vitamin D3 unmixed | B12: 2025 | C12: 14.755015 | D12: 343852 | E12: =IF(D12=0,0,C12*1000000/D12) -> 42.910947 | F12: SECEX/MDIC Comex Stat | G12: NCM 29362921 | H12: https://comexstat.mdic.gov.br/en/geral
A13: Brazil imports, Vitamin D3 unmixed | B13: Jan-Sep 2026 | C13: 11.742568 | D13: 206236 | E13: =IF(D13=0,0,C13*1000000/D13) -> 56.937528 | F13: SECEX/MDIC Comex Stat | G13: NCM 29362921 | H13: https://comexstat.mdic.gov.br/en/geral
A15: Pulled 21 Oct 2026. India's code also covers D2 and analogue APIs (distorts unit values); Brazil's code is straight D3 only, so D3 inside premixes/AD3 is excluded. Volumes swing with sourcing and stock-building, so use these for price direction, not global volume.
