Workbook

Sheet Time Series
A1: Symbiotec Pharmalab - regulatory inspections by agency, site and fiscal year (FY16-FY26)
A2: Rau (Indore; FEI 3005122933) and Pithampur SEZ (Dhar; FEI 3009298759). Indian FY = Apr-Mar. Counts are formulas over 'Event Log' (rows flagged Counted = Yes); inspections bucketed by end date, except where an inspection straddles FY-end (then by start). Blue = hard-coded company disclosures.
A5: Agency | B5: Site | C5: FY16 | D5: FY17 | E5: FY18 | F5: FY19 | G5: FY20 | H5: FY21 | I5: FY22 | J5: FY23 | K5: FY24 | L5: FY25 | M5: FY26 | N5: Total FY16-26 | O5: FY27 YTD (memo)
A6: US FDA | B6: Rau | C6: =COUNTIFS('Event Log'!$B$5:$B$49,$A6,'Event Log'!$C$5:$C$49,$B6,'Event Log'!$D$5:$D$49,C$5,'Event Log'!$I$5:$I$49,"Yes") -> 0 | D6: =COUNTIFS('Event Log'!$B$5:$B$49,$A6,'Event Log'!$C$5:$C$49,$B6,'Event Log'!$D$5:$D$49,D$5,'Event Log'!$I$5:$I$49,"Yes") -> 0 | E6: =COUNTIFS('Event Log'!$B$5:$B$49,$A6,'Event Log'!$C$5:$C$49,$B6,'Event Log'!$D$5:$D$49,E$5,'Event Log'!$I$5:$I$49,"Yes") -> 1 | F6: =COUNTIFS('Event Log'!$B$5:$B$49,$A6,'Event Log'!$C$5:$C$49,$B6,'Event Log'!$D$5:$D$49,F$5,'Event Log'!$I$5:$I$49,"Yes") -> 0 | G6: =COUNTIFS('Event Log'!$B$5:$B$49,$A6,'Event Log'!$C$5:$C$49,$B6,'Event Log'!$D$5:$D$49,G$5,'Event Log'!$I$5:$I$49,"Yes") -> 2 | H6: =COUNTIFS('Event Log'!$B$5:$B$49,$A6,'Event Log'!$C$5:$C$49,$B6,'Event Log'!$D$5:$D$49,H$5,'Event Log'!$I$5:$I$49,"Yes") -> 0 | I6: =COUNTIFS('Event Log'!$B$5:$B$49,$A6,'Event Log'!$C$5:$C$49,$B6,'Event Log'!$D$5:$D$49,I$5,'Event Log'!$I$5:$I$49,"Yes") -> 0 | J6: =COUNTIFS('Event Log'!$B$5:$B$49,$A6,'Event Log'!$C$5:$C$49,$B6,'Event Log'!$D$5:$D$49,J$5,'Event Log'!$I$5:$I$49,"Yes") -> 0 | ... M6: =COUNTIFS('Event Log'!$B$5:$B$49,$A6,'Event Log'!$C$5:$C$49,$B6,'Event Log'!$D$5:$D$49,M$5,'Event Log'!$I$5:$I$49,"Yes") -> 1 | N6: =SUM(C6:M6) -> 4 | O6: =COUNTIFS('Event Log'!$B$5:$B$49,$A6,'Event Log'!$C$5:$C$49,$B6,'Event Log'!$D$5:$D$49,"FY27",'Event Log'!$I$5:$I$49,"Yes") -> 0
A7: US FDA | B7: Pithampur | C7: =COUNTIFS('Event Log'!$B$5:$B$49,$A7,'Event Log'!$C$5:$C$49,$B7,'Event Log'!$D$5:$D$49,C$5,'Event Log'!$I$5:$I$49,"Yes") -> 1 | D7: =COUNTIFS('Event Log'!$B$5:$B$49,$A7,'Event Log'!$C$5:$C$49,$B7,'Event Log'!$D$5:$D$49,D$5,'Event Log'!$I$5:$I$49,"Yes") -> 0 | E7: =COUNTIFS('Event Log'!$B$5:$B$49,$A7,'Event Log'!$C$5:$C$49,$B7,'Event Log'!$D$5:$D$49,E$5,'Event Log'!$I$5:$I$49,"Yes") -> 1 | F7: =COUNTIFS('Event Log'!$B$5:$B$49,$A7,'Event Log'!$C$5:$C$49,$B7,'Event Log'!$D$5:$D$49,F$5,'Event Log'!$I$5:$I$49,"Yes") -> 0 | G7: =COUNTIFS('Event Log'!$B$5:$B$49,$A7,'Event Log'!$C$5:$C$49,$B7,'Event Log'!$D$5:$D$49,G$5,'Event Log'!$I$5:$I$49,"Yes") -> 1 | H7: =COUNTIFS('Event Log'!$B$5:$B$49,$A7,'Event Log'!$C$5:$C$49,$B7,'Event Log'!$D$5:$D$49,H$5,'Event Log'!$I$5:$I$49,"Yes") -> 0 | I7: =COUNTIFS('Event Log'!$B$5:$B$49,$A7,'Event Log'!$C$5:$C$49,$B7,'Event Log'!$D$5:$D$49,I$5,'Event Log'!$I$5:$I$49,"Yes") -> 0 | J7: =COUNTIFS('Event Log'!$B$5:$B$49,$A7,'Event Log'!$C$5:$C$49,$B7,'Event Log'!$D$5:$D$49,J$5,'Event Log'!$I$5:$I$49,"Yes") -> 1 | ... M7: =COUNTIFS('Event Log'!$B$5:$B$49,$A7,'Event Log'!$C$5:$C$49,$B7,'Event Log'!$D$5:$D$49,M$5,'Event Log'!$I$5:$I$49,"Yes") -> 0 | N7: =SUM(C7:M7) -> 5 | O7: =COUNTIFS('Event Log'!$B$5:$B$49,$A7,'Event Log'!$C$5:$C$49,$B7,'Event Log'!$D$5:$D$49,"FY27",'Event Log'!$I$5:$I$49,"Yes") -> 1
A8: EU-GMP | B8: Rau | C8: =COUNTIFS('Event Log'!$B$5:$B$49,$A8,'Event Log'!$C$5:$C$49,$B8,'Event Log'!$D$5:$D$49,C$5,'Event Log'!$I$5:$I$49,"Yes") -> 1 | D8: =COUNTIFS('Event Log'!$B$5:$B$49,$A8,'Event Log'!$C$5:$C$49,$B8,'Event Log'!$D$5:$D$49,D$5,'Event Log'!$I$5:$I$49,"Yes") -> 0 | E8: =COUNTIFS('Event Log'!$B$5:$B$49,$A8,'Event Log'!$C$5:$C$49,$B8,'Event Log'!$D$5:$D$49,E$5,'Event Log'!$I$5:$I$49,"Yes") -> 0 | F8: =COUNTIFS('Event Log'!$B$5:$B$49,$A8,'Event Log'!$C$5:$C$49,$B8,'Event Log'!$D$5:$D$49,F$5,'Event Log'!$I$5:$I$49,"Yes") -> 1 | G8: =COUNTIFS('Event Log'!$B$5:$B$49,$A8,'Event Log'!$C$5:$C$49,$B8,'Event Log'!$D$5:$D$49,G$5,'Event Log'!$I$5:$I$49,"Yes") -> 1 | H8: =COUNTIFS('Event Log'!$B$5:$B$49,$A8,'Event Log'!$C$5:$C$49,$B8,'Event Log'!$D$5:$D$49,H$5,'Event Log'!$I$5:$I$49,"Yes") -> 1 | I8: =COUNTIFS('Event Log'!$B$5:$B$49,$A8,'Event Log'!$C$5:$C$49,$B8,'Event Log'!$D$5:$D$49,I$5,'Event Log'!$I$5:$I$49,"Yes") -> 0 | J8: =COUNTIFS('Event Log'!$B$5:$B$49,$A8,'Event Log'!$C$5:$C$49,$B8,'Event Log'!$D$5:$D$49,J$5,'Event Log'!$I$5:$I$49,"Yes") -> 1 | ... M8: =COUNTIFS('Event Log'!$B$5:$B$49,$A8,'Event Log'!$C$5:$C$49,$B8,'Event Log'!$D$5:$D$49,M$5,'Event Log'!$I$5:$I$49,"Yes") -> 1 | N8: =SUM(C8:M8) -> 6 | O8: =COUNTIFS('Event Log'!$B$5:$B$49,$A8,'Event Log'!$C$5:$C$49,$B8,'Event Log'!$D$5:$D$49,"FY27",'Event Log'!$I$5:$I$49,"Yes") -> 0
A9: EU-GMP | B9: Pithampur | C9: =COUNTIFS('Event Log'!$B$5:$B$49,$A9,'Event Log'!$C$5:$C$49,$B9,'Event Log'!$D$5:$D$49,C$5,'Event Log'!$I$5:$I$49,"Yes") -> 1 | D9: =COUNTIFS('Event Log'!$B$5:$B$49,$A9,'Event Log'!$C$5:$C$49,$B9,'Event Log'!$D$5:$D$49,D$5,'Event Log'!$I$5:$I$49,"Yes") -> 0 | E9: =COUNTIFS('Event Log'!$B$5:$B$49,$A9,'Event Log'!$C$5:$C$49,$B9,'Event Log'!$D$5:$D$49,E$5,'Event Log'!$I$5:$I$49,"Yes") -> 0 | F9: =COUNTIFS('Event Log'!$B$5:$B$49,$A9,'Event Log'!$C$5:$C$49,$B9,'Event Log'!$D$5:$D$49,F$5,'Event Log'!$I$5:$I$49,"Yes") -> 1 | G9: =COUNTIFS('Event Log'!$B$5:$B$49,$A9,'Event Log'!$C$5:$C$49,$B9,'Event Log'!$D$5:$D$49,G$5,'Event Log'!$I$5:$I$49,"Yes") -> 0 | H9: =COUNTIFS('Event Log'!$B$5:$B$49,$A9,'Event Log'!$C$5:$C$49,$B9,'Event Log'!$D$5:$D$49,H$5,'Event Log'!$I$5:$I$49,"Yes") -> 0 | I9: =COUNTIFS('Event Log'!$B$5:$B$49,$A9,'Event Log'!$C$5:$C$49,$B9,'Event Log'!$D$5:$D$49,I$5,'Event Log'!$I$5:$I$49,"Yes") -> 0 | J9: =COUNTIFS('Event Log'!$B$5:$B$49,$A9,'Event Log'!$C$5:$C$49,$B9,'Event Log'!$D$5:$D$49,J$5,'Event Log'!$I$5:$I$49,"Yes") -> 0 | ... M9: =COUNTIFS('Event Log'!$B$5:$B$49,$A9,'Event Log'!$C$5:$C$49,$B9,'Event Log'!$D$5:$D$49,M$5,'Event Log'!$I$5:$I$49,"Yes") -> 1 | N9: =SUM(C9:M9) -> 4 | O9: =COUNTIFS('Event Log'!$B$5:$B$49,$A9,'Event Log'!$C$5:$C$49,$B9,'Event Log'!$D$5:$D$49,"FY27",'Event Log'!$I$5:$I$49,"Yes") -> 0
A10: ANVISA | B10: Rau | C10: =COUNTIFS('Event Log'!$B$5:$B$49,$A10,'Event Log'!$C$5:$C$49,$B10,'Event Log'!$D$5:$D$49,C$5,'Event Log'!$I$5:$I$49,"Yes") -> 0 | D10: =COUNTIFS('Event Log'!$B$5:$B$49,$A10,'Event Log'!$C$5:$C$49,$B10,'Event Log'!$D$5:$D$49,D$5,'Event Log'!$I$5:$I$49,"Yes") -> 0 | E10: =COUNTIFS('Event Log'!$B$5:$B$49,$A10,'Event Log'!$C$5:$C$49,$B10,'Event Log'!$D$5:$D$49,E$5,'Event Log'!$I$5:$I$49,"Yes") -> 0 | F10: =COUNTIFS('Event Log'!$B$5:$B$49,$A10,'Event Log'!$C$5:$C$49,$B10,'Event Log'!$D$5:$D$49,F$5,'Event Log'!$I$5:$I$49,"Yes") -> 0 | G10: =COUNTIFS('Event Log'!$B$5:$B$49,$A10,'Event Log'!$C$5:$C$49,$B10,'Event Log'!$D$5:$D$49,G$5,'Event Log'!$I$5:$I$49,"Yes") -> 0 | H10: =COUNTIFS('Event Log'!$B$5:$B$49,$A10,'Event Log'!$C$5:$C$49,$B10,'Event Log'!$D$5:$D$49,H$5,'Event Log'!$I$5:$I$49,"Yes") -> 0 | I10: =COUNTIFS('Event Log'!$B$5:$B$49,$A10,'Event Log'!$C$5:$C$49,$B10,'Event Log'!$D$5:$D$49,I$5,'Event Log'!$I$5:$I$49,"Yes") -> 0 | J10: =COUNTIFS('Event Log'!$B$5:$B$49,$A10,'Event Log'!$C$5:$C$49,$B10,'Event Log'!$D$5:$D$49,J$5,'Event Log'!$I$5:$I$49,"Yes") -> 0 | ... M10: =COUNTIFS('Event Log'!$B$5:$B$49,$A10,'Event Log'!$C$5:$C$49,$B10,'Event Log'!$D$5:$D$49,M$5,'Event Log'!$I$5:$I$49,"Yes") -> 0 | N10: =SUM(C10:M10) -> 0 | O10: =COUNTIFS('Event Log'!$B$5:$B$49,$A10,'Event Log'!$C$5:$C$49,$B10,'Event Log'!$D$5:$D$49,"FY27",'Event Log'!$I$5:$I$49,"Yes") -> 0
A11: ANVISA | B11: Pithampur | C11: =COUNTIFS('Event Log'!$B$5:$B$49,$A11,'Event Log'!$C$5:$C$49,$B11,'Event Log'!$D$5:$D$49,C$5,'Event Log'!$I$5:$I$49,"Yes") -> 0 | D11: =COUNTIFS('Event Log'!$B$5:$B$49,$A11,'Event Log'!$C$5:$C$49,$B11,'Event Log'!$D$5:$D$49,D$5,'Event Log'!$I$5:$I$49,"Yes") -> 0 | E11: =COUNTIFS('Event Log'!$B$5:$B$49,$A11,'Event Log'!$C$5:$C$49,$B11,'Event Log'!$D$5:$D$49,E$5,'Event Log'!$I$5:$I$49,"Yes") -> 0 | F11: =COUNTIFS('Event Log'!$B$5:$B$49,$A11,'Event Log'!$C$5:$C$49,$B11,'Event Log'!$D$5:$D$49,F$5,'Event Log'!$I$5:$I$49,"Yes") -> 0 | G11: =COUNTIFS('Event Log'!$B$5:$B$49,$A11,'Event Log'!$C$5:$C$49,$B11,'Event Log'!$D$5:$D$49,G$5,'Event Log'!$I$5:$I$49,"Yes") -> 0 | H11: =COUNTIFS('Event Log'!$B$5:$B$49,$A11,'Event Log'!$C$5:$C$49,$B11,'Event Log'!$D$5:$D$49,H$5,'Event Log'!$I$5:$I$49,"Yes") -> 0 | I11: =COUNTIFS('Event Log'!$B$5:$B$49,$A11,'Event Log'!$C$5:$C$49,$B11,'Event Log'!$D$5:$D$49,I$5,'Event Log'!$I$5:$I$49,"Yes") -> 0 | J11: =COUNTIFS('Event Log'!$B$5:$B$49,$A11,'Event Log'!$C$5:$C$49,$B11,'Event Log'!$D$5:$D$49,J$5,'Event Log'!$I$5:$I$49,"Yes") -> 0 | ... M11: =COUNTIFS('Event Log'!$B$5:$B$49,$A11,'Event Log'!$C$5:$C$49,$B11,'Event Log'!$D$5:$D$49,M$5,'Event Log'!$I$5:$I$49,"Yes") -> 0 | N11: =SUM(C11:M11) -> 0 | O11: =COUNTIFS('Event Log'!$B$5:$B$49,$A11,'Event Log'!$C$5:$C$49,$B11,'Event Log'!$D$5:$D$49,"FY27",'Event Log'!$I$5:$I$49,"Yes") -> 0
A12: PMDA | B12: Rau | C12: =COUNTIFS('Event Log'!$B$5:$B$49,$A12,'Event Log'!$C$5:$C$49,$B12,'Event Log'!$D$5:$D$49,C$5,'Event Log'!$I$5:$I$49,"Yes") -> 0 | D12: =COUNTIFS('Event Log'!$B$5:$B$49,$A12,'Event Log'!$C$5:$C$49,$B12,'Event Log'!$D$5:$D$49,D$5,'Event Log'!$I$5:$I$49,"Yes") -> 0 | E12: =COUNTIFS('Event Log'!$B$5:$B$49,$A12,'Event Log'!$C$5:$C$49,$B12,'Event Log'!$D$5:$D$49,E$5,'Event Log'!$I$5:$I$49,"Yes") -> 0 | F12: =COUNTIFS('Event Log'!$B$5:$B$49,$A12,'Event Log'!$C$5:$C$49,$B12,'Event Log'!$D$5:$D$49,F$5,'Event Log'!$I$5:$I$49,"Yes") -> 0 | G12: =COUNTIFS('Event Log'!$B$5:$B$49,$A12,'Event Log'!$C$5:$C$49,$B12,'Event Log'!$D$5:$D$49,G$5,'Event Log'!$I$5:$I$49,"Yes") -> 0 | H12: =COUNTIFS('Event Log'!$B$5:$B$49,$A12,'Event Log'!$C$5:$C$49,$B12,'Event Log'!$D$5:$D$49,H$5,'Event Log'!$I$5:$I$49,"Yes") -> 0 | I12: =COUNTIFS('Event Log'!$B$5:$B$49,$A12,'Event Log'!$C$5:$C$49,$B12,'Event Log'!$D$5:$D$49,I$5,'Event Log'!$I$5:$I$49,"Yes") -> 0 | J12: =COUNTIFS('Event Log'!$B$5:$B$49,$A12,'Event Log'!$C$5:$C$49,$B12,'Event Log'!$D$5:$D$49,J$5,'Event Log'!$I$5:$I$49,"Yes") -> 0 | ... M12: =COUNTIFS('Event Log'!$B$5:$B$49,$A12,'Event Log'!$C$5:$C$49,$B12,'Event Log'!$D$5:$D$49,M$5,'Event Log'!$I$5:$I$49,"Yes") -> 0 | N12: =SUM(C12:M12) -> 0 | O12: =COUNTIFS('Event Log'!$B$5:$B$49,$A12,'Event Log'!$C$5:$C$49,$B12,'Event Log'!$D$5:$D$49,"FY27",'Event Log'!$I$5:$I$49,"Yes") -> 0
A13: PMDA | B13: Pithampur | C13: =COUNTIFS('Event Log'!$B$5:$B$49,$A13,'Event Log'!$C$5:$C$49,$B13,'Event Log'!$D$5:$D$49,C$5,'Event Log'!$I$5:$I$49,"Yes") -> 0 | D13: =COUNTIFS('Event Log'!$B$5:$B$49,$A13,'Event Log'!$C$5:$C$49,$B13,'Event Log'!$D$5:$D$49,D$5,'Event Log'!$I$5:$I$49,"Yes") -> 0 | E13: =COUNTIFS('Event Log'!$B$5:$B$49,$A13,'Event Log'!$C$5:$C$49,$B13,'Event Log'!$D$5:$D$49,E$5,'Event Log'!$I$5:$I$49,"Yes") -> 0 | F13: =COUNTIFS('Event Log'!$B$5:$B$49,$A13,'Event Log'!$C$5:$C$49,$B13,'Event Log'!$D$5:$D$49,F$5,'Event Log'!$I$5:$I$49,"Yes") -> 0 | G13: =COUNTIFS('Event Log'!$B$5:$B$49,$A13,'Event Log'!$C$5:$C$49,$B13,'Event Log'!$D$5:$D$49,G$5,'Event Log'!$I$5:$I$49,"Yes") -> 0 | H13: =COUNTIFS('Event Log'!$B$5:$B$49,$A13,'Event Log'!$C$5:$C$49,$B13,'Event Log'!$D$5:$D$49,H$5,'Event Log'!$I$5:$I$49,"Yes") -> 0 | I13: =COUNTIFS('Event Log'!$B$5:$B$49,$A13,'Event Log'!$C$5:$C$49,$B13,'Event Log'!$D$5:$D$49,I$5,'Event Log'!$I$5:$I$49,"Yes") -> 0 | J13: =COUNTIFS('Event Log'!$B$5:$B$49,$A13,'Event Log'!$C$5:$C$49,$B13,'Event Log'!$D$5:$D$49,J$5,'Event Log'!$I$5:$I$49,"Yes") -> 0 | ... M13: =COUNTIFS('Event Log'!$B$5:$B$49,$A13,'Event Log'!$C$5:$C$49,$B13,'Event Log'!$D$5:$D$49,M$5,'Event Log'!$I$5:$I$49,"Yes") -> 0 | N13: =SUM(C13:M13) -> 0 | O13: =COUNTIFS('Event Log'!$B$5:$B$49,$A13,'Event Log'!$C$5:$C$49,$B13,'Event Log'!$D$5:$D$49,"FY27",'Event Log'!$I$5:$I$49,"Yes") -> 0
A14: MFDS (Korea FDA) | B14: Rau | C14: =COUNTIFS('Event Log'!$B$5:$B$49,$A14,'Event Log'!$C$5:$C$49,$B14,'Event Log'!$D$5:$D$49,C$5,'Event Log'!$I$5:$I$49,"Yes") -> 0 | D14: =COUNTIFS('Event Log'!$B$5:$B$49,$A14,'Event Log'!$C$5:$C$49,$B14,'Event Log'!$D$5:$D$49,D$5,'Event Log'!$I$5:$I$49,"Yes") -> 0 | E14: =COUNTIFS('Event Log'!$B$5:$B$49,$A14,'Event Log'!$C$5:$C$49,$B14,'Event Log'!$D$5:$D$49,E$5,'Event Log'!$I$5:$I$49,"Yes") -> 0 | F14: =COUNTIFS('Event Log'!$B$5:$B$49,$A14,'Event Log'!$C$5:$C$49,$B14,'Event Log'!$D$5:$D$49,F$5,'Event Log'!$I$5:$I$49,"Yes") -> 0 | G14: =COUNTIFS('Event Log'!$B$5:$B$49,$A14,'Event Log'!$C$5:$C$49,$B14,'Event Log'!$D$5:$D$49,G$5,'Event Log'!$I$5:$I$49,"Yes") -> 0 | H14: =COUNTIFS('Event Log'!$B$5:$B$49,$A14,'Event Log'!$C$5:$C$49,$B14,'Event Log'!$D$5:$D$49,H$5,'Event Log'!$I$5:$I$49,"Yes") -> 0 | I14: =COUNTIFS('Event Log'!$B$5:$B$49,$A14,'Event Log'!$C$5:$C$49,$B14,'Event Log'!$D$5:$D$49,I$5,'Event Log'!$I$5:$I$49,"Yes") -> 0 | J14: =COUNTIFS('Event Log'!$B$5:$B$49,$A14,'Event Log'!$C$5:$C$49,$B14,'Event Log'!$D$5:$D$49,J$5,'Event Log'!$I$5:$I$49,"Yes") -> 0 | ... M14: =COUNTIFS('Event Log'!$B$5:$B$49,$A14,'Event Log'!$C$5:$C$49,$B14,'Event Log'!$D$5:$D$49,M$5,'Event Log'!$I$5:$I$49,"Yes") -> 0 | N14: =SUM(C14:M14) -> 0 | O14: =COUNTIFS('Event Log'!$B$5:$B$49,$A14,'Event Log'!$C$5:$C$49,$B14,'Event Log'!$D$5:$D$49,"FY27",'Event Log'!$I$5:$I$49,"Yes") -> 0
A15: MFDS (Korea FDA) | B15: Pithampur | C15: =COUNTIFS('Event Log'!$B$5:$B$49,$A15,'Event Log'!$C$5:$C$49,$B15,'Event Log'!$D$5:$D$49,C$5,'Event Log'!$I$5:$I$49,"Yes") -> 0 | D15: =COUNTIFS('Event Log'!$B$5:$B$49,$A15,'Event Log'!$C$5:$C$49,$B15,'Event Log'!$D$5:$D$49,D$5,'Event Log'!$I$5:$I$49,"Yes") -> 0 | E15: =COUNTIFS('Event Log'!$B$5:$B$49,$A15,'Event Log'!$C$5:$C$49,$B15,'Event Log'!$D$5:$D$49,E$5,'Event Log'!$I$5:$I$49,"Yes") -> 0 | F15: =COUNTIFS('Event Log'!$B$5:$B$49,$A15,'Event Log'!$C$5:$C$49,$B15,'Event Log'!$D$5:$D$49,F$5,'Event Log'!$I$5:$I$49,"Yes") -> 0 | G15: =COUNTIFS('Event Log'!$B$5:$B$49,$A15,'Event Log'!$C$5:$C$49,$B15,'Event Log'!$D$5:$D$49,G$5,'Event Log'!$I$5:$I$49,"Yes") -> 0 | H15: =COUNTIFS('Event Log'!$B$5:$B$49,$A15,'Event Log'!$C$5:$C$49,$B15,'Event Log'!$D$5:$D$49,H$5,'Event Log'!$I$5:$I$49,"Yes") -> 0 | I15: =COUNTIFS('Event Log'!$B$5:$B$49,$A15,'Event Log'!$C$5:$C$49,$B15,'Event Log'!$D$5:$D$49,I$5,'Event Log'!$I$5:$I$49,"Yes") -> 0 | J15: =COUNTIFS('Event Log'!$B$5:$B$49,$A15,'Event Log'!$C$5:$C$49,$B15,'Event Log'!$D$5:$D$49,J$5,'Event Log'!$I$5:$I$49,"Yes") -> 0 | ... M15: =COUNTIFS('Event Log'!$B$5:$B$49,$A15,'Event Log'!$C$5:$C$49,$B15,'Event Log'!$D$5:$D$49,M$5,'Event Log'!$I$5:$I$49,"Yes") -> 0 | N15: =SUM(C15:M15) -> 0 | O15: =COUNTIFS('Event Log'!$B$5:$B$49,$A15,'Event Log'!$C$5:$C$49,$B15,'Event Log'!$D$5:$D$49,"FY27",'Event Log'!$I$5:$I$49,"Yes") -> 0
A16: Identified inspections - total | C16: =SUM(C6:C15) -> 3 | D16: =SUM(D6:D15) -> 0 | E16: =SUM(E6:E15) -> 2 | F16: =SUM(F6:F15) -> 2 | G16: =SUM(G6:G15) -> 4 | H16: =SUM(H6:H15) -> 1 | I16: =SUM(I6:I15) -> 0 | J16: =SUM(J6:J15) -> 2 | ... O16: =SUM(O6:O15) -> 1
A17: of which US FDA | C17: =C6+C7 -> 1 | D17: =D6+D7 -> 0 | E17: =E6+E7 -> 2 | F17: =F6+F7 -> 0 | G17: =G6+G7 -> 3 | H17: =H6+H7 -> 0 | I17: =I6+I7 -> 0 | J17: =J6+J7 -> 1 | ... O17: =O6+O7 -> 1
A18: of which EU-GMP | C18: =C8+C9 -> 2 | D18: =D8+D9 -> 0 | E18: =E8+E9 -> 0 | F18: =F8+F9 -> 2 | G18: =G8+G9 -> 1 | H18: =H8+H9 -> 1 | I18: =I8+I9 -> 0 | J18: =J8+J9 -> 1 | ... O18: =O8+O9 -> 0
A19: of which ANVISA / PMDA / MFDS | C19: =SUM(C10:C15) -> 0 | D19: =SUM(D10:D15) -> 0 | E19: =SUM(E10:E15) -> 0 | F19: =SUM(F10:F15) -> 0 | G19: =SUM(G10:G15) -> 0 | H19: =SUM(H10:H15) -> 0 | I19: =SUM(I10:I15) -> 0 | J19: =SUM(J10:J15) -> 0 | ... O19: =SUM(O10:O15) -> 0
A20: of which adverse (FDA OAI / EU non-compliance) | C20: =COUNTIFS('Event Log'!$D$5:$D$49,C$5,'Event Log'!$I$5:$I$49,"Yes",'Event Log'!$K$5:$K$49,"Yes") -> 0 | D20: =COUNTIFS('Event Log'!$D$5:$D$49,D$5,'Event Log'!$I$5:$I$49,"Yes",'Event Log'!$K$5:$K$49,"Yes") -> 0 | E20: =COUNTIFS('Event Log'!$D$5:$D$49,E$5,'Event Log'!$I$5:$I$49,"Yes",'Event Log'!$K$5:$K$49,"Yes") -> 0 | F20: =COUNTIFS('Event Log'!$D$5:$D$49,F$5,'Event Log'!$I$5:$I$49,"Yes",'Event Log'!$K$5:$K$49,"Yes") -> 0 | G20: =COUNTIFS('Event Log'!$D$5:$D$49,G$5,'Event Log'!$I$5:$I$49,"Yes",'Event Log'!$K$5:$K$49,"Yes") -> 2 | H20: =COUNTIFS('Event Log'!$D$5:$D$49,H$5,'Event Log'!$I$5:$I$49,"Yes",'Event Log'!$K$5:$K$49,"Yes") -> 0 | I20: =COUNTIFS('Event Log'!$D$5:$D$49,I$5,'Event Log'!$I$5:$I$49,"Yes",'Event Log'!$K$5:$K$49,"Yes") -> 0 | J20: =COUNTIFS('Event Log'!$D$5:$D$49,J$5,'Event Log'!$I$5:$I$49,"Yes",'Event Log'!$K$5:$K$49,"Yes") -> 0 | ... M20: =COUNTIFS('Event Log'!$D$5:$D$49,M$5,'Event Log'!$I$5:$I$49,"Yes",'Event Log'!$K$5:$K$49,"Yes") -> 0 | N20: =SUM(C20:M20) -> 2 | O20: =COUNTIFS('Event Log'!$D$5:$D$49,"FY27",'Event Log'!$I$5:$I$49,"Yes",'Event Log'!$K$5:$K$49,"Yes") -> 0
A21: Company-disclosed regulatory audits, both sites (DRHP/RHP) | C21: n/d | D21: n/d | E21: n/d | F21: n/d | G21: n/d | H21: n/d | I21: n/d | J21: 4 | K21: 2 | L21: 4 | M21: 3
A22: Unattributed company-disclosed audits (disclosed - identified) | C22: =IF(ISNUMBER(C21),MAX(0,C21-C16),"") | D22: =IF(ISNUMBER(D21),MAX(0,D21-D16),"") | E22: =IF(ISNUMBER(E21),MAX(0,E21-E16),"") | F22: =IF(ISNUMBER(F21),MAX(0,F21-F16),"") | G22: =IF(ISNUMBER(G21),MAX(0,G21-G16),"") | H22: =IF(ISNUMBER(H21),MAX(0,H21-H16),"") | I22: =IF(ISNUMBER(I21),MAX(0,I21-I16),"") | J22: =IF(ISNUMBER(J21),MAX(0,J21-J16),"") -> 2 | ... M22: =IF(ISNUMBER(M21),MAX(0,M21-M16),"") -> 0 | N22: =SUM(C22:M22) -> 6
A24: Event detail by fiscal year (inspections; [cert]/[accr]/[claim] = certificate, accreditation or undated company claim - not counted above)
A25: Agency | B25: Site | C25: FY16 | D25: FY17 | E25: FY18 | F25: FY19 | G25: FY20 | H25: FY21 | I25: FY22 | J25: FY23 | K25: FY24 | L25: FY25 | M25: FY26 | O25: FY27 YTD (memo)
A26: US FDA | B26: Rau | E26: May-17 VAI | G26: Sep-19 VAI Oct-19 VAI | M26: Mar-Apr-26 VAI, EIR
A27: US FDA | B27: Pithampur | C27: Apr-15 NAI | E27: May-17 VAI, 6 obs | G27: Jul-19 OAI, 4 obs | J27: Sep-22 VAI, 6 obs | K27: ~May-23 483 (likely PAI) | O27: Aug-26 VAI, 4 obs
A28: EU-GMP | B28: Rau | C28: 2015 re-qual (yr only) | F28: 2018 re-qual (yr only) | G28: NON-COMPLIANCE (sterile), pub. Apr-20 | H28: Jun-20 remote assessment, cert | J28: ~Q4FY23 insp., cert Apr-23 | M28: Mar-26 insp., cert
A29: EU-GMP | B29: Pithampur | C29: 2015 re-qual (yr only) | F29: 2018 re-qual (yr only) | K29: ~Q3FY24 insp., cert Feb-24 | M29: Mar-26 insp., cert
A30: ANVISA | B30: Rau | M30: [cert] Aug-25 first CBPF
A31: ANVISA | B31: Pithampur | K31: [cert] Jul-23 CBPF | L31: [cert] May-24 CBPF (hormones) | M31: [cert] Jul-25 CBPF re-grant | O31: [cert] May-26 auto-renewal
A32: PMDA | B32: Rau | D32: [accr] ~Feb-17 FMA (inferred) | I32: [accr] Feb-22 FMA renewal
A33: PMDA | B33: Pithampur
A34: MFDS (Korea FDA) | B34: Rau
A35: MFDS (Korea FDA) | B35: Pithampur
A37: Shading: | C37: blue = counted inspection; red = adverse outcome (FDA OAI Jul-2019 Pithampur; EU GMP non-compliance Rau, published Apr-2020).
A38: ANVISA / PMDA / MFDS: | C38: no dated on-site inspection found in any primary source. ANVISA certificates (DOU) appear desk/reliance-based; PMDA foreign-manufacturer accreditation is document-based; MFDS approval is an undated company claim. The company does say ANVISA and PMDA inspected in FY23-FY26 - these sit in the 'Unattributed' row (6 audits: 2 in FY23, 4 in FY25).
A39: Year-only events: | C39: EU-GMP 2015 and 2018 re-qualifications (company milestones) are placed in FY16 and FY19 (Apr-Dec of the calendar year); they would be FY15/FY18 if they fell in Jan-Mar.
A40: Not in grid: | C40: Rau 17-Jan-2023 (Redica only; conflicts with DRHP) - see Event Log FDA-U1. KDMF/JDMF product filings and the CDSCO Oct-2021 inspection are in the Event Log only.

Sheet Reconciliation
A1: Reconciliation: company-disclosed regulatory audits vs identified inspections
A2: Company counts (DRHP/RHP Risk Factor 2) cover all regulators at both sites; agencies/dates are not disclosed.
A4: FY | B4: Company-disclosed | C4: Identified (Time Series) | D4: Unattributed | E4: Identified events | F4: Likely candidates for unattributed audits
A5: FY23 | B5: ='Time Series'!J21 -> 4 | C5: ='Time Series'!J16 -> 2 | D5: ='Time Series'!J22 -> 2 | E5: FDA-07 Pithampur Sep-2022 (VAI, 6 obs); EU-07 Rau ~Jan-Apr 2023 (cert 21-Apr-2023) | F5: PMDA (Rau; company 'three years' as of Jun-2025 -> ~2022) and MFDS/KFDA (Pithampur; 'three years' -> ~2022). Possibly the Redica-listed Rau event of 17-Jan-2023. Low confidence.
A6: FY24 | B6: ='Time Series'!K21 -> 2 | C6: ='Time Series'!K16 -> 2 | D6: ='Time Series'!K22 -> 0 | E6: FDA-08 Pithampur ~May-2023 (483); EU-08 Pithampur ~Nov-23 to Feb-24 (cert 22-Feb-2024) | F6: None - fully reconciled.
A7: FY25 | B7: ='Time Series'!L21 -> 4 | C7: ='Time Series'!L16 -> 0 | D7: ='Time Series'!L22 -> 4 | E7: None identified | F7: ANVISA / PMDA / KFDA per company (DRHP/RHP name ANVISA & PMDA among inspecting regulators; BRSR FY25 lists PMDA & KFDA). ANVISA hormone CBPF (May-2024) and Rau CBPF application (2024) fall here, but no ANVISA site visit is on record. Low confidence.
A8: FY26 | B8: ='Time Series'!M21 -> 3 | C8: ='Time Series'!M16 -> 3 | D8: ='Time Series'!M22 -> 0 | E8: EU-09 Rau Mar-2026; EU-10 Pithampur Mar-2026; FDA-09 Rau Mar-Apr 2026 (VAI) | F8: None - fully reconciled (matches Q1FY27 investor release).
A9: Total | B9: =SUM(B5:B8) -> 13 | C9: =SUM(C5:C8) -> 7 | D9: =SUM(D5:D8) -> 6
A11: DRHP states '10 inspections by regulatory agencies such as the US FDA, EU-GMP, ANVISA and PMDA' over FY23-Q1FY26 (4+2+4+0).
A12: RHP states 'nine inspections' on p.222 (= 2+4+3) but '11 inspections' on pp.147, 230, 247 - internally inconsistent.
A13: Neither document discloses the Jul-2019 FDA OAI (Pithampur) or the Apr-2020 EU GMP non-compliance (Rau sterile); both pre-date the 3-fiscal disclosure window.
A14: CARE Ratings: both facilities 'approved six times each by USFDA and EU-GMP' (Mar-2020, Feb/Dec-2022); 'seven times each' (Dec-2023, Dec-2024).

Sheet Chart
A1: Identified regulatory inspections per fiscal year, stacked by agency (data: Time Series sheet)
A2: Unattributed = company-disclosed regulatory audits (DRHP/RHP, FY23-FY26 only) not matched to a dated inspection; the company names ANVISA, PMDA and KFDA among its inspecting regulators. FY16-FY22: company counts not disclosed.

Sheet Event Log
A1: Symbiotec Pharmalab - regulatory event log, Rau & Pithampur API sites (Apr-2015 to Oct-2026)
A2: Indian FY = Apr-Mar (FY16 = Apr-2015 to Mar-2016). 'Counted as inspection?' = Yes feeds the Time Series grid. Rau FEI 3005122933; Pithampur SEZ FEI 3009298759. Compiled 30-Oct-2026 from Exa web research.
A4: ID | B4: Agency | C4: Site | D4: FY bucket | E4: Inspection start | F4: Inspection end / event date | G4: Date basis | H4: Event type | I4: Counted as inspection? | J4: Outcome / classification | K4: Adverse? | L4: Form 483 obs. | M4: Reference (FEI / ID / certificate) | N4: Confidence | O4: Notes | P4: Source 1 | Q4: Source 2
A5: FDA-01 | B5: US FDA | C5: Pithampur | D5: FY16 | F5: 42104 | G5: End date exact (FDA dashboard) | H5: cGMP surveillance inspection | I5: Yes | J5: NAI | K5: No | L5: 0 | M5: FEI 3009298759; FDA inspection ID 924417 | N5: High | O5: Company milestone '2015 Re-Accreditation by US-FDA of SEZ Site' is this same inspection. | P5: https://projects.propublica.org/rx-inspector/facilities/3009298759/ | Q5: https://www.pharmacompass.com/fda-inspection/symbiotec-pharmalab
A6: FDA-02 | B6: US FDA | C6: Pithampur | D6: FY18 | E6: 42856 | F6: 42860 | G6: Exact (Form 483) | H6: cGMP surveillance inspection | I6: Yes | J6: VAI | K6: No | L6: 6 | M6: FEI 3009298759; ID 1013794 | N6: High | O6: 483 items: GMP records signed by staff not on site (biometric mismatch), invalid stability test method, Part 11 risk assessment, supplier audits, unqualified pinhole tester. | P6: https://static.propublica.org/fda-inspection-documents/483s/2024-3040%2F483s%2F2018-10239encl2.pdf | Q6: https://projects.propublica.org/rx-inspector/facilities/3009298759/
A7: FDA-03 | B7: US FDA | C7: Rau | D7: FY18 | F7: 42867 | G7: End date exact (FDA dashboard) | H7: cGMP surveillance inspection | I7: Yes | J7: VAI | K7: No | L7: n/d | M7: FEI 3005122933; ID 1014181 | N7: High | O7: No Form 483 published. | P7: https://projects.propublica.org/rx-inspector/facilities/3005122933/ | Q7: https://www.pharmacompass.com/fda-inspection/symbiotec-pharmalab
A8: FDA-04 | B8: US FDA | C8: Pithampur | D8: FY20 | E8: 43647 | F8: 43651 | G8: Exact (Form 483) | H8: cGMP surveillance inspection | I8: Yes | J8: OAI (Official Action Indicated) | K8: Yes | L8: 4 | M8: FEI 3009298759; ID 1098217 | N8: High (dates, 483); Medium (OAI) | O8: OAI per FDA dashboard data republished by SupplierVigil and pharmaceuticalcompanies.com (Oct-2026); not checked on FDA's own dashboard. 483 cites ~21,372 aborted chromatography runs (May-17 to Jul-19), CPP monitoring, cleaning validation. No warning letter / import alert found. Not disclosed in DRHP/RHP. | P8: https://static.propublica.org/fda-inspection-documents/483s/2024-3040%2F483s%2F19008449_enc7_320.pdf | Q8: https://www.suppliervigil.com/suppliers/symbiotec-pharmalab-limited
A9: FDA-05 | B9: US FDA | C9: Rau | D9: FY20 | F9: 43721 | G9: End date exact (FDA dashboard) | H9: cGMP surveillance inspection | I9: Yes | J9: VAI | K9: No | L9: n/d | M9: FEI 3005122933; ID 1106997 | N9: High | O9: Separate inspection ID from FDA-06 (not a project-area duplicate). | P9: https://www.keypedia.com/records/fda_inspections/symbiotec-pharmalab-private-limited/b0ba173d-b65b-43a0-8818-8865313a6c3b | Q9: https://projects.propublica.org/rx-inspector/facilities/3005122933/
A10: FDA-06 | B10: US FDA | C10: Rau | D10: FY20 | F10: 43760 | G10: End date exact (FDA dashboard) | H10: cGMP surveillance inspection | I10: Yes | J10: VAI | K10: No | L10: n/d | M10: FEI 3005122933; ID 1141089 | N10: High | O10: DRHP: 'Rau Facility was last inspected by the US FDA in 2019 ... received Form 483'. | P10: https://www.keypedia.com/records/fda_inspections/symbiotec-pharmalab-private-limited/87bf2ce3-bf0d-4a25-bbbc-41c49e4acebc | Q10: https://www.pharmacompass.com/fda-inspection/symbiotec-pharmalab
A11: FDA-07 | B11: US FDA | C11: Pithampur | D11: FY23 | E11: 44830 | F11: 44834 | G11: Exact (Form 483) | H11: cGMP surveillance inspection | I11: Yes | J11: VAI | K11: No | L11: 6 | M11: FEI 3009298759; ID 1182042 | N11: High | O11: 483 items: lab controls (uncontrolled scratch calculations), cleaning validation, SCADA alarms disabled, KF software errors, method-validation review, late complaint investigations. | P11: https://static.propublica.org/fda-inspection-documents/483s/2024-10376%2F483s%2F2024-9235%2F2022-8697encl20.pdf | Q11: https://projects.propublica.org/rx-inspector/facilities/3009298759/
A12: FDA-08 | B12: US FDA | C12: Pithampur | D12: FY24 | F12: ~15-May-2023 | G12: Year from DRHP/RHP; day from Redica only | H12: Inspection - not on FDA classification dashboard (consistent with a pre-approval inspection; unconfirmed) | I12: Yes | J12: Form 483 issued; company 'subsequently received approval' | K12: No | L12: n/d | M12: FEI 3009298759 | N12: Medium | O12: DRHP p.44: 'Pithampur Facility was last inspected by the US FDA in 2023 and we received Form 483'. Redica lists an FDA investigator (U. Limchumroon) not on the 2017/2019/2022 483s. | P12: https://nsearchives.nseindia.com/corporate/Registration_19122025164857_DRHP_fillingversion.pdf | Q12: https://redica.com/document-store/sites/siteprofile/100013374/symbiotec-pharmalab-private-limited-pithampur-m-india
A13: FDA-09 | B13: US FDA | C13: Rau | D13: FY26 | E13: Mar-2026 (company) | F13: 46115 | G13: End date exact (FDA dashboard); start month per company | H13: cGMP surveillance inspection | I13: Yes | J13: VAI; EIR received | K13: No | L13: 483 issued (count n/d) | M13: FEI 3005122933; ID 1313542 | N13: High | O13: Straddles FY-end: bucketed FY26 by start month (company counts it in FY26's 3 audits); FY27 if bucketed by end date. | P13: https://nsearchives.nseindia.com/corporate/SYMBIOTEC_21092026195951_SymbiotecInvestorReleaseQ1FY2027.pdf | Q13: https://www.keypedia.com/records/fda_inspections/symbiotec-pharmalab-private-limited/6a9a8083-0914-4550-91a6-a546311d6e24
A14: FDA-10 | B14: US FDA | C14: Pithampur | D14: FY27 | E14: 46244 | F14: 46248 | G14: Exact (company filing) | H14: cGMP surveillance inspection | I14: Yes | J14: VAI; EIR announced 29-Sep-2026 | K14: No | L14: 4 | M14: FEI 3009298759; ID 1334248 | N14: High | O14: Outside FY16-26 window (memo). | P14: https://nsearchives.nseindia.com/corporate/SYMBIOTEC_29092026105720_SymbiotecUSFDAApprovalSEZ.pdf | Q14: https://www.sebi.gov.in/sebi_data/attachdocs/aug-2026/1787119258529.pdf
A15: FDA-U1 | B15: US FDA | C15: Rau | D15: FY23 | F15: 17-Jan-2023 (unverified) | G15: Redica 'last known inspection' only | H15: Unverified - excluded | I15: No | J15: n/a | K15: No | L15: n/a | M15: FEI 3005122933 | N15: Low | O15: Conflicts with DRHP ('Rau last inspected by US FDA in 2019'). Not in FDA dashboard/ProPublica/Keypedia. Possibly the EU-GMP inspection behind the 21-Apr-2023 certificate (EU-07). | P15: https://redica.com/document-store/sites/siteprofile/100194580/symbiotec-pharmalab-private-limited-rau-india | Q15: https://nsearchives.nseindia.com/corporate/Registration_19122025164857_DRHP_fillingversion.pdf
A16: EU-01 | B16: EU-GMP | C16: Rau | D16: FY16 | F16: 2015 (year only) | G16: Calendar year only (company milestone); FY15 if Jan-Mar 2015 | H16: Re-qualification inspection (implied) | I16: Yes | J16: EU-GMP certificate re-qualified | K16: No | L16: n/a | M16: Authority presumed Regierung von Oberbayern | N16: Low | O16: No certificate no. or inspection date found. | P16: https://www.symbiotec.in/about-us/milestone/
A17: EU-02 | B17: EU-GMP | C17: Pithampur | D17: FY16 | F17: 2015 (year only) | G17: Calendar year only (company milestone); FY15 if Jan-Mar 2015 | H17: Re-qualification inspection (implied) | I17: Yes | J17: EU-GMP certificate re-qualified | K17: No | L17: n/a | M17: Authority presumed Regierung von Oberbayern | N17: Low | O17: No certificate no. or inspection date found. | P17: https://www.symbiotec.in/about-us/milestone/
A18: EU-03 | B18: EU-GMP | C18: Rau | D18: FY19 | F18: 2018 (year only) | G18: Calendar year only (company milestone); FY18 if Jan-Mar 2018 | H18: Re-qualification inspection (implied) | I18: Yes | J18: EU-GMP certificate re-qualified | K18: No | L18: n/a | M18: Authority presumed Regierung von Oberbayern | N18: Low | O18: No certificate no. or inspection date found. | P18: https://www.symbiotec.in/about-us/milestone/
A19: EU-04 | B19: EU-GMP | C19: Pithampur | D19: FY19 | F19: 2018 (year only) | G19: Calendar year only (company milestone); FY18 if Jan-Mar 2018 | H19: Re-qualification inspection (implied) | I19: Yes | J19: EU-GMP certificate re-qualified | K19: No | L19: n/a | M19: Authority presumed Regierung von Oberbayern | N19: Low | O19: No certificate no. or inspection date found. | P19: https://www.symbiotec.in/about-us/milestone/
A20: EU-05 | B20: EU-GMP | C20: Rau | D20: FY20 | F20: Before 08-Apr-2020 | G20: Inferred: NCS relayed by AIFA 08-Apr-2020; inspection date not found | H20: Inspection -> Statement of GMP non-compliance (sterile) | I20: Yes | J20: NON-COMPLIANT for sterile active substances / sterile products | K20: Yes | L20: n/a | M20: Issuing EEA authority not confirmed (likely Regierung von Oberbayern) | N20: High (event); Low (date) | O20: AIFA asked MAHs to name alternative sites by 16-Apr-2020. Non-sterile APIs unaffected (Rau certificates issued Jul-2020). No longer in public EudraGMDP NCR list (likely withdrawn); lifting date not found. Not disclosed in DRHP/RHP. | P20: https://www.aifa.gov.it/-/statement-non-compliance-gmp-officina-farmaceutica-symbiotec-pharmalab-ltd-india
A21: EU-06 | B21: EU-GMP | C21: Rau | D21: FY21 | F21: 43997 | G21: Exact (EudraGMDP mirror) | H21: Distant (remote) assessment | I21: Yes | J21: GMP certificates issued 16-Jul-2020 and 24-Jul-2020 | K21: No | L21: n/a | M21: DE_BY_04_GMP_2020_0095; DE_BY_04_GMP_2020_0101 (Regierung von Oberbayern) | N21: High | O21: Remote COVID-era assessment, not on-site; scope likely non-sterile only (inference). | P21: https://www.johnsnowlabs.com/marketplace/ema-good-manufacturing-practice-certificates-of-non-eea-countries/
A22: EU-07 | B22: EU-GMP | C22: Rau | D22: FY23 | F22: ~Jan-Apr 2023 (inferred) | G22: Inferred from certificate issue date (90-day rule) | H22: On-site inspection (implied by certificate) | I22: Yes | J22: GMP certificate issued 21-Apr-2023 | K22: No | L22: n/a | M22: EudraGMDP key 160829 (DE_BY_04_...) | N22: Medium | O22: Site attributed to Rau by elimination (NCA ref PL0585; no city shown). FY24 if inspection ended 1-21 Apr 2023. | P22: https://www.pharmacompass.com/edqm-gmp/symbiotec-pharmalab
A23: EU-08 | B23: EU-GMP | C23: Pithampur | D23: FY24 | F23: ~Nov-2023 to Feb-2024 (inferred) | G23: Inferred from certificate issue date (90-day rule) | H23: On-site inspection (implied by certificate) | I23: Yes | J23: GMP certificate issued 22-Feb-2024 | K23: No | L23: n/a | M23: EudraGMDP key 167889 (DE_BY_04_...) | N23: Medium | P23: https://www.pharmacompass.com/edqm-gmp/symbiotec-pharmalab
A24: EU-09 | B24: EU-GMP | C24: Rau | D24: FY26 | F24: 46094 | G24: Exact (EudraGMDP mirror); company confirms Mar-2026 | H24: On-site inspection | I24: Yes | J24: GMP certificate issued 29-May-2026 | K24: No | L24: n/a | M24: DE_BY_04_GMP_2026_0077 (Regierung von Oberbayern) | N24: High | P24: https://www.pharmajungle.com/eudra-gmp | Q24: https://nsearchives.nseindia.com/corporate/SYMBIOTEC_21092026195951_SymbiotecInvestorReleaseQ1FY2027.pdf
A25: EU-10 | B25: EU-GMP | C25: Pithampur | D25: FY26 | F25: 46101 | G25: Exact (EudraGMDP mirror); company confirms Mar-2026 | H25: On-site inspection | I25: Yes | J25: GMP certificate issued 10-Jun-2026 | K25: No | L25: n/a | M25: DE_BY_04_GMP_2026_0078 (Regierung von Oberbayern) | N25: High | P25: https://www.pharmajungle.com/eudra-gmp | Q25: https://nsearchives.nseindia.com/corporate/SYMBIOTEC_21092026195951_SymbiotecInvestorReleaseQ1FY2027.pdf
A26: ANV-01 | B26: ANVISA | C26: Pithampur | D26: FY24 | F26: 45117 | G26: DOU publication date | H26: GMP certificate (CBPF) - no on-site inspection found | I26: No | J26: Granted: prednisolone sodium phosphate; valid 2 yrs | K26: No | L26: n/a | M26: Resolucao-RE 2.493 (07-Jul-2023) | N26: High (cert); Medium (no inspection) | O26: Not on ANVISA's 2022/2023 inspected-foreign-API lists or 2024-26 approved overseas inspection schedules; likely desk/reliance review. | P26: https://www.in.gov.br/en/web/dou/-/resolucao-re-n-2.493-de-7-de-julho-de-2023-495194889
A27: ANV-02 | B27: ANVISA | C27: Pithampur | D27: FY25 | F27: 45432 | G27: DOU publication date | H27: GMP certificate (CBPF) - no on-site inspection found | I27: No | J27: Granted: 7 steroid hormones; valid 2 yrs | K27: No | L27: n/a | M27: Resolucao-RE 1.915 (16-May-2024) | N27: High (cert); Medium (no inspection) | O27: Not on ANVISA's 2022/2023 inspected-foreign-API lists or 2024-26 approved overseas inspection schedules; likely desk/reliance review. | P27: https://www.in.gov.br/en/web/dou/-/resolucao-re-n-1.915-de-16-de-maio-de-2024-560728209
A28: ANV-03 | B28: ANVISA | C28: Pithampur | D28: FY26 | F28: 45852 | G28: DOU publication date | H28: GMP certificate re-grant (CBPF) - no on-site inspection found | I28: No | J28: Granted: prednisolone sodium phosphate; valid 2 yrs | K28: No | L28: n/a | M28: Resolucao-RE 2.573 (10-Jul-2025) | N28: High (cert); Medium (no inspection) | O28: Not on ANVISA's 2022/2023 inspected-foreign-API lists or 2024-26 approved overseas inspection schedules; likely desk/reliance review. | P28: https://www.in.gov.br/en/web/dou/-/resolucao-re-n-2.573-de-10-de-julho-de-2025-641600254
A29: ANV-04 | B29: ANVISA | C29: Rau | D29: FY26 | F29: 45887 | G29: DOU publication date | H29: GMP certificate (CBPF), first for Rau - no on-site inspection found | I29: No | J29: Granted: 11 corticosteroid APIs; valid 2 yrs | K29: No | L29: n/a | M29: Resolucao-RE 3.099 (14-Aug-2025) | N29: High (cert); Medium (no inspection) | O29: Matches RHP 'ANVISA (since 2025)' for Rau. Not on ANVISA's 2022/2023 inspected-foreign-API lists or 2024-26 approved overseas inspection schedules; likely desk/reliance review. | P29: https://www.in.gov.br/en/web/dou/-/resolucao-re-n-3.099-de-14-de-agosto-de-2025-648884164
A30: ANV-05 | B30: ANVISA | C30: Pithampur | D30: FY27 | F30: 46160 | G30: DOU publication date | H30: Automatic certificate renewal (art. 39 RDC 497/2021) - explicitly not an inspection | I30: No | J30: Hormone CBPF renewed to May-2028 | K30: No | L30: n/a | M30: Resolucao-RE 2.008 (14-May-2026) | N30: High | O30: Outside window (memo). | P30: https://www.in.gov.br/en/web/dou/-/resolucao-re-n-2.008-de-14-de-maio-de-2026-706287958
A31: ANV-C | B31: ANVISA | C31: Rau / Pithampur | D31: FY23-FY25 (undated) | F31: Undated | G31: Company claim only | H31: Inspection claimed by company (DRHP/RHP list ANVISA among inspecting regulators) | I31: No | J31: 'No critical observations' | K31: No | L31: n/a | N31: Low | O31: Not dated; may be among the unattributed audits in FY23/FY25 (see Reconciliation). | P31: https://nsearchives.nseindia.com/corporate/Registration_19122025164857_DRHP_fillingversion.pdf | Q31: https://www.sebi.gov.in/sebi_data/attachdocs/aug-2026/1787119258529.pdf
A32: PMDA-01 | B32: PMDA | C32: Rau | D32: FY17 | F32: ~27-Feb-2017 (inferred) | G32: Inferred from accreditation number sequence | H32: Foreign Manufacturer Accreditation (original grant) - document-based | I32: No | J32: Accredited | K32: No | L32: n/a | M32: AG12300303 | N32: Medium-low | O32: PMDA: accreditation surveys are in principle document-based. | P32: https://www.pmda.go.jp/files/000283243.pdf | Q32: https://www.pmda.go.jp/files/000161368.pdf
A33: PMDA-02 | B33: PMDA | C33: Rau | D33: FY22 | F33: 44619 | G33: Exact (MHLW/PMDA accreditation list) | H33: Foreign Manufacturer Accreditation renewal - document-based | I33: No | J33: Accredited 27-Feb-2022 to 26-Feb-2027; renewal filed | K33: No | L33: n/a | M33: AG12300303 | N33: High | O33: Pithampur is not Japan-accredited. | P33: https://www.pmda.go.jp/files/000283243.pdf
A34: PMDA-03 | B34: PMDA | C34: Rau | D34: FY18 | F34: 42850 | G34: Exact (PMDA MF list) | H34: Product filing (JDMF) | I34: No | J34: 229MF10086 clobetasol propionate | K34: No | L34: n/a | M34: 229MF10086 | N34: High | P34: https://www.pmda.go.jp/files/000240885.pdf
A35: PMDA-04 | B35: PMDA | C35: Rau | D35: FY18 | F35: 42888 | G35: Exact (PMDA MF list) | H35: Product filing (JDMF) | I35: No | J35: 229MF10100 clobetasone butyrate | K35: No | L35: n/a | M35: 229MF10100 | N35: High | P35: https://www.pmda.go.jp/files/000240885.pdf
A36: PMDA-C | B36: PMDA | C36: Rau | D36: FY23-FY25 (undated) | F36: Undated | G36: Company claim only | H36: GMP compliance inspection claimed by company (DRHP/RHP; 'PMDA (three years)') | I36: No | J36: 'No critical observations' | K36: No | L36: n/a | N36: Low-medium | O36: On-site vs desk not disclosed. Likely among unattributed audits in FY23/FY25. | P36: https://nsearchives.nseindia.com/corporate/Registration_19122025164857_DRHP_fillingversion.pdf | Q36: https://www.sebi.gov.in/sebi_data/attachdocs/aug-2026/1787119258529.pdf
A37: MFDS-C | B37: MFDS (Korea FDA) | C37: Pithampur | D37: ~FY23 (undated) | F37: Undated (~2022) | G37: Company claim: 'MFDS (three years)' as of Jun-2025 | H37: GMP approval/audit claimed by company | I37: No | J37: Approved | K37: No | L37: n/a | N37: Low | O37: No MFDS inspection record found (nedrug, MFDS press, Korean trade press). BRSR FY25 lists 'KFDA' among regulatory auditors. | P37: https://www.sebi.gov.in/sebi_data/attachdocs/aug-2026/1787119258529.pdf | Q37: https://nsearchives.nseindia.com/corporate/SYMBIOTEC_21092026195544_SymbiotecInvestorPresentationQ1FY2027.pdf
A38: KDMF-01 | B38: MFDS (Korea FDA) | C38: Rau | D38: FY16 | F38: 42254 | G38: Registration date (PharmaCompass KDMF data) | H38: Product filing (KDMF) | I38: No | J38: Triamcinolone acetonide | K38: No | L38: n/a | N38: Medium | O38: Not an inspection. | P38: https://www.pharmacompass.com/korea-drug-master-files-dmfs/symbiotec-pharmalab
A39: KDMF-02 | B39: MFDS (Korea FDA) | C39: Pithampur | D39: FY22 | F39: 44392 | G39: Registration date (PharmaCompass KDMF data) | H39: Product filing (KDMF) | I39: No | J39: Methylprednisolone | K39: No | L39: n/a | N39: Medium | O39: Not an inspection. | P39: https://www.pharmacompass.com/korea-drug-master-files-dmfs/symbiotec-pharmalab
A40: KDMF-03 | B40: MFDS (Korea FDA) | C40: Rau | D40: FY22 | F40: 44510 | G40: Registration date (PharmaCompass KDMF data) | H40: Product filing (KDMF) | I40: No | J40: Clobetasol propionate | K40: No | L40: n/a | N40: Medium | O40: Not an inspection. | P40: https://www.pharmacompass.com/korea-drug-master-files-dmfs/symbiotec-pharmalab
A41: KDMF-04 | B41: MFDS (Korea FDA) | C41: Rau | D41: FY22 | F41: 44512 | G41: Registration date (PharmaCompass KDMF data) | H41: Product filing (KDMF) | I41: No | J41: Triamcinolone acetonide | K41: No | L41: n/a | N41: Medium | O41: Not an inspection. | P41: https://www.pharmacompass.com/korea-drug-master-files-dmfs/symbiotec-pharmalab
...

Sheet Sources & Gaps
A1: Method, key sources, conflicts and open gaps
A3: Method
A4: - Exa web search/fetch across FDA-derived datasets, EudraGMDP mirrors, Brazil DOU, PMDA/MHLW lists, IPO offer documents, exchange filings, ratings and news; five parallel research streams, then de-duplicated.
A5: - FDA dashboard rows are one per project area; duplicates collapsed using FDA inspection IDs. Sites resolved by FEI.
A6: - 'Inspection' = an on-site or remote GMP inspection/assessment by the agency. Certificates/accreditations granted without a recorded site visit are logged but not counted.
A8: Key primary sources
A9: - DRHP 19-Dec-2025: https://nsearchives.nseindia.com/corporate/Registration_19122025164857_DRHP_fillingversion.pdf
A10: - RHP 18-Aug-2026: https://www.sebi.gov.in/sebi_data/attachdocs/aug-2026/1787119258529.pdf
A11: - Q1FY27 investor release 21-Sep-2026: https://nsearchives.nseindia.com/corporate/SYMBIOTEC_21092026195951_SymbiotecInvestorReleaseQ1FY2027.pdf
A12: - NSE filing 29-Sep-2026 (Pithampur EIR, VAI): https://nsearchives.nseindia.com/corporate/SYMBIOTEC_29092026105720_SymbiotecUSFDAApprovalSEZ.pdf
A13: - FDA Form 483s (FOIA, via ProPublica): 2017 https://static.propublica.org/fda-inspection-documents/483s/2024-3040%2F483s%2F2018-10239encl2.pdf | 2019 https://static.propublica.org/fda-inspection-documents/483s/2024-3040%2F483s%2F19008449_enc7_320.pdf | 2022 https://static.propublica.org/fda-inspection-documents/483s/2024-10376%2F483s%2F2024-9235%2F2022-8697encl20.pdf
A14: - AIFA EU GMP non-compliance notice 08-Apr-2020: https://www.aifa.gov.it/-/statement-non-compliance-gmp-officina-farmaceutica-symbiotec-pharmalab-ltd-india
... A28: - ANVISA / PMDA / MFDS: no dated inspection exists in public sources; the company's undated claims cannot be placed in a fiscal year beyond the FY23/FY25 residuals.
